Workbook

Sheet Assumptions
A1: Goods on Country — GOC-only 3-Statement Model
A2: Blue = input (override-able). Black = formula. All AUD ex-GST. 5-year horizon (FY1=FY2026-27). Defaults = recommended pending Ben's six decisions (see Assumptions notes + the pack's alignment doc). Base case = the central-production investment case (Pot 1); the community wraparound (Pot 2) is fully wired but zeroed until the rollout is set.
A4: 1. PRICE & UNIT ECONOMICS (Pot 1 production — from the bed model)
A5: Selling price per bed | B5: 750 | H5: Verified: shop stretch-bed-single, held flat.
A6: Buy-Kit marginal cost per bed | B6: 684.79 | H6: Modelled (verified inputs). Today's bought-in path.
A7: Factory marginal cost per bed | B7: 425.74 | H7: PROCESS PROVEN (40-bed Maningrida in-house run); per-bed cost modelled pending measured actuals.
A8: Community marginal cost per bed | B8: 420.74 | H8: Modelled; on-country community path is future.
A10: 2. PRODUCTION DRIVERS
A11: Number of factories | B11: 1 | H11: Sunshine Coast facility, constant.
A12: Beds per factory per year | B12: 500 | H12: Practical max ~1,000/yr.
A13: Beds per container per year | B13: 500 | H13: Same ~1,000/yr practical max. OPEN: 250 vs 1,250 vs 1,500 — a measured run confirms.
A14: Kit (Defy) beds per year (max) | B14: 100 | H14: Auto-tapers to 0 once in-house covers it.
A15: First-year utilisation of new facilities | B15: 0.4 | H15: Ramp: facilities run at 40% in their build year, 100% after.
C16: Year 1 | D16: Year 2 | E16: Year 3 | F16: Year 4 | G16: Year 5
A17: New containers built per year | C17: 1 | D17: 0 | E17: 0 | F17: 1 | G17: 2 | H17: Explicit build plan (Ben decision). Matches Matt's endogenous ramp Y1-5.
A19: 3. FIXED OPERATING BLOCK (Pot 1, per year)
A20: Founder production time (30d x $560) | B20: 16800 | H20: Locked 2026-05-29. Only production days touch unit cost.
A21: Kirmos facility (50% to beds) | B21: 27000 | H21: GoC Q&A Q1 confirms.
A22: Admin | B22: 14700
A23: Field travel | B23: 51000
A24: TOTAL fixed block / yr | B24: =SUM(B20:B23) | H24: =$109,500 (confirmed line by line).
A25: Equipment subtotal (maintenance base) | B25: 167000 | H25: Shredder+press+CNC+bench midpoints.
A26: Equipment maintenance % of subtotal | B26: 0.05 | H26: Placeholder 3-5% pending vendor quotes; per facility/yr.
A28: 4. CAPEX & DEPRECIATION
A29: Facility build cost per container | B29: 207450 | H29: Matt Inputs B27 (equipment $167K + container fit-out $40,450). Capitalised.
A30: Opening plant (sunk, evidenced) | B30: 75000 | H30: MVF evidenced sunk hardware (Nic, used deals). Ownership handover targeted end-Aug 2026.
A31: Plant useful life (years) | B31: 10 | H31: Straight-line, full year in year of acquisition (simplification).
A33: 5. WORKING CAPITAL & TAX
A34: Debtor days | B34: 30 | H34: On product revenue.
A35: Creditor days | B35: 30 | H35: On cash operating costs.
A36: Inventory days | B36: 45 | H36: On bed COGS.
A37: Company tax rate | B37: 0.25 | H37: Pty Ltd base rate. Confirm charity/DGR treatment with accountant. Loss carry-forward modelled.
A38: Interest rate on debt | B38: 0.06 | H38: On QBE+SEFA borrowings, interest-only in the 5-yr window.
A39: Opening cash | B39: 50000 | H39: Most important single input (base placeholder).
A41: 6. CAPITAL STACK (draw schedule) | C41: Year 1 | D41: Year 2 | E41: Year 3 | F41: Year 4 | G41: Year 5
A42: Debt draw (SEFA Yr1, QBE Yr2) | C42: 300000 | D42: 400000 | E42: 0 | F42: 0 | G42: 0 | H42: Repayable capital. PLACEHOLDER — confirm split + QBE match ratio. $0 signed today.
A43: Equity draw (anchor philanthropy) | C43: 500000 | D43: 0 | E43: 0 | F43: 0 | G43: 0 | H43: Contributed capital / grant to capital. PLACEHOLDER.
A45: 7. POT 2 — COMMUNITY WRAPAROUND (grant-funded; ZERO in base case) | C45: Year 1 | D45: Year 2 | E45: Year 3 | F45: Year 4 | G45: Year 5
A46: Active community sites | C46: 0 | D46: 0 | E46: 0 | F46: 0 | G46: 0 | H46: Base case = 0. Set >0 to bring the community rollout (Pot 2) into the statements.
A47: Bare facility op cost / site / yr | B47: 151666 | H47: DEWR-derived: rent+insurance+admin+upkeep. Consortium/grant-carried.
...

Sheet Production
A1: Production schedule
A2: Drives the three statements. Factory beds = factories x rate (x util in Yr1). Community beds = containers x rate (new containers at util in build year). Kit auto-tapers to 0 once in-house covers the kit input.
A3: Line | C3: Year 1 | D3: Year 2 | E3: Year 3 | F3: Year 4 | G3: Year 5
A4: Factories | C4: ='Assumptions'!$B$11 | D4: ='Assumptions'!$B$11 | E4: ='Assumptions'!$B$11 | F4: ='Assumptions'!$B$11 | G4: ='Assumptions'!$B$11
A5: New containers built | C5: ='Assumptions'!C17 | D5: ='Assumptions'!D17 | E5: ='Assumptions'!E17 | F5: ='Assumptions'!F17 | G5: ='Assumptions'!G17
A6: Containers operating (cumulative) | C6: =C5 | D6: =C6+D5 | E6: =D6+E5 | F6: =E6+F5 | G6: =F6+G5
A7: Factory beds | C7: ='Assumptions'!$B$11*'Assumptions'!$B$12*'Assumptions'!$B$15 | D7: ='Assumptions'!$B$11*'Assumptions'!$B$12 | E7: ='Assumptions'!$B$11*'Assumptions'!$B$12 | F7: ='Assumptions'!$B$11*'Assumptions'!$B$12 | G7: ='Assumptions'!$B$11*'Assumptions'!$B$12
A8: Community beds | C8: =(C6-C5)*'Assumptions'!$B$13+C5*'Assumptions'!$B$13*'Assumptions'!$B$15 | D8: =(D6-D5)*'Assumptions'!$B$13+D5*'Assumptions'!$B$13*'Assumptions'!$B$15 | E8: =(E6-E5)*'Assumptions'!$B$13+E5*'Assumptions'!$B$13*'Assumptions'!$B$15 | F8: =(F6-F5)*'Assumptions'!$B$13+F5*'Assumptions'!$B$13*'Assumptions'!$B$15 | G8: =(G6-G5)*'Assumptions'!$B$13+G5*'Assumptions'!$B$13*'Assumptions'!$B$15
A9: Kit beds | C9: =IF(C7+C8>='Assumptions'!$B$14,0,'Assumptions'!$B$14) | D9: =IF(D7+D8>='Assumptions'!$B$14,0,'Assumptions'!$B$14) | E9: =IF(E7+E8>='Assumptions'!$B$14,0,'Assumptions'!$B$14) | F9: =IF(F7+F8>='Assumptions'!$B$14,0,'Assumptions'!$B$14) | G9: =IF(G7+G8>='Assumptions'!$B$14,0,'Assumptions'!$B$14)
A10: Total beds | C10: =C7+C8+C9 | D10: =D7+D8+D9 | E10: =E7+E8+E9 | F10: =F7+F8+F9 | G10: =G7+G8+G9
A11: Product revenue | C11: =C10*'Assumptions'!$B$5 | D11: =D10*'Assumptions'!$B$5 | E11: =E10*'Assumptions'!$B$5 | F11: =F10*'Assumptions'!$B$5 | G11: =G10*'Assumptions'!$B$5
A12: Bed COGS | C12: =C9*'Assumptions'!$B$6+C7*'Assumptions'!$B$7+C8*'Assumptions'!$B$8 | D12: =D9*'Assumptions'!$B$6+D7*'Assumptions'!$B$7+D8*'Assumptions'!$B$8 | E12: =E9*'Assumptions'!$B$6+E7*'Assumptions'!$B$7+E8*'Assumptions'!$B$8 | F12: =F9*'Assumptions'!$B$6+F7*'Assumptions'!$B$7+F8*'Assumptions'!$B$8 | G12: =G9*'Assumptions'!$B$6+G7*'Assumptions'!$B$7+G8*'Assumptions'!$B$8
A13: Gross margin (production) | C13: =C11-C12 | D13: =D11-D12 | E13: =E11-E12 | F13: =F11-F12 | G13: =G11-G12
A14: Equipment maintenance | C14: ='Assumptions'!$B$26*'Assumptions'!$B$25*(C4+C6) | D14: ='Assumptions'!$B$26*'Assumptions'!$B$25*(D4+D6) | E14: ='Assumptions'!$B$26*'Assumptions'!$B$25*(E4+E6) | F14: ='Assumptions'!$B$26*'Assumptions'!$B$25*(F4+F6) | G14: ='Assumptions'!$B$26*'Assumptions'!$B$25*(G4+G6)

Sheet BalanceSheet
A1: Balance Sheet (AUD)
B3: Opening | C3: Year 1 | D3: Year 2 | E3: Year 3 | F3: Year 4 | G3: Year 5
A4: ASSETS
A5: Cash | B5: ='Assumptions'!$B$39 | C5: ='CashFlow'!C22 | D5: ='CashFlow'!D22 | E5: ='CashFlow'!E22 | F5: ='CashFlow'!F22 | G5: ='CashFlow'!G22
A6: Accounts receivable | B6: 0 | C6: ='BalanceSheet'!C40 | D6: ='BalanceSheet'!D40 | E6: ='BalanceSheet'!E40 | F6: ='BalanceSheet'!F40 | G6: ='BalanceSheet'!G40
A7: Inventory | B7: 0 | C7: ='BalanceSheet'!C41 | D7: ='BalanceSheet'!D41 | E7: ='BalanceSheet'!E41 | F7: ='BalanceSheet'!F41 | G7: ='BalanceSheet'!G41
A8: Net PP&E | B8: ='Assumptions'!$B$30 | C8: ='BalanceSheet'!C36 | D8: ='BalanceSheet'!D36 | E8: ='BalanceSheet'!E36 | F8: ='BalanceSheet'!F36 | G8: ='BalanceSheet'!G36
A9: TOTAL ASSETS | B9: =SUM(B5:B8) | C9: =SUM(C5:C8) | D9: =SUM(D5:D8) | E9: =SUM(E5:E8) | F9: =SUM(F5:F8) | G9: =SUM(G5:G8)
A11: LIABILITIES
A12: Accounts payable | B12: 0 | C12: ='BalanceSheet'!C42 | D12: ='BalanceSheet'!D42 | E12: ='BalanceSheet'!E42 | F12: ='BalanceSheet'!F42 | G12: ='BalanceSheet'!G42
A13: Borrowings | B13: 0 | C13: ='BalanceSheet'!C38 | D13: ='BalanceSheet'!D38 | E13: ='BalanceSheet'!E38 | F13: ='BalanceSheet'!F38 | G13: ='BalanceSheet'!G38
A14: TOTAL LIABILITIES | B14: =B12+B13 | C14: =C12+C13 | D14: =D12+D13 | E14: =E12+E13 | F14: =F12+F13 | G14: =G12+G13
A16: EQUITY
A17: Contributed capital | B17: ='Assumptions'!$B$52 | C17: =B17+'Assumptions'!C43 | D17: =C17+'Assumptions'!D43 | E17: =D17+'Assumptions'!E43 | F17: =E17+'Assumptions'!F43 | G17: =F17+'Assumptions'!G43
A18: Retained earnings | B18: 0 | C18: =B18+'P&L'!C25 | D18: =C18+'P&L'!D25 | E18: =D18+'P&L'!E25 | F18: =E18+'P&L'!F25 | G18: =F18+'P&L'!G25
A19: TOTAL EQUITY | B19: =B17+B18 | C19: =C17+C18 | D19: =D17+D18 | E19: =E17+E18 | F19: =F17+F18 | G19: =G17+G18
A20: TOTAL LIABILITIES + EQUITY | B20: =B14+B19 | C20: =C14+C19 | D20: =D14+D19 | E20: =E14+E19 | F20: =F14+F19 | G20: =G14+G19
A22: BALANCE CHECK (must be 0) | B22: =B9-B20 | C22: =C9-C20 | D22: =D9-D20 | E22: =E9-E20 | F22: =F9-F20 | G22: =G9-G20
A30: WORKINGS
A31: Capex (container builds) | C31: ='Production'!C5*'Assumptions'!$B$29 | D31: ='Production'!D5*'Assumptions'!$B$29 | E31: ='Production'!E5*'Assumptions'!$B$29 | F31: ='Production'!F5*'Assumptions'!$B$29 | G31: ='Production'!G5*'Assumptions'!$B$29
A32: Cumulative capex | C32: =C31 | D32: =C32+D31 | E32: =D32+E31 | F32: =E32+F31 | G32: =F32+G31
A33: Gross PP&E | B33: ='Assumptions'!$B$30 | C33: ='Assumptions'!$B$30+C32 | D33: ='Assumptions'!$B$30+D32 | E33: ='Assumptions'!$B$30+E32 | F33: ='Assumptions'!$B$30+F32 | G33: ='Assumptions'!$B$30+G32
A34: Depreciation (year) | C34: =C33/'Assumptions'!$B$31 | D34: =D33/'Assumptions'!$B$31 | E34: =E33/'Assumptions'!$B$31 | F34: =F33/'Assumptions'!$B$31 | G34: =G33/'Assumptions'!$B$31
A35: Accumulated depreciation | B35: 0 | C35: =B35+C34 | D35: =C35+D34 | E35: =D35+E34 | F35: =E35+F34 | G35: =F35+G34
A36: Net PP&E | B36: ='Assumptions'!$B$30 | C36: =C33-C35 | D36: =D33-D35 | E36: =E33-E35 | F36: =F33-F35 | G36: =G33-G35
A37: Debt draw | C37: ='Assumptions'!C42 | D37: ='Assumptions'!D42 | E37: ='Assumptions'!E42 | F37: ='Assumptions'!F42 | G37: ='Assumptions'!G42
A38: Borrowings (close) | B38: 0 | C38: =B38+C37 | D38: =C38+D37 | E38: =D38+E37 | F38: =E38+F37 | G38: =F38+G37
A39: Interest expense | C39: =B38*'Assumptions'!$B$38 | D39: =C38*'Assumptions'!$B$38 | E39: =D38*'Assumptions'!$B$38 | F39: =E38*'Assumptions'!$B$38 | G39: =F38*'Assumptions'!$B$38
A40: Accounts receivable | C40: ='Assumptions'!$B$34/365*'Production'!C11 | D40: ='Assumptions'!$B$34/365*'Production'!D11 | E40: ='Assumptions'!$B$34/365*'Production'!E11 | F40: ='Assumptions'!$B$34/365*'Production'!F11 | G40: ='Assumptions'!$B$34/365*'Production'!G11
A41: Inventory | C41: ='Assumptions'!$B$36/365*'Production'!C12 | D41: ='Assumptions'!$B$36/365*'Production'!D12 | E41: ='Assumptions'!$B$36/365*'Production'!E12 | F41: ='Assumptions'!$B$36/365*'Production'!F12 | G41: ='Assumptions'!$B$36/365*'Production'!G12
A42: Accounts payable | C42: ='Assumptions'!$B$35/365*('Production'!C12+'Assumptions'!$B$24+'Production'!C14) | D42: ='Assumptions'!$B$35/365*('Production'!D12+'Assumptions'!$B$24+'Production'!D14) | E42: ='Assumptions'!$B$35/365*('Production'!E12+'Assumptions'!$B$24+'Production'!E14) | F42: ='Assumptions'!$B$35/365*('Production'!F12+'Assumptions'!$B$24+'Production'!F14) | G42: ='Assumptions'!$B$35/365*('Production'!G12+'Assumptions'!$B$24+'Production'!G14)

Sheet P&L
A1: Profit & Loss (accrual, AUD)
C3: Year 1 | D3: Year 2 | E3: Year 3 | F3: Year 4 | G3: Year 5
A4: POT 1 — PRODUCTION (the investment case)
A5: Product revenue | C5: ='Production'!C11 | D5: ='Production'!D11 | E5: ='Production'!E11 | F5: ='Production'!F11 | G5: ='Production'!G11
A6: Bed COGS | C6: =-'Production'!C12 | D6: =-'Production'!D12 | E6: =-'Production'!E12 | F6: =-'Production'!F12 | G6: =-'Production'!G12
A7: Gross profit | C7: =C5+C6 | D7: =D5+D6 | E7: =E5+E6 | F7: =F5+F6 | G7: =G5+G6
A8: Central fixed operating block | C8: =-'Assumptions'!$B$24 | D8: =-'Assumptions'!$B$24 | E8: =-'Assumptions'!$B$24 | F8: =-'Assumptions'!$B$24 | G8: =-'Assumptions'!$B$24
A9: Equipment maintenance | C9: =-'Production'!C14 | D9: =-'Production'!D14 | E9: =-'Production'!E14 | F9: =-'Production'!F14 | G9: =-'Production'!G14
A10: Production EBITDA | C10: =C7+C8+C9 | D10: =D7+D8+D9 | E10: =E7+E8+E9 | F10: =F7+F8+F9 | G10: =G7+G8+G9
A12: POT 2 — WRAPAROUND (grant-funded; zero in base case)
A13: Grant / program income | C13: ='Assumptions'!C50 | D13: ='Assumptions'!D50 | E13: ='Assumptions'!E50 | F13: ='Assumptions'!F50 | G13: ='Assumptions'!G50
A14: Community-site facility operating | C14: =-'Assumptions'!C46*'Assumptions'!$B$47 | D14: =-'Assumptions'!D46*'Assumptions'!$B$47 | E14: =-'Assumptions'!E46*'Assumptions'!$B$47 | F14: =-'Assumptions'!F46*'Assumptions'!$B$47 | G14: =-'Assumptions'!G46*'Assumptions'!$B$47
A15: Program & staff costs | C15: =-('Assumptions'!C46*'Assumptions'!$B$48+IF('Assumptions'!C46>0,'Assumptions'!$B$49,0)) | D15: =-('Assumptions'!D46*'Assumptions'!$B$48+IF('Assumptions'!D46>0,'Assumptions'!$B$49,0)) | E15: =-('Assumptions'!E46*'Assumptions'!$B$48+IF('Assumptions'!E46>0,'Assumptions'!$B$49,0)) | F15: =-('Assumptions'!F46*'Assumptions'!$B$48+IF('Assumptions'!F46>0,'Assumptions'!$B$49,0)) | G15: =-('Assumptions'!G46*'Assumptions'!$B$48+IF('Assumptions'!G46>0,'Assumptions'!$B$49,0))
A16: Pot 2 net (grant less program) | C16: =C13+C14+C15 | D16: =D13+D14+D15 | E16: =E13+E14+E15 | F16: =F13+F14+F15 | G16: =G13+G14+G15
A18: ENTITY
A19: EBITDA | C19: =C10+C16 | D19: =D10+D16 | E19: =E10+E16 | F19: =F10+F16 | G19: =G10+G16
A20: Depreciation | C20: =-'BalanceSheet'!C34 | D20: =-'BalanceSheet'!D34 | E20: =-'BalanceSheet'!E34 | F20: =-'BalanceSheet'!F34 | G20: =-'BalanceSheet'!G34
A21: EBIT | C21: =C19+C20 | D21: =D19+D20 | E21: =E19+E20 | F21: =F19+F20 | G21: =G19+G20
A22: Interest expense | C22: =-'BalanceSheet'!C39 | D22: =-'BalanceSheet'!D39 | E22: =-'BalanceSheet'!E39 | F22: =-'BalanceSheet'!F39 | G22: =-'BalanceSheet'!G39
A23: NPBT | C23: =C21+C22 | D23: =D21+D22 | E23: =E21+E22 | F23: =F21+F22 | G23: =G21+G22
A24: Income tax | C24: =-C28*'Assumptions'!$B$37 | D24: =-D28*'Assumptions'!$B$37 | E24: =-E28*'Assumptions'!$B$37 | F24: =-F28*'Assumptions'!$B$37 | G24: =-G28*'Assumptions'!$B$37
A25: NPAT | C25: =C23+C24 | D25: =D23+D24 | E25: =E23+E24 | F25: =F23+F24 | G25: =G23+G24
A26: Tax working (loss carry-forward)
A27: Loss pool (opening) | B27: 0 | C27: =B27 | D27: =C29 | E27: =D29 | F27: =E29 | G27: =F29
A28: Taxable profit | C28: =MAX(0,C23-C27) | D28: =MAX(0,D23-D27) | E28: =MAX(0,E23-E27) | F28: =MAX(0,F23-F27) | G28: =MAX(0,G23-G27)
A29: Loss pool (closing) | C29: =MAX(0,C27-MAX(0,C23))+MAX(0,-C23) | D29: =MAX(0,D27-MAX(0,D23))+MAX(0,-D23) | E29: =MAX(0,E27-MAX(0,E23))+MAX(0,-E23) | F29: =MAX(0,F27-MAX(0,F23))+MAX(0,-F23) | G29: =MAX(0,G27-MAX(0,G23))+MAX(0,-G23)
A31: MEMO — founder time sensitivity
A32: Full founder cost ($84K/yr) | C32: =-'Assumptions'!$B$20/16800*84000 | D32: =-'Assumptions'!$B$20/16800*84000 | E32: =-'Assumptions'!$B$20/16800*84000 | F32: =-'Assumptions'!$B$20/16800*84000 | G32: =-'Assumptions'!$B$20/16800*84000 | H32: Founder time is a sensitivity, not a headline. Production 30 days already in the fixed block; this memo adds the other 120 days ($67,200).
A33: NPAT after full founder time | C33: =C25+C32+'Assumptions'!$B$20 | D33: =D25+D32+'Assumptions'!$B$20 | E33: =E25+E32+'Assumptions'!$B$20 | F33: =F25+F32+'Assumptions'!$B$20 | G33: =G25+G32+'Assumptions'!$B$20

Sheet CashFlow
A1: Cash Flow (AUD)
C3: Year 1 | D3: Year 2 | E3: Year 3 | F3: Year 4 | G3: Year 5
A4: OPERATING
A5: NPAT | C5: ='P&L'!C25 | D5: ='P&L'!D25 | E5: ='P&L'!E25 | F5: ='P&L'!F25 | G5: ='P&L'!G25
A6: add: depreciation | C6: ='BalanceSheet'!C34 | D6: ='BalanceSheet'!D34 | E6: ='BalanceSheet'!E34 | F6: ='BalanceSheet'!F34 | G6: ='BalanceSheet'!G34
A7: less: increase in receivables | C7: =-('BalanceSheet'!C40-0) | D7: =-('BalanceSheet'!D40-'BalanceSheet'!C40) | E7: =-('BalanceSheet'!E40-'BalanceSheet'!D40) | F7: =-('BalanceSheet'!F40-'BalanceSheet'!E40) | G7: =-('BalanceSheet'!G40-'BalanceSheet'!F40)
A8: less: increase in inventory | C8: =-('BalanceSheet'!C41-0) | D8: =-('BalanceSheet'!D41-'BalanceSheet'!C41) | E8: =-('BalanceSheet'!E41-'BalanceSheet'!D41) | F8: =-('BalanceSheet'!F41-'BalanceSheet'!E41) | G8: =-('BalanceSheet'!G41-'BalanceSheet'!F41)
A9: add: increase in payables | C9: =('BalanceSheet'!C42-0) | D9: =('BalanceSheet'!D42-'BalanceSheet'!C42) | E9: =('BalanceSheet'!E42-'BalanceSheet'!D42) | F9: =('BalanceSheet'!F42-'BalanceSheet'!E42) | G9: =('BalanceSheet'!G42-'BalanceSheet'!F42)
A10: Net cash from operating | C10: =SUM(C5:C9) | D10: =SUM(D5:D9) | E10: =SUM(E5:E9) | F10: =SUM(F5:F9) | G10: =SUM(G5:G9)
A12: INVESTING
A13: Capex (container builds) | C13: =-'BalanceSheet'!C31 | D13: =-'BalanceSheet'!D31 | E13: =-'BalanceSheet'!E31 | F13: =-'BalanceSheet'!F31 | G13: =-'BalanceSheet'!G31
A15: FINANCING
A16: Debt draws | C16: ='Assumptions'!C42 | D16: ='Assumptions'!D42 | E16: ='Assumptions'!E42 | F16: ='Assumptions'!F42 | G16: ='Assumptions'!G42
A17: Equity contributions | C17: ='Assumptions'!C43 | D17: ='Assumptions'!D43 | E17: ='Assumptions'!E43 | F17: ='Assumptions'!F43 | G17: ='Assumptions'!G43
A18: Net cash from financing | C18: =C16+C17 | D18: =D16+D17 | E18: =E16+E17 | F18: =F16+F17 | G18: =G16+G17
A20: Net change in cash | C20: =C10+C13+C18 | D20: =D10+D13+D18 | E20: =E10+E13+E18 | F20: =F10+F13+F18 | G20: =G10+G13+G18
A21: Cash at start | C21: ='Assumptions'!$B$39 | D21: =C22 | E21: =D22 | F21: =E22 | G21: =F22
A22: Cash at end | C22: =C21+C20 | D22: =D21+D20 | E22: =E21+E20 | F22: =F21+F20 | G22: =G21+G20

Sheet Sources
A1: Sources & status
A3: Full figure set | B3: goc-data-and-figures-pack.csv (116+ rows, status + source per figure) — this workbook's inputs trace to it.
A4: Price, BOM, path costs | B4: Verified from invoices (Defy/DNA Steel/Centre Canvas). Path marginal costs modelled from verified inputs.
A5: Factory path | B5: PROVEN: 40 Maningrida Stretch beds (INV-0303) pressed + CNC'd + assembled in-house at the farm. Per-bed cost modelled pending measured actuals.
A6: Fixed block $109,500 | B6: GoC Q&A Q1 confirms line by line.
A7: Capex | B7: Central factory $112-222K gross (modelled midpoints, NOT firm quotes). Sunk plant ~$75K evidenced (MVF). Container build $207,450 = Matt Inputs B27.
A8: Community wraparound (Pot 2) | B8: DEWR-derived: bare ~$152K/yr, staffed ~$342K/yr, program $300K/yr. Zeroed in base case; grant-funded, never bed sales.
A9: Capital stack | B9: PLACEHOLDER: SEFA $300K + QBE $400K (debt) + philanthropy $500K (equity). $0 signed match-eligible today. Confirm split + QBE match ratio.
A10: Historical base | B10: Accountant-signed Goods-only carve-out revenue $713,827 (only externally-quotable figure). ~89% grant-funded.
A11: Caveats | B11: Xero-mirror workpaper, NOT accountant-reviewed statutory accounts. Capex not firm-quoted. Two pots never cross-subsidise on paper.
A12: Model conventions | B12: Accrual P&L; capex capitalised + straight-line depreciated (full year in year of acquisition); loss carry-forward tax; debt interest-only in the 5-yr window; over-capitalised base case builds idle cash (runway).
