Workbook

Sheet Start
A1: Goods financial plan
A3: Read Alignment first: who pays for what, every incoming line, buyers and grants to date, outgoings, options, balances and the plan. Phase and raise holds the cost bridge and funding gap. This Start sheet retains the selected detailed forecast and target costing. AUD, ex-GST.
A5: Current view | B5: Value | C5: What it means
A6: Selected case | B6: ='Assumptions'!B6 | C6: Choose the case on Assumptions. All forecasts follow it.
A7: Beds supported by current capacity | B7: =INDEX('Cases'!H6:H10,MATCH('Assumptions'!B6,'Cases'!A6:A10,0)) | C7: Compare with the 400-bed target and capacity gap below. These are not confirmed orders.
A8: Goods priced spending in Year 1 | B8: =INDEX('Cases'!I6:I10,MATCH('Assumptions'!B6,'Cases'!A6:A10,0)) | C8: Forecast at current capacity, including existing facility, central work and capital. It is not the complete 400-bed programme or incremental raise.
A9: Money assumed to come in | B9: =INDEX('Cases'!J6:J10,MATCH('Assumptions'!B6,'Cases'!A6:A10,0)) | C9: A scenario that includes possible grants and borrowing. It is not secured funding.
A10: Highest Year 1 cash shortfall | B10: =INDEX('Cases'!L6:L10,MATCH('Assumptions'!B6,'Cases'!A6:A10,0)) | C10: Goods operating cash need under this scenario. It is not the QBE request.
A11: Year 1 loan payments | B11: =INDEX('Cases'!K6:K10,MATCH('Assumptions'!B6,'Cases'!A6:A10,0)) | C11: Principal and interest under the proposed borrowing scenario.
A12: Cost lines still missing | B12: =INDEX('Cases'!N6:N10,MATCH('Assumptions'!B6,'Cases'!A6:A10,0)) | C12: The plan is not fully priced while this is above zero.
A13: Fully priced and feasible Year 1 plan | B13: =IF(AND('Assumptions'!B8="Yes",B12=0,B17=0,B46=0),B8,"") | C13: Blank until cost scope, required inputs and the production capacity gap are resolved.
A14: Funding actually secured | B14: ='Funding'!F19 | C14: Only received funds or signed commitments with satisfied conditions.
A15: QBE allocation difference | B15: =INDEX('Cases'!O6:O10,MATCH('Assumptions'!B6,'Cases'!A6:A10,0)) | C15: Zero means the draft allocation adds to the request. It does not mean QBE has approved it.
A16: Opening balance inputs completed | B16: ='Assumptions'!B47 | C16: Ten opening figures are required. Enter zero only when zero is verified.
A17: Forecast input errors | B17: =SUMIFS(CashSchedule[Invalid inputs],CashSchedule[Case],'Assumptions'!B6) | C17: Must be zero before relying on forecast outputs.
A18: Original source tabs preserved | B18: =COUNTA(SourceCoverage[Original tab]) | C18: All 27 supplied source tabs have a recorded destination and preserved contents.
A21: Funder and partner view | B21: Question | C21: Plain answer
A22: QBE | B22: What would the grant buy? | C22: Contribution to initial trading stock, agreed support and/or separate infrastructure. Final amount and allocation remain open.
A23: Sefa | B23: What could the loan finance? | C23: Up to $200,000 of eligible facility capital is proposed. No loan is approved, and grant and loan money must not pay the same item.
A24: Sefa | B24: What would repay the loan? | C24: Not yet proven. Repayment must come from evidenced Butterfly / Goods cash flow. Community bed-sale proceeds stay with community and are excluded.
A25: Community organisations | B25: Who funds and runs local operations? | C25: Goods funds initial stock, delivery and agreed initial programme support. Community organisations fund ongoing operations and retain their sales proceeds.
A26: Impact | B26: What change is planned? | C26: Useful beds, recycled material used in production, paid participation and stronger local operating capability. No automatic bed, job or clinical outcome follows from a grant amount.
A27: Evidence | B27: How will progress be checked? | C27: Delivery and repair records, weighed production batches, paid-hour and payment records, and agreements showing operator, asset and decision responsibilities.
A28: Sustainability | B28: What keeps the system working? | C28: Confirmed buyers and orders, funded local operations, affordable finance with a separate repayment source, maintained equipment, quality support and clear community decision rights.
A32: One master | C32: Maintain this workbook as the detailed source. Attachments are dated snapshots and do not auto-sync.
A34: What to edit | C34: Blue cells are inputs. Formulas stay protected. Record a source and status for every material change.
A36: Before sharing | C36: Resolve the capacity gap, programme support, quotes, cost overlaps, funding allocation and cash timing before approving a complete budget or final request.
A40: First-year target and cost review | C40: Agreed direction, 9 September 2026. Costs are planning estimates.
A42: Initial trading-stock target | B42: ='Sites'!I6 | C42: Made at the current production facility at The Harvest.
A43: Modelled finished beds per day | B43: =IF('Sites'!C6="Own sheets",'NM Play'!B49,'NM Play'!C49) | C43: Process assumption, not a measured sustained production rate.
A44: Production days currently available | B44: =SUM('Assumptions'!D67:O67) | C44: Existing monthly roster assumptions retained.
A45: Selected Year 1 output | B45: =B7 | C45: Actual output of the linked capacity-constrained schedule.
A46: Beds above current capacity | B46: =MAX(0,B42-B45) | C46: Target less scheduled output. Do not count this as delivered stock.
A47: Minimum productive days for target | B47: =IF(B43>0,ROUNDUP(B42/B43,0),"") | C47: Theoretical minimum, before downtime; with zero opening stock.
A48: Making cost per target bed | B48: =IF('Sites'!D6="Annual staff",IF('Sites'!C6="Own sheets",'NM Play'!B66,'NM Play'!C66),IF('Sites'!C6="Own sheets",'NM Play'!B65,'NM Play'!C65)-'NM Play'!B64)+'Sites'!Z6*'NM Play'!B32 | C48: NM inputs before freight, excluding annual crew/rent. The original expert $295.74 included freight under different material assumptions; see Phase and raise.
A49: Freight per target bed | B49: ='Sites'!R6 | C49: Inherited estimate; actual community routes need quotes.
A50: Making the target stock | B50: =B42*B48 | C50: Target pricing, not the current capacity-constrained cash forecast.
A51: Delivering the target stock | B51: =B42*B49 | C51: Target quantity multiplied by the current freight estimate.
A52: Two-facility capital allowance | B52: =SUM('Capital'!E7:E8) | C52: Separate from the initial stock. Equipment/setup scope and quotations remain open.
A53: Current facility annual fixed costs | B53: ='Responsibilities'!B22 | C53: Inherited annual operating provision; no additional staffing budget invented.
...

Sheet Model
A1: The model on one sheet (reads the other sheets; change nothing here)
A3: 1. Mission
A4: Manufacturing and economic ownership moved into community. Beds are the first proven product. Success is enterprises operating and revenue kept locally, not beds made. Five layers: community demand; catalytic capital pays Goods $750 a bed for first stock; the community enterprise sells to institutional buyers and keeps the money; manufacturing transfer through plants; shared services and governance through The Butterfly Movement Ltd.
A6: 2. Impact, per bed and this year
A7: Beds funded, tiers 1 and 2 | B7: ='Phase and raise'!B124
A8: Employment: labour hours (2 a bed) | B8: ='Phase and raise'!B124*'Plan to July 2027'!B79/'Plan to July 2027'!B80
A9: Community: enterprises with 100 beds to sell | B9: ='Phase and raise'!B126
A10: Economic: $ kept locally when the community sells them | B10: ='Phase and raise'!B124*'Bed calculator'!B44
A11: Recycling: kg of HDPE out of landfill | B11: ='Phase and raise'!B124*'Phase and raise'!B150
A12: Health: people off the floor (the reason, never a claimed outcome) | B12: ='Phase and raise'!B124
A14: 3. Last year, the whole ledger (Xero FY26, accrual)
A15: Income | B15: 1640724 | C15: Other revenue $1,371,344; grants $154,558; consulting $78,102; rent $36,720
A16: Expenses | B16: 1472755 | C16: Materials $363K, travel $233K, consulting and accounting $174K, sub-contractors $167K, marketing $142K, the rest $394K
A17: Net, before founder wages | B17: 167970 | C17: Wages $0
A18: Goods-tagged receipts | B18: 653246 | C18: Sheet FY26 invoices
A19: Goods-tagged bills | B19: 286507 | C19: ACT-GD project code
A21: 4. One bed
A22: Price at the factory door | B22: ='Phase and raise'!B87
A23: Cost to make it (labour inside) | B23: ='Phase and raise'!B88
A24: Stays with Goods | B24: ='Phase and raise'!B89
A25: Running the business a year | B25: ='Phase and raise'!B92
A26: Beds a year that carry it on beds alone | B26: ='Phase and raise'!B93
A28: 5. Every way a bed gets paid for
A29: Tier 1, invited: beds | B29: ='Phase and raise'!B123
A30: Tiers 1 and 2, asks to make: beds | B30: ='Phase and raise'!B124
A31: Tiers 1 to 3, with repayable capital: beds | B31: ='Phase and raise'!B125
A32: Catalytic capital still to find for the 400, $ | B32: ='Phase and raise'!B98
A33: Buyers pay the community, never Goods: Centrecorp 130 on quote, NT Health and Miwatj, Shepherdson College, Ceduna Aboriginal Corporation in conversation.
A35: 6. Making
A36: Beds ready to assemble now | B36: ='Bed calculator'!B27
A37: Beds possible from everything at Witta | B37: ='Bed calculator'!B28
A38: Witta a month, own panels / Defy legs | B38: ='Bed calculator'!B111
A39: First month the plan falls short | B39: ='Bed calculator'!B69
A40: Bulka bags of shred for the year | B40: ='Bed calculator'!B73
A42: 7. The year to July 2027
A43: Lowest closing cash, $ | B43: ='Plan to July 2027'!B51
A44: Cash at July 2027, $ | B44: ='Plan to July 2027'!B53
A45: Beds made, October to July | B45: ='Plan to July 2027'!B57
A46: Beds someone pays Goods for | B46: ='Plan to July 2027'!B59
A47: Operating result after operating support, $ | B47: ='Plan to July 2027'!B65
...

Sheet Assumptions
A1: Goods assumptions
A3: AUD. Blue cells are editable, including source-linked defaults. Monthly overrides are optional. Unknown opening balances and accounting policies remain blank.
A5: Assumption | B5: Value | C5: Unit | D5: Source / basis | H5: Meaning
A6: Selected case | B6: Full | C6: case | D6: Cases | H6: One selector for all working outputs.
A7: First forecast month | B7: 46357 | C7: date | D7: Ben 9 Sep 2026: December 2026, the first month QBE cash could land after the 13 Nov pre-condition date. Months 1 to 7 fall in FY27 (to 30 Jun 2027). | H7: Optional calendar anchor. Use the first of a month.
A8: Cost scope reconciled? | B8: No | C8: Yes / No | D8: Open | H8: Resolve crew, rent, freight, feedstock, youth and other omitted costs.
A9: Accounting basis reconciled? | B9: No | C9: Yes / No | D9: Open | H9: Opening balances, tax, GST and grant policy require finance review.
A10: Opening cash | C10: AUD | D10: Open | H10: Available Goods cash in the charity; not the old $50,000 placeholder.
A11: Opening receivables | C11: AUD | D11: Open | H11: Reconcile invoices; do not carry the old Rotary receivable.
A12: Opening inventory | C12: AUD | D12: Open | H12: Reconcile value to materials and finished stock.
A13: Opening net fixed assets | C13: AUD | D13: Open | H13: Recognise actual asset transfers, not the historic sunk-spend figure automatically.
A14: Opening payables | C14: AUD | D14: Open | H14: Enter explicit zero only after reconciliation.
A15: Opening deferred grants | C15: AUD | D15: Open | H15: Unspent restricted receipts may be liabilities. Confirm treatment.
A16: Opening debt | C16: AUD | D16: Open | H16: Separate from the proposed new Sefa draw.
A17: Opening net assets / equity | C17: AUD | D17: Open | H17: Independent opening balance; never plugged to force the balance sheet.
A18: Depreciation life | B18: 10 | C18: years | D18: Inputs (1)!B51 | H18: Illustrative straight-line life. Confirm policy.
A19: Income tax rate | C19: rate | D19: Open | H19: Blank until the charity’s applicable treatment is confirmed.
A20: Opening other liabilities | C20: AUD | D20: Open | H20: Includes any reconciled liabilities not separately listed.
A21: Opening income tax payable | C21: AUD | D21: Open | H21: Required for the forecast balance sheet; explicit zero permitted.
A23: Founder salaries | B23: ='Source records'!E2443 | C23: AUD/year | D23: Inputs (1)!B13 | H23: Current forward provision. Do not add the older founder-day allowance.
A24: Head office | B24: 0 | C24: AUD/year | D24: Ben 9 Sep 2026: not needed. Matt's $53,000 provision (Inputs (1)!B14) retained in Source records. | H24: Includes insurance, legal, IT, governance and accounting.
A25: Marketing | B25: 10000 | C25: AUD/year | D25: Ben 9 Sep 2026: $10,000. Matt's $35,000 provision (Inputs (1)!B15) retained in Source records. | H25: Source provision.
A26: Field travel | B26: ='Source records'!E2458 | C26: AUD/year | D26: Inputs (1)!B16 | H26: Shared Goods travel, entered once.
A27: Consulting and accounting | B27: ='Source records'!E2474 | C27: AUD/year | D27: Inputs (1)!B18 | H27: Possible overlap with head office remains explicit.
A28: Additional staff | C28: AUD/year | D28: Inputs (1)!B12 unresolved | H28: Unknown; source nil was not confirmation of no cost.
A29: Research and development | C29: AUD/year | D29: Inputs (1)!B17 unresolved | H29: Washer/prototype and other R&D scope remains to price.
A30: Other annual adjustment | B30: 0 | C30: AUD/year | D30: Planning input | H30: Negative values remove an explicitly agreed duplicate.
A33: Goods sale price | B33: ='Source records'!E2412 | C33: AUD/bed | D33: Ben 9 Sep 2026: $750 is the price at the factory door. Freight is charged on top, at cost, as its own line per community (Sites, freight per bed). Canon stretch-price. | H33: Direct Goods sales only; customer and GST terms require confirmation.
A34: Goods collection delay | B34: 1 | C34: months | D34: Prior working plan | H34: A timing scenario, not proof of buyer payment.
A35: Full QBE request | B35: 300000 | C35: AUD | D35: Ben 9 Sep 2026: QBE funds the two community plants outside Alice Springs. Request $300,000. | H35: Candidate only. Reallocate against initial stock, support and separate infrastructure. The earlier capital-only comparison is historical.
A36: Smaller QBE request | B36: 150000 | C36: AUD | D36: Ben 9 Sep 2026: smaller request = one plant, $150,000. | H36: Alternative amount only. Smaller case stages capital but retains the same initial-stock target until a smaller programme is agreed.
A37: Two new facilities allowance | B37: 300000 | C37: AUD | D37: Ben, 8 September | H37: Two community facilities in addition to the current facility at The Harvest; quotes and scope remain open.
A38: Proposed Sefa amount | B38: 200000 | C38: AUD | D38: Ben, 8 September | H38: EOI preparation, not approved lending.
A39: Illustrative loan interest | B39: 0.07 | C39: rate | D39: Backing the Bold guidelines, June 2026 | H39: Fixed-rate scenario; contractual terms must be entered if agreed.
A40: Illustrative loan term | B40: 5 | C40: years | D40: Programme range 3–5 years | H40: Monthly principal and interest.
A41: Proposed draw month | B41: 1 | C41: month | D41: Planning scenario | H41: First payment in draw month. Change to agreed timing when known.
A42: Loan fees | C42: AUD | D42: Unpriced | H42: Excluded from priced cash until entered.
A43: Grant recognition basis | B43: As received | C43: policy | D43: Source model assumption | H43: Monthly recognition overrides below allow a different reviewed schedule.
A44: Youth support per programme | B44: 10000 | C44: AUD/programme | D44: Ben 9 Sep 2026: $10,000 per community for Nic and Ben to facilitate the bed programme. Matt's $60,000 Youth Employment Program Support (Inputs (1)!B34) is retained in Source records as the earlier figure. Check overlap with founder salaries and field travel. | H44: Count separately from facilities; excludes additional brokerage/wages.
A45: Calendar date confirmed? | B45: Yes | C45: Yes / No | D45: Ben 9 Sep 2026: Month 1 = December 2026. | H45: Dates remain planning labels until agreed.
...

Sheet NM Play
A1: NM production and costing
A3: Source process assumptions feed every site and scenario. Stock figures below are old snapshots; the forecast uses only stock explicitly entered on Sites.
A5: Process input | B5: Value | C5: Unit | D5: Original source | E5: Use in the model | F5: Status
A6: Default production route | B6: Own sheets | C6: route | D6: Making plan B6 | E6: Sites link here unless overridden | F6: Planning
A7: Days per week | B7: 5 | C7: days | D7: Making plan B7 | E7: Weekly capacity | F7: Planning
A8: Weeks per planning month | B8: 4 | C8: weeks | D8: Making plan B8 | E8: Monthly process benchmark | F8: Planning
A9: Productive weeks per year | B9: 48 | C9: weeks | D9: Making plan B9 | E9: Annual benchmark; Sites controls scheduled days | F9: Planning
A10: Pressed sheets per day | B10: ='Source records'!E1670 | C10: sheets/day | D10: NM Play B66 | E10: Press capacity, raw input, power | F10: Unverified sustained rate
A11: Tabs per bed | B11: 8 | C11: pieces | D11: Making plan B11 | E11: Material conversion | F11: Ben, 6 September
A12: Leg pieces per bed | B12: 8 | C12: pieces | D12: Making plan B12 | E12: Material conversion | F12: Ben, 6 September
A13: Tabs per sheet | B13: 8 | C13: pieces | D13: Making plan B13 | E13: Sheet conversion | F13: Working yield
A14: Legs per sheet | B14: 8 | C14: pieces | D14: Making plan B14 | E14: Sheet conversion | F14: Working yield
A15: Tab sheets cut per day | B15: 22 | C15: sheets/day | D15: Making plan B15 | E15: Shared CNC time | F15: Buffered source rate
A16: Leg sheets cut per day | B16: 14 | C16: sheets/day | D16: Making plan B16 | E16: Shared CNC time | F16: Buffered source rate
A17: Working minutes per day | B17: 480 | C17: minutes | D17: Making plan B17 | E17: Paid-time benchmark | F17: Planning
A18: Ready tabs snapshot | B18: 660 | C18: pieces | D18: Making plan B18 | E18: Batch benchmark only | F18: Count requires refresh
A19: Ready legs snapshot | B19: 464 | C19: pieces | D19: Making plan B19 | E19: Batch benchmark only | F19: Count requires refresh
A20: Raw plastic snapshot | B20: 1800 | C20: kg | D20: Making plan B20 | E20: Batch purchasing benchmark | F20: Count requires refresh
A21: Plastic per pressed sheet | B21: 10 | C21: kg | D21: Ben 9 Sep 2026: a leg sheet takes 21 kg of shred, a tab sheet 15 kg; one of each per bed, so 36 kg of shred is pressed for one bed. The finished bed is 20 kg (two legs at 10 kg; tab mass to weigh). The offcut from the melt edge and the CNC router, about 16 kg, is shredded again for the next beds. Net new shred per bed is therefore about 20 kg, which is what this model charges (10 kg a sheet net). Press throughput still counts two sheets a bed. | E21: Gross material consumption | F21: Reconcile against product mass
A22: Raw plastic price | B22: 3 | C22: AUD/kg | D22: Defy shred: $2.00/kg at 1,200 kg (INV-1731, QU0467), $1.80/kg at 1,800 kg (INV-1940). Coloured: black $3, red and yellow $5 (INV-1955). Model keeps $3 as the conservative all-in rate until freight per kg is settled. | E22: Material purchases and inventory use | F22: NM planning price
A23: Electricity per press day | B23: ='Source records'!E1674 | C23: AUD/day | D23: NM Play B67 | E23: Press days × daily rate | F23: Estimate
A24: Joey / production crew | B24: ='Source records'!E1718 | C24: AUD/day | D24: NM Play B87 | E24: Charged only in NM crew mode | F24: Scope to reconcile
A25: Katrina / additional crew | C25: AUD/day | D25: NM Play B88 blank | E25: Unknown crew allowance | F25: Unpriced
A26: Consumables | B26: ='Source records'!E1723 | C26: AUD/day | D26: NM Play B89 | E26: Production days × daily rate | F26: Overlap to review
A27: Rent under NM daily basis | B27: ='Source records'!E1726 | C27: AUD/day | D27: NM Play B90 | E27: Charged only in NM crew mode | F27: Annual-rent alternative
A28: Defy leg panels | B28: 200 | C28: AUD/bed | D28: Making plan B25; NM Play B82. Defy INV-1731 (27 Mar 2026): 1200 x 1200 x 19 mm jungle half sheet $200 ex GST at bulk rate; full 1200 x 2400 panel $446.10 less 10% = $401.49 (INV-1840, INV-1951). One half sheet per bed (INV-1602: 8 full sheets credited as 16 beds). Freight extra: $980 for 20 full panels to Witta. Was 160, unsourced. | E28: Still require cutting | F28: Quote/scope to confirm
A29: Poles | B29: ='Source records'!E1540 | C29: AUD/bed | D29: NM Play D7 | E29: Bought parts for every bed | F29: Source cost
A30: Canvas | B30: ='Source records'!E1545 | C30: AUD/bed | D30: NM Play D8 | E30: Bought parts for every bed | F30: Source cost
A31: Hardware | B31: ='Source records'!E1550 | C31: AUD/bed | D31: NM Play D9 | E31: Bought parts for every bed | F31: Mixed evidence
A32: Extra assembly allowance | B32: ='Source records'!E1554 | C32: AUD/bed | D32: NM Play D10 | E32: Only the share selected on Sites is added | F32: Avoid duplicate crew charge
A33: Edging / finishing allowance | C33: AUD/day | D33: NM Play A77 unpriced | E33: Additional production-day allowance | F33: Unpriced
A34: Shredding allowance | C34: AUD/day | D34: NM Play A78 unpriced | E34: Additional production-day allowance | F34: Unpriced
A35: Extra raw material allowance | B35: 0 | C35: rate | D35: Planning assumption | E35: Extra raw kg for waste/rework; no recovered scrap credit | F35: Yield not measured
A36: Assembly capacity | B36: 5 | C36: beds/day | D36: Earlier unit-model rate | E36: Independent assembly ceiling; verify staffing | F36: Planning
A37: Crew hours per paid day | B37: 8 | C37: hours | D37: 480-minute source day | E37: NM paid-hours scenario only | F37: Not actual paid work
A38: Bed design mass | B38: 20 | C38: kg/bed | D38: Current product convention | E38: Modelled in-product mass, not weighed diversion | F38: Definition conflict remains
A39: Legacy hours-per-bed estimate | B39: 4.8 | C39: hours/bed | D39: NM Cashflow row 19 | E39: Comparison only, not used as paid-work evidence | F39: Not measured
A42: Process result | B42: Own sheets | C42: Defy legs | D42: Unit | E42: Interpretation
A43: Tab sheets per bed | B43: =$B$11/$B$13 | C43: =$B$11/$B$13 | D43: sheets/bed
A44: Leg sheets per bed | B44: =$B$12/$B$14 | C44: =$B$12/$B$14 | D44: sheets/bed
...

Sheet Sites
A1: Sites and delivery assumptions
A3: Agreed first-year target: 400 initial trading-stock beds made at the current facility at The Harvest. New community facilities are a separate capital investment; no first-year output assigned. Existing days constrain output below target. Years 2 and 3 remain inherited scenarios, not commitments.
A5: Site ID | B5: Site | C5: Route | D5: Staffing cost basis | E5: Include | F5: Start month | G5: End month | H5: Days/month | I5: Year 1 target | J5: Year 2 target | K5: Year 3 target | L5: Year 1 Goods sales | M5: Year 2 Goods sales | N5: Year 3 Goods sales | O5: Year 1 youth programmes | P5: Year 2 youth programmes | Q5: Year 3 youth programmes | R5: Freight/bed | S5: Capital share | T5: Capital basis | U5: Coordinator/year | V5: Trainer/year | W5: Rent/year | X5: Insurance/year | Y5: Maintenance/year | Z5: Extra assembly share | AA5: Opening ready tabs | AB5: Opening ready legs | AC5: Opening raw kg | AD5: Authority / stock basis | AE5: Bed communities note
A6: WITTA | B6: Goods production facility at The Harvest | C6: ='NM Play'!B6 | D6: Annual staff | E6: 1 | F6: 1 | G6: 36 | H6: 20 | I6: 400 | J6: 500 | K6: 500 | L6: 0 | M6: 0 | N6: 0 | O6: 4 | R6: 100 | S6: 0 | T6: Allowance | U6: 0 | V6: 0 | W6: ='Source records'!E2647 | X6: ='Source records'!E2655 | Y6: ='Source records'!E2633 | Z6: 0 | AA6: 812 | AB6: 650 | AC6: 145 | AD6: Witta count, Ben 9 Sep 2026 (provisional, two readings to confirm). Tabs 13 x 28 + 16 x 28 = 812 pieces; legs 650 pieces (NM's unit, 8 per bed, as in the earlier 464 = 58 sets); weighed shred 10 x 14.5 kg = 145 kg. Not yet in kg: 27 x 60 L buckets of vacuum shred, 30 sheets of press offcuts, 32 CNC tab-sheet skeletons, 'heaps' of vacuum. Also about 59 uncut tab sheets (Ben: may be miscounted; recount) not in the tab count. Not counted: finished beds, uncut leg sheets, poles, canvas. Replaces the undated NM snapshot (660 / 464 / 1,800). | AE6: Ben 9 Sep 2026: Alice Springs is NOT one of the four bed communities (its programme is Oonchiumpa's under DEWR). The four are likely from: Mount Isa and Lower Gulf, Kununurra, Ceduna / Port Augusta, Tennant Creek, and possibly more beds to the Utopia homelands. Count stays at four at $10,000 facilitation each.
A7: NEW1 | B7: Palm Island (working choice, may change) | C7: ='NM Play'!B6 | D7: Annual staff | E7: 1 | F7: 1 | G7: 36 | H7: 10 | I7: 0 | J7: 500 | K7: 500 | L7: 0 | M7: 0 | N7: 0 | R7: 50 | S7: 0.5 | T7: Allowance | U7: ='Source records'!E2559 | V7: ='Source records'!E2568 | W7: ='Source records'!E2648 | X7: ='Source records'!E2656 | Y7: ='Source records'!E2633 | Z7: 0 | AA7: 0 | AB7: 0 | AC7: 0 | AD7: Separate community facility investment. First-year production quantity not committed; zero excludes it from the initial 400. Local start, operating costs and funding remain to agree.
A8: NEW2 | B8: Maningrida (working choice, may change) | C8: ='NM Play'!B6 | D8: Annual staff | E8: 1 | F8: 1 | G8: 36 | H8: 10 | I8: 0 | J8: 500 | K8: 500 | L8: 0 | M8: 0 | N8: 0 | R8: 50 | S8: 0.5 | T8: Allowance | U8: ='Source records'!E2559 | V8: ='Source records'!E2568 | W8: ='Source records'!E2648 | X8: ='Source records'!E2656 | Y8: ='Source records'!E2633 | Z8: 0 | AA8: 0 | AB8: 0 | AC8: 0 | AD8: Separate community facility investment. First-year production quantity not committed; zero excludes it from the initial 400. Local start, operating costs and funding remain to agree.
A11: Annual staff uses coordinator, trainer and annual rent once. NM crew replaces coordinator and annual rent with NM daily crew and rent. Trainer, insurance and maintenance remain separate.
A13: Default extra assembly is 0 as a scope assumption, pending review of crew duties. Change its share only for genuinely additional work. Freight and raw input are priced independently.

Sheet Costs
A1: Operating costs
A3: Source cost rates are preserved. Responsibilities assigns cash costs to Goods or community operators. Local costs remain priced even when excluded from Goods cash.
A5: Cost ID | B5: Cost | C5: Cost centre | D5: Site | E5: Annual / unit rate | F5: Treatment | G5: Source / scope
A6: C01 | B6: Founder salaries | C6: Goods network | D6: ALL | E6: =IF(ISNUMBER('Assumptions'!B23),'Assumptions'!B23,"") | F6: Monthly driver grid | G6: Assumptions row 23; optional monthly overrides
A7: C02 | B7: Head office | C7: Goods network | D7: ALL | E7: =IF(ISNUMBER('Assumptions'!B24),'Assumptions'!B24,"") | F7: Monthly driver grid | G7: Assumptions row 24; optional monthly overrides
A8: C03 | B8: Marketing | C8: Goods network | D8: ALL | E8: =IF(ISNUMBER('Assumptions'!B25),'Assumptions'!B25,"") | F8: Monthly driver grid | G8: Assumptions row 25; optional monthly overrides
A9: C04 | B9: Field travel | C9: Goods network | D9: ALL | E9: =IF(ISNUMBER('Assumptions'!B26),'Assumptions'!B26,"") | F9: Monthly driver grid | G9: Assumptions row 26; optional monthly overrides
A10: C05 | B10: Consulting and accounting | C10: Goods network | D10: ALL | E10: =IF(ISNUMBER('Assumptions'!B27),'Assumptions'!B27,"") | F10: Monthly driver grid | G10: Assumptions row 27; optional monthly overrides
A11: C06 | B11: Additional staff | C11: Goods network | D11: ALL | E11: =IF(ISNUMBER('Assumptions'!B28),'Assumptions'!B28,"") | F11: Monthly driver grid | G11: Assumptions row 28; optional monthly overrides
A12: C07 | B12: R&D | C12: Goods network | D12: ALL | E12: =IF(ISNUMBER('Assumptions'!B29),'Assumptions'!B29,"") | F12: Monthly driver grid | G12: Assumptions row 29; optional monthly overrides
A13: C08 | B13: Other adjustment | C13: Goods network | D13: ALL | E13: =IF(ISNUMBER('Assumptions'!B30),'Assumptions'!B30,"") | F13: Monthly driver grid | G13: Assumptions row 30; optional monthly overrides
A14: S1-1 | B14: Site coordinator | C14: Product making | D14: WITTA | E14: ='Sites'!U6 | F14: Annual staff basis only | G14: Sites row 6, U
A15: S1-2 | B15: Trainer / WHS | C15: Product making | D15: WITTA | E15: ='Sites'!V6 | F15: All staffing bases | G15: Sites row 6, V
A16: S1-3 | B16: Site rent | C16: Product making | D16: WITTA | E16: ='Sites'!W6 | F16: Annual staff basis only | G16: Sites row 6, W
A17: S1-4 | B17: Site insurance | C17: Product making | D17: WITTA | E17: ='Sites'!X6 | F17: All staffing bases | G17: Sites row 6, X
A18: S1-5 | B18: Maintenance | C18: Product making | D18: WITTA | E18: ='Sites'!Y6 | F18: All staffing bases | G18: Sites row 6, Y
A19: S2-1 | B19: Site coordinator | C19: Product making | D19: NEW1 | E19: ='Sites'!U7 | F19: Annual staff basis only | G19: Sites row 7, U
A20: S2-2 | B20: Trainer / WHS | C20: Product making | D20: NEW1 | E20: ='Sites'!V7 | F20: All staffing bases | G20: Sites row 7, V
A21: S2-3 | B21: Site rent | C21: Product making | D21: NEW1 | E21: ='Sites'!W7 | F21: Annual staff basis only | G21: Sites row 7, W
A22: S2-4 | B22: Site insurance | C22: Product making | D22: NEW1 | E22: ='Sites'!X7 | F22: All staffing bases | G22: Sites row 7, X
A23: S2-5 | B23: Maintenance | C23: Product making | D23: NEW1 | E23: ='Sites'!Y7 | F23: All staffing bases | G23: Sites row 7, Y
A24: S3-1 | B24: Site coordinator | C24: Product making | D24: NEW2 | E24: ='Sites'!U8 | F24: Annual staff basis only | G24: Sites row 8, U
A25: S3-2 | B25: Trainer / WHS | C25: Product making | D25: NEW2 | E25: ='Sites'!V8 | F25: All staffing bases | G25: Sites row 8, V
A26: S3-3 | B26: Site rent | C26: Product making | D26: NEW2 | E26: ='Sites'!W8 | F26: Annual staff basis only | G26: Sites row 8, W
A27: S3-4 | B27: Site insurance | C27: Product making | D27: NEW2 | E27: ='Sites'!X8 | F27: All staffing bases | G27: Sites row 8, X
A28: S3-5 | B28: Maintenance | C28: Product making | D28: NEW2 | E28: ='Sites'!Y8 | F28: All staffing bases | G28: Sites row 8, Y
A29: Y1 | B29: Youth support programme | C29: Community support | D29: WITTA | E29: ='Assumptions'!B44 | F29: Programme count × rate | G29: Assumptions B44 ($10,000 facilitation per community, Ben 9 Sep; was Matt's $60,000). Counts on Sites. Brokerage and employment wages remain separate.
A30: Y2 | B30: Youth support programme | C30: Community support | D30: NEW1 | E30: ='Assumptions'!B44 | F30: Programme count × rate | G30: Inputs (1)!B34; counts on Sites. Brokerage and employment wages remain separate.
A31: Y3 | B31: Youth support programme | C31: Community support | D31: NEW2 | E31: ='Assumptions'!B44 | F31: Programme count × rate | G31: Inputs (1)!B34; counts on Sites. Brokerage and employment wages remain separate.
A35: Cost ID | B35: Additional cost | C35: Cost centre | D35: Site | E35: Annual amount | F35: Include 1 / 0 | G35: Source / scope
A36: X01 | B36: Additional employment brokerage and wages | C36: Community support | D36: ALL | F36: 0 | G36: Known Other Costs A47: $300,000/site/year is an alternative programme, not silently included.
A37: X02 | B37: Extra community administration / IT | C37: Community support | D37: ALL | F37: 0 | G37: Known Other Costs A41. Resolve overlap with head office.
A38: X03 | B38: Measurement and consented follow-up | C38: Community support | D38: ALL | F38: 0 | G38: Price only work additional to staff, travel and programme provisions.
A39: X04 | B39: Repairs and warranty beyond maintenance | C39: Product making | D39: ALL | F39: 0 | G39: Confirm scope and reserve.
A40: X05 | B40: Other operating cost | C40: Goods network | D40: ALL | F40: 0 | G40: Name and source before including.
A44: Unpriced active extras | E44: =SUMPRODUCT((F36:F40=1)*(ISNUMBER(E36:E40)=FALSE))
A46: NM raw material, panels, bought parts, power, consumables, daily crew and freight are calculated from Production schedule. They are not added again as annual lines.

Sheet Capital
A1: Facility capital
A3: The current allowance is $300,000 for two new facilities. Modules are an alternative calculation, not extra costs on top of the allowance. Quotes and site authority remain to confirm.
A5: Site ID | B5: Basis | C5: Allowance share | D5: Selected module cost | E5: Selected capital | F5: Deposit share | G5: Deposit month | H5: Balance month | I5: Unpriced selected modules | J5: Source
A6: WITTA | B6: ='Sites'!T6 | C6: ='Assumptions'!B37*'Sites'!S6 | D6: =SUMPRODUCT(E14:E26,F14:F26) | E6: =IF(B6="Allowance",C6,D6) | F6: 1 | G6: 1 | H6: ='Sites'!F6 | I6: =IF(B6="Modules",SUMPRODUCT((F14:F26>0)*(ISNUMBER(E14:E26)=FALSE)),0) | J6: Existing Witta capital is not purchased again.
A7: NEW1 | B7: ='Sites'!T7 | C7: ='Assumptions'!B37*'Sites'!S7 | D7: =SUMPRODUCT(E14:E26,G14:G26) | E7: =IF(B7="Allowance",C7,D7) | F7: 1 | G7: 1 | H7: ='Sites'!F7 | I7: =IF(B7="Modules",SUMPRODUCT((G14:G26>0)*(ISNUMBER(E14:E26)=FALSE)),0) | J7: Ben current allowance; original module alternatives below
A8: NEW2 | B8: ='Sites'!T8 | C8: ='Assumptions'!B37*'Sites'!S8 | D8: =SUMPRODUCT(E14:E26,H14:H26) | E8: =IF(B8="Allowance",C8,D8) | F8: 1 | G8: 1 | H8: ='Sites'!F8 | I8: =IF(B8="Modules",SUMPRODUCT((H14:H26>0)*(ISNUMBER(E14:E26)=FALSE)),0) | J8: Ben current allowance; original module alternatives below
A13: Module ID | B13: Module / component | C13: Source low | D13: Source high | E13: Selected price | F13: Witta quantity | G13: New 1 quantity | H13: New 2 quantity | I13: Source / condition | J13: New 1 amount | K13: New 2 amount
A14: M01 | B14: 40ft shipping container | C14: ='Source records'!E1207 | D14: ='Source records'!E1208 | E14: =AVERAGE(C14:D14) | F14: 0 | G14: 0 | H14: 0 | I14: Facility & Modules row 6. Original range is an estimate or historical proxy, not a current quote. | J14: =IF(G14=0,0,IF(ISNUMBER(E14),G14*E14,"")) | K14: =IF(H14=0,0,IF(ISNUMBER(E14),H14*E14,""))
A15: M02 | B15: 20ft shipping container | C15: ='Source records'!E1212 | D15: ='Source records'!E1213 | E15: =AVERAGE(C15:D15) | F15: 0 | G15: 0 | H15: 0 | I15: Facility & Modules row 7. Original range is an estimate or historical proxy, not a current quote. | J15: =IF(G15=0,0,IF(ISNUMBER(E15),G15*E15,"")) | K15: =IF(H15=0,0,IF(ISNUMBER(E15),H15*E15,""))
A16: M03 | B16: Diesel generator (press-line sized) | C16: ='Source records'!E1217 | D16: ='Source records'!E1218 | E16: =AVERAGE(C16:D16) | F16: 0 | G16: 0 | H16: 0 | I16: Facility & Modules row 8. Original range is an estimate or historical proxy, not a current quote. | J16: =IF(G16=0,0,IF(ISNUMBER(E16),G16*E16,"")) | K16: =IF(H16=0,0,IF(ISNUMBER(E16),H16*E16,""))
A17: M04 | B17: Crane placement + transport | C17: ='Source records'!E1222 | D17: ='Source records'!E1223 | E17: =AVERAGE(C17:D17) | F17: 0 | G17: 0 | H17: 0 | I17: Facility & Modules row 9. Original range is an estimate or historical proxy, not a current quote. | J17: =IF(G17=0,0,IF(ISNUMBER(E17),G17*E17,"")) | K17: =IF(H17=0,0,IF(ISNUMBER(E17),H17*E17,""))
A18: M05 | B18: Electrical fit-out (board, three-phase) | C18: ='Source records'!E1227 | D18: ='Source records'!E1228 | E18: =AVERAGE(C18:D18) | F18: 0 | G18: 0 | H18: 0 | I18: Facility & Modules row 10. Original range is an estimate or historical proxy, not a current quote. | J18: =IF(G18=0,0,IF(ISNUMBER(E18),G18*E18,"")) | K18: =IF(H18=0,0,IF(ISNUMBER(E18),H18*E18,""))
A19: M06 | B19: Ventilation / fume extraction | C19: ='Source records'!E1232 | D19: ='Source records'!E1233 | E19: =AVERAGE(C19:D19) | F19: 0 | G19: 0 | H19: 0 | I19: Facility & Modules row 11. Original range is an estimate or historical proxy, not a current quote. | J19: =IF(G19=0,0,IF(ISNUMBER(E19),G19*E19,"")) | K19: =IF(H19=0,0,IF(ISNUMBER(E19),H19*E19,""))
A20: M07 | B20: Site prep (pad, levelling) | C20: ='Source records'!E1237 | D20: ='Source records'!E1238 | E20: =AVERAGE(C20:D20) | F20: 0 | G20: 0 | H20: 0 | I20: Facility & Modules row 12. Original range is an estimate or historical proxy, not a current quote. | J20: =IF(G20=0,0,IF(ISNUMBER(E20),G20*E20,"")) | K20: =IF(H20=0,0,IF(ISNUMBER(E20),H20*E20,""))
A21: M08 | B21: PPE + startup consumables | C21: ='Source records'!E1241 | D21: ='Source records'!E1242 | E21: =AVERAGE(C21:D21) | F21: 0 | G21: 0 | H21: 0 | I21: Facility & Modules row 13. Original range is an estimate or historical proxy, not a current quote. | J21: =IF(G21=0,0,IF(ISNUMBER(E21),G21*E21,"")) | K21: =IF(H21=0,0,IF(ISNUMBER(E21),H21*E21,""))
A22: M09 | B22: Collection and sorting | C22: ='Source records'!E1258 | D22: ='Source records'!E1259 | E22: =AVERAGE(C22:D22) | F22: 0 | G22: 0 | H22: 0 | I22: Facility & Modules row 18. Original range is an estimate or historical proxy, not a current quote. | J22: =IF(G22=0,0,IF(ISNUMBER(E22),G22*E22,"")) | K22: =IF(H22=0,0,IF(ISNUMBER(E22),H22*E22,""))
A23: M10 | B23: Shredding | C23: ='Source records'!E1264 | D23: ='Source records'!E1265 | E23: =AVERAGE(C23:D23) | F23: 0 | G23: 0 | H23: 0 | I23: Facility & Modules row 19. Original range is an estimate or historical proxy, not a current quote. | J23: =IF(G23=0,0,IF(ISNUMBER(E23),G23*E23,"")) | K23: =IF(H23=0,0,IF(ISNUMBER(E23),H23*E23,""))
A24: M11 | B24: Pressing, CNC and finishing | C24: ='Source records'!E1270 | D24: ='Source records'!E1271 | E24: =AVERAGE(C24:D24) | F24: 0 | G24: 0 | H24: 0 | I24: Facility & Modules row 20. Original range is an estimate or historical proxy, not a current quote. | J24: =IF(G24=0,0,IF(ISNUMBER(E24),G24*E24,"")) | K24: =IF(H24=0,0,IF(ISNUMBER(E24),H24*E24,""))
A25: M12 | B25: Assembly and workshop | C25: ='Source records'!E1276 | D25: ='Source records'!E1277 | E25: =AVERAGE(C25:D25) | F25: 0 | G25: 0 | H25: 0 | I25: Facility & Modules row 21. Original range is an estimate or historical proxy, not a current quote. | J25: =IF(G25=0,0,IF(ISNUMBER(E25),G25*E25,"")) | K25: =IF(H25=0,0,IF(ISNUMBER(E25),H25*E25,""))
A26: M13 | B26: Sales and delivery | C26: ='Source records'!E1282 | D26: ='Source records'!E1283 | E26: =AVERAGE(C26:D26) | F26: 0 | G26: 0 | H26: 0 | I26: Facility & Modules row 22. Original range is an estimate or historical proxy, not a current quote. | J26: =IF(G26=0,0,IF(ISNUMBER(E26),G26*E26,"")) | K26: =IF(H26=0,0,IF(ISNUMBER(E26),H26*E26,""))
A30: Allowance reference | C30: ='Assumptions'!B37
A31: Replication + installation / site | C31: ='Source records'!E2594+'Source records'!E2618
A32: Turnkey / site | C32: ='Source records'!E2600
A34: Select either container size and the modules a partner actually requests. The workbook calculates prices; it does not establish a technically complete facility or partner permission.

Sheet Funding
A1: Funding and receipt conditions
A3: Invitations, possible grants and proposed borrowing remain separate from secured receipts. Conditions must be satisfied explicitly. Receipt months are scenario assumptions, not promised payment dates.
A5: Tranche ID | B5: Funder | C5: Instrument | D5: Recipient | E5: Evidence stage | F5: Amount | G5: Conditions satisfied? | H5: Secured receipt date | I5: Scenario month | J5: Include scenario | K5: Whole invitation | L5: Condition / next evidence | M5: Source | N5: Secured amount | O5: Secured month | P5: Potential amount | Q5: Invalid / missing input | R5: Full possible | S5: Smaller possible | T5: No QBE possible | U5: Delayed receipts possible | V5: Lower sales possible
A6: F01 | B6: QBE | C6: Grant | D6: Butterfly / Goods | E6: Application | F6: ='Assumptions'!B35 | G6: No | I6: 1 | J6: 1 | K6: =F6 | L6: Due Fri 25 Sep 2026 12:00pm AEST. Review meeting Wed 7 Oct 9:45am. Conditional outcomes by Fri 23 Oct. Any funding pre-conditions due by Fri 13 Nov. | M6: SIH email 24 Aug 2026 (Jay Boolkin) and interview invite 28 Aug. Amount remains an unapproved candidate. | N6: =IF(AND(ISNUMBER(F6),OR(E6="Received",AND(E6="Signed commitment",G6="Yes"))),F6,0) | O6: =IF(AND(N6>0,ISNUMBER(H6),ISNUMBER('Assumptions'!$B$7)),12*(YEAR(H6)-YEAR('Assumptions'!$B$7))+MONTH(H6)-MONTH('Assumptions'!$B$7)+1,0) | P6: =IF(N6>0,0,IF(AND(J6=1,ISNUMBER(F6)),F6,0)) | Q6: =IF(OR(F6<0,AND(J6=1,NOT(ISNUMBER(F6))),AND(P6>0,NOT(ISNUMBER(I6))),AND(N6>0,OR(NOT(ISNUMBER(H6)),NOT(ISNUMBER('Assumptions'!$B$7))))),1,0)+IF(COUNTIF(FundingTranches[Tranche ID],A6)>1,1,0) | R6: =IF(N6>0,0,IF(J6<>1,0,IF(E6="Signed commitment",F6,IF(A6="F01",'Cases'!B6,IF(A6="F06",'Cases'!C6,IF(ISNUMBER(F6),F6,0)))))) | S6: =IF(N6>0,0,IF(J6<>1,0,IF(E6="Signed commitment",F6,IF(A6="F01",'Cases'!B7,IF(A6="F06",'Cases'!C7,IF(ISNUMBER(F6),F6,0)))))) | T6: =IF(N6>0,0,IF(J6<>1,0,IF(E6="Signed commitment",F6,IF(A6="F01",'Cases'!B8,IF(A6="F06",'Cases'!C8,IF(ISNUMBER(F6),F6,0)))))) | U6: =IF(N6>0,0,IF(J6<>1,0,IF(E6="Signed commitment",F6,IF(A6="F01",'Cases'!B9,IF(A6="F06",'Cases'!C9,IF(ISNUMBER(F6),F6,0)))))) | V6: =IF(N6>0,0,IF(J6<>1,0,IF(E6="Signed commitment",F6,IF(A6="F01",'Cases'!B10,IF(A6="F06",'Cases'!C10,IF(ISNUMBER(F6),F6,0))))))
A7: F02-Y1 | B7: Tim Fairfax Family Foundation | C7: Grant | D7: Butterfly | E7: Invitation | F7: 100000 | G7: No | I7: 1 | J7: 1 | K7: 300000 | L7: TFFF Resilience stream = multi-year GENERAL OPERATING SUPPORT, assessed on governance, leadership, strategy and financial health, not a project budget. SmartyGrants form MYGOS FY27 (eligibility, organisation and strategy, governance and leadership, relationships, financials, supporting material, declaration); AI use must be declared. Due Fri 9 Oct 2026 5:00pm AEST; board late November, after the QBE 13 Nov pre-condition date. Three equal annual payments to The Butterfly Movement (ACNC, DGR1). No vehicles, conferences or endowments. | M7: Katie Norman email 31 Aug 2026; tfff.org.au strategy page and SmartyGrants form preview pasted by Ben 9 Sep 2026. | N7: =IF(AND(ISNUMBER(F7),OR(E7="Received",AND(E7="Signed commitment",G7="Yes"))),F7,0) | O7: =IF(AND(N7>0,ISNUMBER(H7),ISNUMBER('Assumptions'!$B$7)),12*(YEAR(H7)-YEAR('Assumptions'!$B$7))+MONTH(H7)-MONTH('Assumptions'!$B$7)+1,0) | P7: =IF(N7>0,0,IF(AND(J7=1,ISNUMBER(F7)),F7,0)) | Q7: =IF(OR(F7<0,AND(J7=1,NOT(ISNUMBER(F7))),AND(P7>0,NOT(ISNUMBER(I7))),AND(N7>0,OR(NOT(ISNUMBER(H7)),NOT(ISNUMBER('Assumptions'!$B$7))))),1,0)+IF(COUNTIF(FundingTranches[Tranche ID],A7)>1,1,0) | R7: =IF(N7>0,0,IF(J7<>1,0,IF(E7="Signed commitment",F7,IF(A7="F01",'Cases'!B6,IF(A7="F06",'Cases'!C6,IF(ISNUMBER(F7),F7,0)))))) | S7: =IF(N7>0,0,IF(J7<>1,0,IF(E7="Signed commitment",F7,IF(A7="F01",'Cases'!B7,IF(A7="F06",'Cases'!C7,IF(ISNUMBER(F7),F7,0)))))) | T7: =IF(N7>0,0,IF(J7<>1,0,IF(E7="Signed commitment",F7,IF(A7="F01",'Cases'!B8,IF(A7="F06",'Cases'!C8,IF(ISNUMBER(F7),F7,0)))))) | U7: =IF(N7>0,0,IF(J7<>1,0,IF(E7="Signed commitment",F7,IF(A7="F01",'Cases'!B9,IF(A7="F06",'Cases'!C9,IF(ISNUMBER(F7),F7,0)))))) | V7: =IF(N7>0,0,IF(J7<>1,0,IF(E7="Signed commitment",F7,IF(A7="F01",'Cases'!B10,IF(A7="F06",'Cases'!C10,IF(ISNUMBER(F7),F7,0))))))
A8: F03 | B8: Brian M. Davis Charitable Foundation | C8: Grant | D8: Butterfly proposed | E8: Invitation | F8: 100000 | G8: No | I8: 1 | J8: 1 | K8: 100000 | L8: Application due Fri 25 Sep 2026; Grants Committee October; Board 19 Nov, after the QBE 13 Nov pre-condition date. CONDITION CONFIRMED 9 Sep: the BMDCF budget template instructions (row B16) say BMDCF only pays out a grant once all funding for the project has been confirmed; unconfirmed lines must be flagged No and reported on. The Grant Conditions PDF adds annual review and acquittal within three months. Grant is GST-free; budget ex GST. Define the BMD project so its other income is confirmed. | M8: Miranda Campbell email 1 Sep 2026; BMDCF Grant Conditions.pdf, Budget template 3yr 2026 and application questions in 'BMD - application forms' (read 9 Sep 2026). | N8: =IF(AND(ISNUMBER(F8),OR(E8="Received",AND(E8="Signed commitment",G8="Yes"))),F8,0) | O8: =IF(AND(N8>0,ISNUMBER(H8),ISNUMBER('Assumptions'!$B$7)),12*(YEAR(H8)-YEAR('Assumptions'!$B$7))+MONTH(H8)-MONTH('Assumptions'!$B$7)+1,0) | P8: =IF(N8>0,0,IF(AND(J8=1,ISNUMBER(F8)),F8,0)) | Q8: =IF(OR(F8<0,AND(J8=1,NOT(ISNUMBER(F8))),AND(P8>0,NOT(ISNUMBER(I8))),AND(N8>0,OR(NOT(ISNUMBER(H8)),NOT(ISNUMBER('Assumptions'!$B$7))))),1,0)+IF(COUNTIF(FundingTranches[Tranche ID],A8)>1,1,0) | R8: =IF(N8>0,0,IF(J8<>1,0,IF(E8="Signed commitment",F8,IF(A8="F01",'Cases'!B6,IF(A8="F06",'Cases'!C6,IF(ISNUMBER(F8),F8,0)))))) | S8: =IF(N8>0,0,IF(J8<>1,0,IF(E8="Signed commitment",F8,IF(A8="F01",'Cases'!B7,IF(A8="F06",'Cases'!C7,IF(ISNUMBER(F8),F8,0)))))) | T8: =IF(N8>0,0,IF(J8<>1,0,IF(E8="Signed commitment",F8,IF(A8="F01",'Cases'!B8,IF(A8="F06",'Cases'!C8,IF(ISNUMBER(F8),F8,0)))))) | U8: =IF(N8>0,0,IF(J8<>1,0,IF(E8="Signed commitment",F8,IF(A8="F01",'Cases'!B9,IF(A8="F06",'Cases'!C9,IF(ISNUMBER(F8),F8,0)))))) | V8: =IF(N8>0,0,IF(J8<>1,0,IF(E8="Signed commitment",F8,IF(A8="F01",'Cases'!B10,IF(A8="F06",'Cases'!C10,IF(ISNUMBER(F8),F8,0))))))
A9: F04 | B9: Snow Foundation | C9: Grant | D9: To confirm | E9: Discussion | G9: No | J9: 0 | L9: No current ask found in email to 9 Sep 2026; only introductions (Coolamon Community, 22 Jul). Enter an amount only after a new dated ask. | M9: Gmail search 9 Sep 2026 | N9: =IF(AND(ISNUMBER(F9),OR(E9="Received",AND(E9="Signed commitment",G9="Yes"))),F9,0) | O9: =IF(AND(N9>0,ISNUMBER(H9),ISNUMBER('Assumptions'!$B$7)),12*(YEAR(H9)-YEAR('Assumptions'!$B$7))+MONTH(H9)-MONTH('Assumptions'!$B$7)+1,0) | P9: =IF(N9>0,0,IF(AND(J9=1,ISNUMBER(F9)),F9,0)) | Q9: =IF(OR(F9<0,AND(J9=1,NOT(ISNUMBER(F9))),AND(P9>0,NOT(ISNUMBER(I9))),AND(N9>0,OR(NOT(ISNUMBER(H9)),NOT(ISNUMBER('Assumptions'!$B$7))))),1,0)+IF(COUNTIF(FundingTranches[Tranche ID],A9)>1,1,0) | R9: =IF(N9>0,0,IF(J9<>1,0,IF(E9="Signed commitment",F9,IF(A9="F01",'Cases'!B6,IF(A9="F06",'Cases'!C6,IF(ISNUMBER(F9),F9,0)))))) | S9: =IF(N9>0,0,IF(J9<>1,0,IF(E9="Signed commitment",F9,IF(A9="F01",'Cases'!B7,IF(A9="F06",'Cases'!C7,IF(ISNUMBER(F9),F9,0)))))) | T9: =IF(N9>0,0,IF(J9<>1,0,IF(E9="Signed commitment",F9,IF(A9="F01",'Cases'!B8,IF(A9="F06",'Cases'!C8,IF(ISNUMBER(F9),F9,0)))))) | U9: =IF(N9>0,0,IF(J9<>1,0,IF(E9="Signed commitment",F9,IF(A9="F01",'Cases'!B9,IF(A9="F06",'Cases'!C9,IF(ISNUMBER(F9),F9,0)))))) | V9: =IF(N9>0,0,IF(J9<>1,0,IF(E9="Signed commitment",F9,IF(A9="F01",'Cases'!B10,IF(A9="F06",'Cases'!C10,IF(ISNUMBER(F9),F9,0))))))
A10: F05 | B10: Dusseldorp | C10: Grant | D10: To confirm | E10: Discussion | G10: No | J10: 0 | L10: $15,000 released 25 Jun 2026 for CONTAINED (INV-0338, paid); not a Goods bed line. No Goods ask in email; the 6 Sep thread is Indigenous media and story work. | M10: Rachel Fyfe emails 25 Jun and 6 Sep 2026 | N10: =IF(AND(ISNUMBER(F10),OR(E10="Received",AND(E10="Signed commitment",G10="Yes"))),F10,0) | O10: =IF(AND(N10>0,ISNUMBER(H10),ISNUMBER('Assumptions'!$B$7)),12*(YEAR(H10)-YEAR('Assumptions'!$B$7))+MONTH(H10)-MONTH('Assumptions'!$B$7)+1,0) | P10: =IF(N10>0,0,IF(AND(J10=1,ISNUMBER(F10)),F10,0)) | Q10: =IF(OR(F10<0,AND(J10=1,NOT(ISNUMBER(F10))),AND(P10>0,NOT(ISNUMBER(I10))),AND(N10>0,OR(NOT(ISNUMBER(H10)),NOT(ISNUMBER('Assumptions'!$B$7))))),1,0)+IF(COUNTIF(FundingTranches[Tranche ID],A10)>1,1,0) | R10: =IF(N10>0,0,IF(J10<>1,0,IF(E10="Signed commitment",F10,IF(A10="F01",'Cases'!B6,IF(A10="F06",'Cases'!C6,IF(ISNUMBER(F10),F10,0)))))) | S10: =IF(N10>0,0,IF(J10<>1,0,IF(E10="Signed commitment",F10,IF(A10="F01",'Cases'!B7,IF(A10="F06",'Cases'!C7,IF(ISNUMBER(F10),F10,0)))))) | T10: =IF(N10>0,0,IF(J10<>1,0,IF(E10="Signed commitment",F10,IF(A10="F01",'Cases'!B8,IF(A10="F06",'Cases'!C8,IF(ISNUMBER(F10),F10,0)))))) | U10: =IF(N10>0,0,IF(J10<>1,0,IF(E10="Signed commitment",F10,IF(A10="F01",'Cases'!B9,IF(A10="F06",'Cases'!C9,IF(ISNUMBER(F10),F10,0)))))) | V10: =IF(N10>0,0,IF(J10<>1,0,IF(E10="Signed commitment",F10,IF(A10="F01",'Cases'!B10,IF(A10="F06",'Cases'!C10,IF(ISNUMBER(F10),F10,0))))))
A11: F06 | B11: Sefa Backing the Bold Queensland | C11: Loan | D11: Butterfly / Goods | E11: Discussion | F11: ='Assumptions'!B38 | G11: No | I11: ='Assumptions'!B41 | J11: 1 | K11: =F11 | L11: No EOI sent. Joel Bird (25 Aug) offered to review an EOI; Tanya Wong (Sefa investment team) offered to review the financials. $200,000 is our number, not Sefa's. Eligibility, affordability and borrower unresolved. | M11: Joel Bird email 25 Aug 2026; Backing the Bold guidelines. Verified 9 Sep 2026. | N11: =IF(AND(ISNUMBER(F11),OR(E11="Received",AND(E11="Signed commitment",G11="Yes"))),F11,0) | O11: =IF(AND(N11>0,ISNUMBER(H11),ISNUMBER('Assumptions'!$B$7)),12*(YEAR(H11)-YEAR('Assumptions'!$B$7))+MONTH(H11)-MONTH('Assumptions'!$B$7)+1,0) | P11: =IF(N11>0,0,IF(AND(J11=1,ISNUMBER(F11)),F11,0)) | Q11: =IF(OR(F11<0,AND(J11=1,NOT(ISNUMBER(F11))),AND(P11>0,NOT(ISNUMBER(I11))),AND(N11>0,OR(NOT(ISNUMBER(H11)),NOT(ISNUMBER('Assumptions'!$B$7))))),1,0)+IF(COUNTIF(FundingTranches[Tranche ID],A11)>1,1,0) | R11: =IF(N11>0,0,IF(J11<>1,0,IF(E11="Signed commitment",F11,IF(A11="F01",'Cases'!B6,IF(A11="F06",'Cases'!C6,IF(ISNUMBER(F11),F11,0)))))) | S11: =IF(N11>0,0,IF(J11<>1,0,IF(E11="Signed commitment",F11,IF(A11="F01",'Cases'!B7,IF(A11="F06",'Cases'!C7,IF(ISNUMBER(F11),F11,0)))))) | T11: =IF(N11>0,0,IF(J11<>1,0,IF(E11="Signed commitment",F11,IF(A11="F01",'Cases'!B8,IF(A11="F06",'Cases'!C8,IF(ISNUMBER(F11),F11,0)))))) | U11: =IF(N11>0,0,IF(J11<>1,0,IF(E11="Signed commitment",F11,IF(A11="F01",'Cases'!B9,IF(A11="F06",'Cases'!C9,IF(ISNUMBER(F11),F11,0)))))) | V11: =IF(N11>0,0,IF(J11<>1,0,IF(E11="Signed commitment",F11,IF(A11="F01",'Cases'!B10,IF(A11="F06",'Cases'!C10,IF(ISNUMBER(F11),F11,0))))))
A12: F08 | B12: Minderoo | C12: Grant | D12: To confirm | E12: Discussion | F12: 100000 | G12: No | J12: 0 | L12: No live ask in email. Lucy Stronach paused conversations 14 May 2026. Not a current prospect. | M12: Gmail search 9 Sep 2026 | N12: =IF(AND(ISNUMBER(F12),OR(E12="Received",AND(E12="Signed commitment",G12="Yes"))),F12,0) | O12: =IF(AND(N12>0,ISNUMBER(H12),ISNUMBER('Assumptions'!$B$7)),12*(YEAR(H12)-YEAR('Assumptions'!$B$7))+MONTH(H12)-MONTH('Assumptions'!$B$7)+1,0) | P12: =IF(N12>0,0,IF(AND(J12=1,ISNUMBER(F12)),F12,0)) | Q12: =IF(OR(F12<0,AND(J12=1,NOT(ISNUMBER(F12))),AND(P12>0,NOT(ISNUMBER(I12))),AND(N12>0,OR(NOT(ISNUMBER(H12)),NOT(ISNUMBER('Assumptions'!$B$7))))),1,0)+IF(COUNTIF(FundingTranches[Tranche ID],A12)>1,1,0) | R12: =IF(N12>0,0,IF(J12<>1,0,IF(E12="Signed commitment",F12,IF(A12="F01",'Cases'!B6,IF(A12="F06",'Cases'!C6,IF(ISNUMBER(F12),F12,0)))))) | S12: =IF(N12>0,0,IF(J12<>1,0,IF(E12="Signed commitment",F12,IF(A12="F01",'Cases'!B7,IF(A12="F06",'Cases'!C7,IF(ISNUMBER(F12),F12,0)))))) | T12: =IF(N12>0,0,IF(J12<>1,0,IF(E12="Signed commitment",F12,IF(A12="F01",'Cases'!B8,IF(A12="F06",'Cases'!C8,IF(ISNUMBER(F12),F12,0)))))) | U12: =IF(N12>0,0,IF(J12<>1,0,IF(E12="Signed commitment",F12,IF(A12="F01",'Cases'!B9,IF(A12="F06",'Cases'!C9,IF(ISNUMBER(F12),F12,0)))))) | V12: =IF(N12>0,0,IF(J12<>1,0,IF(E12="Signed commitment",F12,IF(A12="F01",'Cases'!B10,IF(A12="F06",'Cases'!C10,IF(ISNUMBER(F12),F12,0))))))
A13: F02-Y2 | B13: Tim Fairfax Family Foundation | C13: Grant | D13: Butterfly | E13: Invitation | F13: 100000 | G13: No | I13: 13 | J13: 1 | K13: 300000 | L13: Second annual tranche only if awarded. | M13: Same invitation as F02-Y1; whole invitation is not summed | N13: =IF(AND(ISNUMBER(F13),OR(E13="Received",AND(E13="Signed commitment",G13="Yes"))),F13,0) | O13: =IF(AND(N13>0,ISNUMBER(H13),ISNUMBER('Assumptions'!$B$7)),12*(YEAR(H13)-YEAR('Assumptions'!$B$7))+MONTH(H13)-MONTH('Assumptions'!$B$7)+1,0) | P13: =IF(N13>0,0,IF(AND(J13=1,ISNUMBER(F13)),F13,0)) | Q13: =IF(OR(F13<0,AND(J13=1,NOT(ISNUMBER(F13))),AND(P13>0,NOT(ISNUMBER(I13))),AND(N13>0,OR(NOT(ISNUMBER(H13)),NOT(ISNUMBER('Assumptions'!$B$7))))),1,0)+IF(COUNTIF(FundingTranches[Tranche ID],A13)>1,1,0) | R13: =IF(N13>0,0,IF(J13<>1,0,IF(E13="Signed commitment",F13,IF(A13="F01",'Cases'!B6,IF(A13="F06",'Cases'!C6,IF(ISNUMBER(F13),F13,0)))))) | S13: =IF(N13>0,0,IF(J13<>1,0,IF(E13="Signed commitment",F13,IF(A13="F01",'Cases'!B7,IF(A13="F06",'Cases'!C7,IF(ISNUMBER(F13),F13,0)))))) | T13: =IF(N13>0,0,IF(J13<>1,0,IF(E13="Signed commitment",F13,IF(A13="F01",'Cases'!B8,IF(A13="F06",'Cases'!C8,IF(ISNUMBER(F13),F13,0)))))) | U13: =IF(N13>0,0,IF(J13<>1,0,IF(E13="Signed commitment",F13,IF(A13="F01",'Cases'!B9,IF(A13="F06",'Cases'!C9,IF(ISNUMBER(F13),F13,0)))))) | V13: =IF(N13>0,0,IF(J13<>1,0,IF(E13="Signed commitment",F13,IF(A13="F01",'Cases'!B10,IF(A13="F06",'Cases'!C10,IF(ISNUMBER(F13),F13,0))))))
A14: F02-Y3 | B14: Tim Fairfax Family Foundation | C14: Grant | D14: Butterfly | E14: Invitation | F14: 100000 | G14: No | I14: 25 | J14: 1 | K14: 300000 | L14: Third annual tranche only if awarded. | M14: Same invitation as F02-Y1 | N14: =IF(AND(ISNUMBER(F14),OR(E14="Received",AND(E14="Signed commitment",G14="Yes"))),F14,0) | O14: =IF(AND(N14>0,ISNUMBER(H14),ISNUMBER('Assumptions'!$B$7)),12*(YEAR(H14)-YEAR('Assumptions'!$B$7))+MONTH(H14)-MONTH('Assumptions'!$B$7)+1,0) | P14: =IF(N14>0,0,IF(AND(J14=1,ISNUMBER(F14)),F14,0)) | Q14: =IF(OR(F14<0,AND(J14=1,NOT(ISNUMBER(F14))),AND(P14>0,NOT(ISNUMBER(I14))),AND(N14>0,OR(NOT(ISNUMBER(H14)),NOT(ISNUMBER('Assumptions'!$B$7))))),1,0)+IF(COUNTIF(FundingTranches[Tranche ID],A14)>1,1,0) | R14: =IF(N14>0,0,IF(J14<>1,0,IF(E14="Signed commitment",F14,IF(A14="F01",'Cases'!B6,IF(A14="F06",'Cases'!C6,IF(ISNUMBER(F14),F14,0)))))) | S14: =IF(N14>0,0,IF(J14<>1,0,IF(E14="Signed commitment",F14,IF(A14="F01",'Cases'!B7,IF(A14="F06",'Cases'!C7,IF(ISNUMBER(F14),F14,0)))))) | T14: =IF(N14>0,0,IF(J14<>1,0,IF(E14="Signed commitment",F14,IF(A14="F01",'Cases'!B8,IF(A14="F06",'Cases'!C8,IF(ISNUMBER(F14),F14,0)))))) | U14: =IF(N14>0,0,IF(J14<>1,0,IF(E14="Signed commitment",F14,IF(A14="F01",'Cases'!B9,IF(A14="F06",'Cases'!C9,IF(ISNUMBER(F14),F14,0)))))) | V14: =IF(N14>0,0,IF(J14<>1,0,IF(E14="Signed commitment",F14,IF(A14="F01",'Cases'!B10,IF(A14="F06",'Cases'!C10,IF(ISNUMBER(F14),F14,0))))))
A15: F09 | B15: Oonchiumpa (DEWR REAL Innovation Fund) plant set-up | C15: Grant | D15: Goods, paid by Oonchiumpa (pass-through) | E15: Offer letter | F15: 150000 | G15: No | I15: 1 | J15: 0 | K15: =F15 | L15: ALICE SPRINGS PLANT ONLY, pass-through. DEWR offer letter 12 Aug 2026: $1,695,000 to Oonchiumpa over FY26-27 to FY29-30, subject to a Grant Agreement; Oonchiumpa intends to accept (25 Aug). Ben 9 Sep: about $150,000 pays Goods to build the Alice Springs plant; Goods spends it on that build, so net zero for Goods. Excluded from scenarios (Include 0). Not one of the two plants in this workbook. | M15: DEWR outcome letter 12 Aug 2026 (Downloads); Tanya Turner emails 13 and 26 Aug; Ben 9 Sep 2026 | N15: =IF(AND(ISNUMBER(F15),OR(E15="Received",AND(E15="Signed commitment",G15="Yes"))),F15,0) | O15: =IF(AND(N15>0,ISNUMBER(H15),ISNUMBER('Assumptions'!$B$7)),12*(YEAR(H15)-YEAR('Assumptions'!$B$7))+MONTH(H15)-MONTH('Assumptions'!$B$7)+1,0) | P15: =IF(N15>0,0,IF(AND(J15=1,ISNUMBER(F15)),F15,0)) | Q15: =IF(OR(F15<0,AND(J15=1,NOT(ISNUMBER(F15))),AND(P15>0,NOT(ISNUMBER(I15))),AND(N15>0,OR(NOT(ISNUMBER(H15)),NOT(ISNUMBER('Assumptions'!$B$7))))),1,0)+IF(COUNTIF(FundingTranches[Tranche ID],A15)>1,1,0) | R15: =IF(N15>0,0,IF(J15<>1,0,IF(E15="Signed commitment",F15,IF(A15="F01",'Cases'!B6,IF(A15="F06",'Cases'!C6,IF(ISNUMBER(F15),F15,0)))))) | S15: =IF(N15>0,0,IF(J15<>1,0,IF(E15="Signed commitment",F15,IF(A15="F01",'Cases'!B7,IF(A15="F06",'Cases'!C7,IF(ISNUMBER(F15),F15,0)))))) | T15: =IF(N15>0,0,IF(J15<>1,0,IF(E15="Signed commitment",F15,IF(A15="F01",'Cases'!B8,IF(A15="F06",'Cases'!C8,IF(ISNUMBER(F15),F15,0)))))) | U15: =IF(N15>0,0,IF(J15<>1,0,IF(E15="Signed commitment",F15,IF(A15="F01",'Cases'!B9,IF(A15="F06",'Cases'!C9,IF(ISNUMBER(F15),F15,0)))))) | V15: =IF(N15>0,0,IF(J15<>1,0,IF(E15="Signed commitment",F15,IF(A15="F01",'Cases'!B10,IF(A15="F06",'Cases'!C10,IF(ISNUMBER(F15),F15,0))))))
A16: F10 | B16: NIAA Local Investments Funding (via Oonchiumpa) | C16: Grant | D16: Goods, paid by Oonchiumpa (pass-through) | E16: Discussion | F16: 150000 | G16: No | I16: 3 | J16: 0 | K16: =F16 | L16: ALICE SPRINGS PLANT ONLY, pass-through. NIAA Local Investments up to $150,000 ex GST, one financial year; invitation in train (Tanya replied to Alex Cadden; NIAA confirmed plant equipment is eligible, Ben 9 Sep). Paid to Goods for the Alice Springs build and spent on it; net zero for Goods. Excluded from scenarios (Include 0). | M16: Alex Cadden email 7 Aug 2026 (forwarded 13 Aug); deliverables/LIF-150K-play.md; Ben 9 Sep 2026 | N16: =IF(AND(ISNUMBER(F16),OR(E16="Received",AND(E16="Signed commitment",G16="Yes"))),F16,0) | O16: =IF(AND(N16>0,ISNUMBER(H16),ISNUMBER('Assumptions'!$B$7)),12*(YEAR(H16)-YEAR('Assumptions'!$B$7))+MONTH(H16)-MONTH('Assumptions'!$B$7)+1,0) | P16: =IF(N16>0,0,IF(AND(J16=1,ISNUMBER(F16)),F16,0)) | Q16: =IF(OR(F16<0,AND(J16=1,NOT(ISNUMBER(F16))),AND(P16>0,NOT(ISNUMBER(I16))),AND(N16>0,OR(NOT(ISNUMBER(H16)),NOT(ISNUMBER('Assumptions'!$B$7))))),1,0)+IF(COUNTIF(FundingTranches[Tranche ID],A16)>1,1,0) | R16: =IF(N16>0,0,IF(J16<>1,0,IF(E16="Signed commitment",F16,IF(A16="F01",'Cases'!B6,IF(A16="F06",'Cases'!C6,IF(ISNUMBER(F16),F16,0)))))) | S16: =IF(N16>0,0,IF(J16<>1,0,IF(E16="Signed commitment",F16,IF(A16="F01",'Cases'!B7,IF(A16="F06",'Cases'!C7,IF(ISNUMBER(F16),F16,0)))))) | T16: =IF(N16>0,0,IF(J16<>1,0,IF(E16="Signed commitment",F16,IF(A16="F01",'Cases'!B8,IF(A16="F06",'Cases'!C8,IF(ISNUMBER(F16),F16,0)))))) | U16: =IF(N16>0,0,IF(J16<>1,0,IF(E16="Signed commitment",F16,IF(A16="F01",'Cases'!B9,IF(A16="F06",'Cases'!C9,IF(ISNUMBER(F16),F16,0)))))) | V16: =IF(N16>0,0,IF(J16<>1,0,IF(E16="Signed commitment",F16,IF(A16="F01",'Cases'!B10,IF(A16="F06",'Cases'!C10,IF(ISNUMBER(F16),F16,0))))))
A17: F11 | B17: SEDI First Nations Capability Building Grant (Impact Investing Australia) | C17: Grant | D17: Butterfly or ACT via general SEDI; Oonchiumpa via SEDI First Nations | E17: Discussion | G17: No | J17: 0 | K17: =F17 | L17: $50,000 to $120,000, rolling EOIs to early 2027; one EOI is assessed for both SEDI First Nations and general SEDI, and a non-Indigenous applicant is transferred to general SEDI. Funds capability services only (finance, evaluation, legal, consulting), up to 20% internal costs; cannot buy plant or beds. Applicant must trade beyond start-up with revenue over $50,000 and repeatable trading revenue over $35,000; grant cannot exceed annual revenue. Decide the applicant entity and the capability plan before entering an amount. | M17: https://impactinvestingaustralia.com/sedi-first-nations-grants/ read 9 Sep 2026; EOI https://sedigrants.grantplatform.com; forwarded by Nic 24 Aug 2026 | N17: =IF(AND(ISNUMBER(F17),OR(E17="Received",AND(E17="Signed commitment",G17="Yes"))),F17,0) | O17: =IF(AND(N17>0,ISNUMBER(H17),ISNUMBER('Assumptions'!$B$7)),12*(YEAR(H17)-YEAR('Assumptions'!$B$7))+MONTH(H17)-MONTH('Assumptions'!$B$7)+1,0) | P17: =IF(N17>0,0,IF(AND(J17=1,ISNUMBER(F17)),F17,0)) | Q17: =IF(OR(F17<0,AND(J17=1,NOT(ISNUMBER(F17))),AND(P17>0,NOT(ISNUMBER(I17))),AND(N17>0,OR(NOT(ISNUMBER(H17)),NOT(ISNUMBER('Assumptions'!$B$7))))),1,0)+IF(COUNTIF(FundingTranches[Tranche ID],A17)>1,1,0) | R17: =IF(N17>0,0,IF(J17<>1,0,IF(E17="Signed commitment",F17,IF(A17="F01",'Cases'!B6,IF(A17="F06",'Cases'!C6,IF(ISNUMBER(F17),F17,0)))))) | S17: =IF(N17>0,0,IF(J17<>1,0,IF(E17="Signed commitment",F17,IF(A17="F01",'Cases'!B7,IF(A17="F06",'Cases'!C7,IF(ISNUMBER(F17),F17,0)))))) | T17: =IF(N17>0,0,IF(J17<>1,0,IF(E17="Signed commitment",F17,IF(A17="F01",'Cases'!B8,IF(A17="F06",'Cases'!C8,IF(ISNUMBER(F17),F17,0)))))) | U17: =IF(N17>0,0,IF(J17<>1,0,IF(E17="Signed commitment",F17,IF(A17="F01",'Cases'!B9,IF(A17="F06",'Cases'!C9,IF(ISNUMBER(F17),F17,0)))))) | V17: =IF(N17>0,0,IF(J17<>1,0,IF(E17="Signed commitment",F17,IF(A17="F01",'Cases'!B10,IF(A17="F06",'Cases'!C10,IF(ISNUMBER(F17),F17,0))))))
