Workbook

Sheet Control Panel
A1: CONTROL PANEL — the dials (yellow). Turn a dial; every tab re-flows.
A2: ~89% grant-funded. Xero-mirror workpaper, NOT audited. Capital ask: $112K-$222K GROSS (firm quote pending). CRM pipeline is INTERNAL ONLY, not committed capital.
A4: DASHBOARD (the six numbers an investor asks for)
A5: Marginal cost/bed (selected method) | B5: ='Unit Cost'!$B$14
A6: Annual fixed block | B6: ='Assumptions & Provenance'!$B$35
A7: Breakeven beds/yr | B7: ='Unit Cost'!$B$18
A8: Operating surplus after founder time (fwd, annual) | B8: ='P&L'!$E$11
A9: Gross capex ask (low-high) | B9: ='Investment & Financing'!$B$5
A10: 36-mo cumulative cash trough | B10: ='Cashflow 36-month'!$B$20
A11: (forward surplus = contribution x beds - non-founder fixed - founder*FTE%; annual, before depreciation/interest)
A13: DIALS
A14: Dial | B14: Value | C14: Tag | D14: Notes
A15: Beds/yr (Year-1 run-rate) | B15: 120 | C15: modelled | D15: today ~100-150, NOT 500
A16: Annual volume growth % | B16: 0.6 | C16: target | D16: feeds the 36-mo ramp
A17: Price per bed | B17: 750 | C17: verified | D17: shop stretch-bed-single
A18: Build method (1-4) | B18: 1 | C18: dial | D18: 1 Buy-Kit / 2 Buy-Panels / 3 Factory / 4 Community
A19: Production location (1-3) | B19: 1 | C19: dial | D19: 1 Sydney-Defy / 2 Sunshine Coast / 3 On-Country
A20: Containerise? (0/1) | B20: 0 | C20: dial | D20: 1 = mobile container plant economics
A21: Founder FTE % (combined) | B21: 1 | C21: dial | D21: 25 / 50 / 75 / 100 — feeds P&L founder line
A22: Labour rate $/day | B22: 400 | C22: inferred | D22: promoted from hardcode (also in Assumptions)
A23: Factory throughput beds/day | B23: 5 | C23: modelled | D23: drives labour/bed
A24: Local freight $/bed | B24: 25 | C24: modelled | D24: marginal
A25: Long-haul freight $/bed | B25: 150 | C25: modelled | D25: marginal, not overhead
A26: # containerised plants (0-N) | B26: 0 | C26: dial | D26: each ~$180K, capacity ~1,000/yr
... A30: Use scenario preset? (0=manual, 1-6) | B30: 0 | C30: dial | D30: 0=use dials above; 1-6 pull a Scenarios preset
A32: Yellow = input dial. White = formula. Sanity-check all dials in Google Sheets (openpyxl does not compute formulas).

Sheet Unit Cost
A1: UNIT COST — v6 cost ladder, formula-driven off dials (no constants)
A2: Build-path direct cost/bed (materials + on-site labour; EX long-haul freight)
A3: Buy-Kit direct | B3: ='Assumptions & Provenance'!$B$11+'Assumptions & Provenance'!$B$43 | G3: ≈ 534.79 (BOM 469.79 + kit assembly/handling 65.00)
A4: Buy-Panels direct | B4: =2*'Assumptions & Provenance'!$B$16+'Assumptions & Provenance'!$B$6+'Assumptions & Provenance'!$B$7+'Assumptions & Provenance'!$B$15+'Assumptions & Provenance'!$B$17 | G4: ≈ 584.07 (400 + 27 + 93.50 + 5.24 + 58.33 self-CNC labour). Labour-add closes the gap; no separate diesel line.
A5: Factory direct | B5: ='Assumptions & Provenance'!$B$13+'Assumptions & Provenance'!$B$14+('Control Panel'!$B$22/'Control Panel'!$B$23)+'Assumptions & Provenance'!$B$6+'Assumptions & Provenance'!$B$7+'Assumptions & Provenance'!$B$15 | G5: ≈ 275.74 (55 + 15 + 80 + 27 + 93.50 + 5.24)
A6: Community direct | B6: ='Assumptions & Provenance'!$B$6+'Assumptions & Provenance'!$B$7+'Assumptions & Provenance'!$B$15+'Assumptions & Provenance'!$B$14 | G6: ≈ 140.74 (steel 27 + canvas 93.50 + hardware 5.24 + diesel 15; plastic = community-collected free, labour absorbed)
A8: Selected direct (per build method dial) | B8: =CHOOSE('Control Panel'!$B$18,$B$3,$B$4,$B$5,$B$6)
A10: Marginal cost/bed (direct + long-haul freight)
A11: Buy-Kit marginal | B11: =$B$3+'Location & Containerisation'!$B$14 | G11: ≈ 684.79 at 150 freight
A12: Buy-Panels marginal | B12: =$B$4+'Location & Containerisation'!$B$14
A13: Factory marginal | B13: =$B$5+'Location & Containerisation'!$B$14 | G13: ≈ 425.74 at 150 freight
A14: SELECTED marginal cost/bed | B14: =$B$8+'Location & Containerisation'!$B$14 | G14: <- Control Panel dashboard reads this cell ($B$14)
A16: Contribution & breakeven
A17: Contribution /bed @ price | B17: ='Control Panel'!$B$17-$B$14 | G17: ≈ price - selected marginal (Buy-Kit 65.21 / Factory 324.26 / Community 459.26)
A18: Breakeven beds/yr | B18: =ROUND('Assumptions & Provenance'!$B$35/$B$17,0) | G18: ≈ ROUND(109,500 / contribution). Factory 338 / Buy-Kit 1679 / Community 238. [Spec said ROUNDUP -> simplified to ROUND to match LOCKED values.]
A20: Idiot index — HDPE legs
A21: vs Defy shred floor (8.6x) | B21: ='Assumptions & Provenance'!$B$5/'Assumptions & Provenance'!$B$22 | G21: ≈ 344.05 / 40.00 (20kg x $2/kg Defy shred SELL price)
A22: vs raw polymer floor (~21.5x) | B22: ='Assumptions & Provenance'!$B$5/'Assumptions & Provenance'!$B$23 | G22: ≈ 344.05 / 16.00 (20kg x $0.80/kg Envirobank). The TRUE physics floor.
A23: Idiot index — steel | B23: ='Assumptions & Provenance'!$B$6/12.86 | G23: ~2.1x
A24: Idiot index — canvas | B24: ='Assumptions & Provenance'!$B$7/38.96 | G24: ~2.4x
A26: THE CAPITAL CASE: 20kg of plastic costing ~$16-40 of raw material sits inside a $344 part. That gap x volume = the investment case.

Sheet Location & Containerisation
A1: LOCATION & CONTAINERISATION — named levers as a lookup
A2: Location lookup (the method dial cannot reach these on its own)
A3: Location (1-3) | B3: Facility rent $/yr | C3: Inbound freight $/bed | D3: Outbound freight $/bed | E3: Note
A4: 1 | B4: 0 | C4: 0 | D4: 150 | E4: Sydney-Defy: buy kits, no facility
A5: 2 | B5: 54000 | C5: 30 | D5: 150 | E5: Sunshine Coast: Kirmos $4,500/mo
A6: 3 | B6: 24000 | C6: 60 | D6: 80 | E6: On-Country: feedstock in, shorter local haul
A8: SELECTED (driven by Control Panel)
A9: Selected location rent $/yr | B9: =INDEX($B$4:$B$6,MATCH('Control Panel'!$B$19,$A$4:$A$6,0))
A10: Selected inbound freight $/bed | B10: =INDEX($C$4:$C$6,MATCH('Control Panel'!$B$19,$A$4:$A$6,0))
A11: Selected outbound freight $/bed | B11: =IF('Control Panel'!$B$20=1,$D$6,INDEX($D$4:$D$6,MATCH('Control Panel'!$B$19,$A$4:$A$6,0)))
A12: Container fit-out capex (total) | B12: ='Control Panel'!$B$26*'Assumptions & Provenance'!$B$57
A13: Container capacity (beds/yr) | B13: ='Control Panel'!$B$26*1000
A14: Long-haul freight applied $/bed (effective) | B14: =$B$11
A16: Wire: Selected rent -> P&L opex; Selected outbound -> Unit Cost marginal freight.

Sheet Wages & People
A1: WAGES & PEOPLE — founder wage (FTE dial flows to P&L) + staffing-hire layer
A2: Founder line (flows to P&L — satisfies Matt's 'are the founders paid' test)
A3: Founder cost/yr (FTE-scaled) | B3: ='Control Panel'!$B$28*'Control Panel'!$B$29*'Control Panel'!$B$21 | F3: ≈ 560 x 150 x FTE%
A4: Production share/yr (touches unit cost) | B4: ='Control Panel'!$B$28*'Assumptions & Provenance'!$B$27*'Control Panel'!$B$21 | F4: ≈ 560 x 30 x FTE%
A6: FTE sensitivity strip (READS off the dial structure, not static)
A7: FTE % | B7: 25% | C7: 50% | D7: 75% | E7: 100%
A8: Founder cost/yr | B8: ='Assumptions & Provenance'!$B$28*0.25 | C8: ='Assumptions & Provenance'!$B$28*0.5 | D8: ='Assumptions & Provenance'!$B$28*0.75 | E8: ='Assumptions & Provenance'!$B$28*1.0
A9: Fwd annual surplus AFTER founder (Factory@500 ref) | B9: =(750-425.74)*500-'Assumptions & Provenance'!$B$34-'Assumptions & Provenance'!$B$28*0.25 | C9: =(750-425.74)*500-'Assumptions & Provenance'!$B$34-'Assumptions & Provenance'!$B$28*0.5 | D9: =(750-425.74)*500-'Assumptions & Provenance'!$B$34-'Assumptions & Provenance'!$B$28*0.75 | E9: =(750-425.74)*500-'Assumptions & Provenance'!$B$34-'Assumptions & Provenance'!$B$28*1.0 | F9: 100% -> -14,570 (Factory@500). Illustrative; live P&L uses the dialled method/volume.
A11: Staffing hires (Matt's investment scenario layer)
A12: Role | B12: Fully-loaded $/yr | C12: Ramp month | D12: Active months (of 36) | E12: 3-yr cost | F12: Contribution note
A13: Salesperson 1 | B13: 90000 | C13: 1 | D13: =MAX(0,37-$C$13) | E13: =$B$13*$D$13/12 | F13: +X committed beds/yr
A14: Salesperson 2 | B14: 90000 | C14: 4 | D14: =MAX(0,37-$C$14) | E14: =$B$14*$D$14/12 | F14: +X committed beds/yr
A15: Salesperson 3 | B15: 90000 | C15: 7 | D15: =MAX(0,37-$C$15) | E15: =$B$15*$D$15/12 | F15: +X committed beds/yr
A16: Head of manufacturing | B16: 130000 | C16: 1 | D16: =MAX(0,37-$C$16) | E16: =$B$16*$D$16/12 | F16: unlocks N plants / throughput
A17: Total staffing 3-yr cost | E17: =SUM($E$13:$E$16)
A18: Annual staffing run-rate (all roles active) | B18: =SUM($B$13:$B$16) | F18: ≈ 0 by default in forward P&L unless you opt staffing in (see note).
A19: Include staffing in forward P&L? (0/1) | B19: 0 | F19: 0 = founder-only base case (default). 1 = load the 3 sales + head of mfg.

Sheet Revenue
A1: REVENUE — demand-driven (beds/yr is an OUTPUT, never a free 500)
A2: Demand schedule (Year 1)
A3: Source | B3: Beds Y1 | C3: Probability | D3: Weighted beds | E3: Basis / tag
A4: Committed (signed only) | B4: 60 | C4: 1 | D4: =$B$4*$C$4 | E4: name them — verified
A5: Weighted pipeline | B5: 100 | C5: 0.4 | D5: =$B$5*$C$5 | E5: INTERNAL ONLY — not committed revenue
A6: Retail / direct | B6: 20 | C6: 0.8 | D6: =$B$6*$C$6 | E6: modelled
A7: Driven beds/yr (demand) | D7: =SUM($D$4:$D$6)
A8: Beds/yr used by model | B8: ='Control Panel'!$B$15 | E8: ≈ Control Panel beds/yr dial. Demand schedule above is the honest cross-check.
A9: Year-1 revenue (beds x price) | B9: =$B$8*'Control Panel'!$B$17 | E9: Never let the internal pipeline read as committed revenue.

Sheet P&L
A1: P&L — forward annual summary + 36-month monthly + actuals anchor
A2: FORWARD ANNUAL SUMMARY (live, off the dials)
A3: Beds/yr | C3: ='Revenue'!$B$8
A4: Revenue | C4: ='Revenue'!$B$8*'Control Panel'!$B$17
A5: Variable COGS (beds x marginal) | C5: ='Revenue'!$B$8*'Unit Cost'!$B$14
A6: Contribution | C6: =C4-C5
A7: Non-founder fixed base | C7: ='Assumptions & Provenance'!$B$34
A8: Location rent (selected) | C8: ='Location & Containerisation'!$B$9
A9: Staffing (if included) | C9: ='Wages & People'!$B$19*'Wages & People'!$B$18
A10: Surplus BEFORE founder time | C10: =C6-C7-C8-C9 | E10: fwd; Factory@500 = +69,430 (location rent 0 at Sydney)
A11: Founder cost (FTE-scaled) | C11: ='Wages & People'!$B$3 | D11: Surplus AFTER founder -> | E11: =C10-C11
A12: (Control Panel dashboard 'surplus after founder' reads $E$11)
A14: ACTUALS ANCHOR — Xero workpaper, NOT audited (the P0-1 waterfall)
A15: Revenue received (cumulative) | C15: ='Assumptions & Provenance'!$B$46
A16: less Goods expenses (single cash basis) | C16: =-'Assumptions & Provenance'!$B$48
A17: ≈ Operating surplus BEFORE founder time | C17: =C15+C16 | E17: ≈ 340,585 (ties exactly: 649,710.79 - 309,126)
A18: less founder time (FTE-scaled) | C18: =-'Wages & People'!$B$3
A19: ≈ Operating surplus AFTER founder time | C19: =C17+C18 | E19: ≈ 256,585 at 100% FTE (NOT 151,585 — that endpoint was undocumented).
A20: Revenue billed (memo) | C20: ='Assumptions & Provenance'!$B$45
A21: AR Rotary (memo) | C21: ='Assumptions & Provenance'!$B$47
A23: 36-MONTH MONTHLY P&L (drives Balance Sheet + Cashflow)
A24: Month | B24: M1 | C24: M2 | D24: M3 | E24: M4 | F24: M5 | G24: M6 | H24: M7 | I24: M8 | J24: M9 | K24: M10 | L24: M11 | M24: M12 | N24: M13 | O24: M14 | P24: M15 | Q24: M16 | R24: M17 | S24: M18 | T24: M19 | U24: M20 | V24: M21 | W24: M22 | X24: M23 | Y24: M24 | Z24: M25 | AA24: M26 | AB24: M27 | AC24: M28 | AD24: M29 | AE24: M30 | AF24: M31 | AG24: M32 | AH24: M33 | AI24: M34 | AJ24: M35 | AK24: M36
A25: Beds (month) | B25: =('Revenue'!$B$8/12)*(1+'Control Panel'!$B$16)^INT((1-1)/12) | C25: =('Revenue'!$B$8/12)*(1+'Control Panel'!$B$16)^INT((2-1)/12) | D25: =('Revenue'!$B$8/12)*(1+'Control Panel'!$B$16)^INT((3-1)/12) | E25: =('Revenue'!$B$8/12)*(1+'Control Panel'!$B$16)^INT((4-1)/12) | F25: =('Revenue'!$B$8/12)*(1+'Control Panel'!$B$16)^INT((5-1)/12) | G25: =('Revenue'!$B$8/12)*(1+'Control Panel'!$B$16)^INT((6-1)/12) | H25: =('Revenue'!$B$8/12)*(1+'Control Panel'!$B$16)^INT((7-1)/12) | I25: =('Revenue'!$B$8/12)*(1+'Control Panel'!$B$16)^INT((8-1)/12) | J25: =('Revenue'!$B$8/12)*(1+'Control Panel'!$B$16)^INT((9-1)/12) | K25: =('Revenue'!$B$8/12)*(1+'Control Panel'!$B$16)^INT((10-1)/12) | L25: =('Revenue'!$B$8/12)*(1+'Control Panel'!$B$16)^INT((11-1)/12) | M25: =('Revenue'!$B$8/12)*(1+'Control Panel'!$B$16)^INT((12-1)/12) | N25: =('Revenue'!$B$8/12)*(1+'Control Panel'!$B$16)^INT((13-1)/12) | O25: =('Revenue'!$B$8/12)*(1+'Control Panel'!$B$16)^INT((14-1)/12) | P25: =('Revenue'!$B$8/12)*(1+'Control Panel'!$B$16)^INT((15-1)/12) | Q25: =('Revenue'!$B$8/12)*(1+'Control Panel'!$B$16)^INT((16-1)/12) | R25: =('Revenue'!$B$8/12)*(1+'Control Panel'!$B$16)^INT((17-1)/12) | S25: =('Revenue'!$B$8/12)*(1+'Control Panel'!$B$16)^INT((18-1)/12) | T25: =('Revenue'!$B$8/12)*(1+'Control Panel'!$B$16)^INT((19-1)/12) | U25: =('Revenue'!$B$8/12)*(1+'Control Panel'!$B$16)^INT((20-1)/12) | V25: =('Revenue'!$B$8/12)*(1+'Control Panel'!$B$16)^INT((21-1)/12) | W25: =('Revenue'!$B$8/12)*(1+'Control Panel'!$B$16)^INT((22-1)/12) | X25: =('Revenue'!$B$8/12)*(1+'Control Panel'!$B$16)^INT((23-1)/12) | Y25: =('Revenue'!$B$8/12)*(1+'Control Panel'!$B$16)^INT((24-1)/12) | Z25: =('Revenue'!$B$8/12)*(1+'Control Panel'!$B$16)^INT((25-1)/12) | AA25: =('Revenue'!$B$8/12)*(1+'Control Panel'!$B$16)^INT((26-1)/12) | AB25: =('Revenue'!$B$8/12)*(1+'Control Panel'!$B$16)^INT((27-1)/12) | AC25: =('Revenue'!$B$8/12)*(1+'Control Panel'!$B$16)^INT((28-1)/12) | AD25: =('Revenue'!$B$8/12)*(1+'Control Panel'!$B$16)^INT((29-1)/12) | AE25: =('Revenue'!$B$8/12)*(1+'Control Panel'!$B$16)^INT((30-1)/12) | AF25: =('Revenue'!$B$8/12)*(1+'Control Panel'!$B$16)^INT((31-1)/12) | AG25: =('Revenue'!$B$8/12)*(1+'Control Panel'!$B$16)^INT((32-1)/12) | AH25: =('Revenue'!$B$8/12)*(1+'Control Panel'!$B$16)^INT((33-1)/12) | AI25: =('Revenue'!$B$8/12)*(1+'Control Panel'!$B$16)^INT((34-1)/12) | AJ25: =('Revenue'!$B$8/12)*(1+'Control Panel'!$B$16)^INT((35-1)/12) | AK25: =('Revenue'!$B$8/12)*(1+'Control Panel'!$B$16)^INT((36-1)/12)
A26: Revenue | B26: =B25*'Control Panel'!$B$17 | C26: =C25*'Control Panel'!$B$17 | D26: =D25*'Control Panel'!$B$17 | E26: =E25*'Control Panel'!$B$17 | F26: =F25*'Control Panel'!$B$17 | G26: =G25*'Control Panel'!$B$17 | H26: =H25*'Control Panel'!$B$17 | I26: =I25*'Control Panel'!$B$17 | ... AK26: =AK25*'Control Panel'!$B$17
A27: COGS (variable) | B27: =B25*'Unit Cost'!$B$14 | C27: =C25*'Unit Cost'!$B$14 | D27: =D25*'Unit Cost'!$B$14 | E27: =E25*'Unit Cost'!$B$14 | F27: =F25*'Unit Cost'!$B$14 | G27: =G25*'Unit Cost'!$B$14 | H27: =H25*'Unit Cost'!$B$14 | I27: =I25*'Unit Cost'!$B$14 | ... AK27: =AK25*'Unit Cost'!$B$14
A28: Gross profit | B28: =B26-B27 | C28: =C26-C27 | D28: =D26-D27 | E28: =E26-E27 | F28: =F26-F27 | G28: =G26-G27 | H28: =H26-H27 | I28: =I26-I27 | ... AK28: =AK26-AK27
A29: Opex (fixed+rent+staffing)/mo | B29: =('Assumptions & Provenance'!$B$34+'Location & Containerisation'!$B$9+'Wages & People'!$B$19*'Wages & People'!$B$18)/12 | C29: =('Assumptions & Provenance'!$B$34+'Location & Containerisation'!$B$9+'Wages & People'!$B$19*'Wages & People'!$B$18)/12 | D29: =('Assumptions & Provenance'!$B$34+'Location & Containerisation'!$B$9+'Wages & People'!$B$19*'Wages & People'!$B$18)/12 | E29: =('Assumptions & Provenance'!$B$34+'Location & Containerisation'!$B$9+'Wages & People'!$B$19*'Wages & People'!$B$18)/12 | F29: =('Assumptions & Provenance'!$B$34+'Location & Containerisation'!$B$9+'Wages & People'!$B$19*'Wages & People'!$B$18)/12 | G29: =('Assumptions & Provenance'!$B$34+'Location & Containerisation'!$B$9+'Wages & People'!$B$19*'Wages & People'!$B$18)/12 | H29: =('Assumptions & Provenance'!$B$34+'Location & Containerisation'!$B$9+'Wages & People'!$B$19*'Wages & People'!$B$18)/12 | I29: =('Assumptions & Provenance'!$B$34+'Location & Containerisation'!$B$9+'Wages & People'!$B$19*'Wages & People'!$B$18)/12 | ... AK29: =('Assumptions & Provenance'!$B$34+'Location & Containerisation'!$B$9+'Wages & People'!$B$19*'Wages & People'!$B$18)/12
A30: Founder cost /mo | B30: ='Wages & People'!$B$3/12 | C30: ='Wages & People'!$B$3/12 | D30: ='Wages & People'!$B$3/12 | E30: ='Wages & People'!$B$3/12 | F30: ='Wages & People'!$B$3/12 | G30: ='Wages & People'!$B$3/12 | H30: ='Wages & People'!$B$3/12 | I30: ='Wages & People'!$B$3/12 | ... AK30: ='Wages & People'!$B$3/12
A31: EBITDA | B31: =B28-B29-B30 | C31: =C28-C29-C30 | D31: =D28-D29-D30 | E31: =E28-E29-E30 | F31: =F28-F29-F30 | G31: =G28-G29-G30 | H31: =H28-H29-H30 | I31: =I28-I29-I30 | ... AK31: =AK28-AK29-AK30
A32: Depreciation | B32: ='Investment & Financing'!$B$22 | C32: ='Investment & Financing'!$B$22 | D32: ='Investment & Financing'!$B$22 | E32: ='Investment & Financing'!$B$22 | F32: ='Investment & Financing'!$B$22 | G32: ='Investment & Financing'!$B$22 | H32: ='Investment & Financing'!$B$22 | I32: ='Investment & Financing'!$B$22 | ... AK32: ='Investment & Financing'!$B$22
A33: Interest (SEFA) | B33: ='Investment & Financing'!$B$27 | C33: ='Investment & Financing'!$B$27 | D33: ='Investment & Financing'!$B$27 | E33: ='Investment & Financing'!$B$27 | F33: ='Investment & Financing'!$B$27 | G33: ='Investment & Financing'!$B$27 | H33: ='Investment & Financing'!$B$27 | I33: ='Investment & Financing'!$B$27 | ... AK33: ='Investment & Financing'!$B$27
A34: Net profit | B34: =B31-B32-B33 | C34: =C31-C32-C33 | D34: =D31-D32-D33 | E34: =E31-E32-E33 | F34: =F31-F32-F33 | G34: =G31-G32-G33 | H34: =H31-H32-H33 | I34: =I31-I32-I33 | ... AK34: =AK31-AK32-AK33
A35: Cumulative net profit (-> equity) | B35: =B34 | C35: =B35+C34 | D35: =C35+D34 | E35: =D35+E34 | F35: =E35+F34 | G35: =F35+G34 | H35: =G35+H34 | I35: =H35+I34 | J35: =I35+J34 | ... AK35: =AJ35+AK34

Sheet Balance Sheet & WC
A1: BALANCE SHEET & WC — must balance. BALANCE CHECK reads 0 every period.
A2: Monthly balance sheet (ties to P&L cumulative net + Cashflow closing cash)
A3: Month | B3: M1 | C3: M2 | D3: M3 | E3: M4 | F3: M5 | G3: M6 | H3: M7 | I3: M8 | J3: M9 | K3: M10 | L3: M11 | M3: M12 | N3: M13 | O3: M14 | P3: M15 | Q3: M16 | R3: M17 | S3: M18 | T3: M19 | U3: M20 | V3: M21 | W3: M22 | X3: M23 | Y3: M24 | Z3: M25 | AA3: M26 | AB3: M27 | AC3: M28 | AD3: M29 | AE3: M30 | AF3: M31 | AG3: M32 | AH3: M33 | AI3: M34 | AJ3: M35 | AK3: M36
A4: Cash (= Cashflow closing) | B4: ='Cashflow 36-month'!B13 | C4: ='Cashflow 36-month'!C13 | D4: ='Cashflow 36-month'!D13 | E4: ='Cashflow 36-month'!E13 | F4: ='Cashflow 36-month'!F13 | G4: ='Cashflow 36-month'!G13 | H4: ='Cashflow 36-month'!H13 | I4: ='Cashflow 36-month'!I13 | ... AK4: ='Cashflow 36-month'!AK13
A5: Accounts receivable (Rotary) | B5: ='Assumptions & Provenance'!$B$47 | C5: ='Assumptions & Provenance'!$B$47 | D5: ='Assumptions & Provenance'!$B$47 | E5: ='Assumptions & Provenance'!$B$47 | F5: ='Assumptions & Provenance'!$B$47 | G5: ='Assumptions & Provenance'!$B$47 | H5: ='Assumptions & Provenance'!$B$47 | I5: ='Assumptions & Provenance'!$B$47 | ... AK5: ='Assumptions & Provenance'!$B$47
A6: Inventory (seed) | B6: =$B$24 | C6: =$B$24 | D6: =$B$24 | E6: =$B$24 | F6: =$B$24 | G6: =$B$24 | H6: =$B$24 | I6: =$B$24 | ... AK6: =$B$24
A7: PP&E (capex - accum dep) | B7: =('Investment & Financing'!$B$7+'Assumptions & Provenance'!$B$49)-'Investment & Financing'!$B$22*1 | C7: =('Investment & Financing'!$B$7+'Assumptions & Provenance'!$B$49)-'Investment & Financing'!$B$22*2 | D7: =('Investment & Financing'!$B$7+'Assumptions & Provenance'!$B$49)-'Investment & Financing'!$B$22*3 | E7: =('Investment & Financing'!$B$7+'Assumptions & Provenance'!$B$49)-'Investment & Financing'!$B$22*4 | F7: =('Investment & Financing'!$B$7+'Assumptions & Provenance'!$B$49)-'Investment & Financing'!$B$22*5 | G7: =('Investment & Financing'!$B$7+'Assumptions & Provenance'!$B$49)-'Investment & Financing'!$B$22*6 | H7: =('Investment & Financing'!$B$7+'Assumptions & Provenance'!$B$49)-'Investment & Financing'!$B$22*7 | I7: =('Investment & Financing'!$B$7+'Assumptions & Provenance'!$B$49)-'Investment & Financing'!$B$22*8 | J7: =('Investment & Financing'!$B$7+'Assumptions & Provenance'!$B$49)-'Investment & Financing'!$B$22*9 | K7: =('Investment & Financing'!$B$7+'Assumptions & Provenance'!$B$49)-'Investment & Financing'!$B$22*10 | L7: =('Investment & Financing'!$B$7+'Assumptions & Provenance'!$B$49)-'Investment & Financing'!$B$22*11 | M7: =('Investment & Financing'!$B$7+'Assumptions & Provenance'!$B$49)-'Investment & Financing'!$B$22*12 | N7: =('Investment & Financing'!$B$7+'Assumptions & Provenance'!$B$49)-'Investment & Financing'!$B$22*13 | O7: =('Investment & Financing'!$B$7+'Assumptions & Provenance'!$B$49)-'Investment & Financing'!$B$22*14 | P7: =('Investment & Financing'!$B$7+'Assumptions & Provenance'!$B$49)-'Investment & Financing'!$B$22*15 | Q7: =('Investment & Financing'!$B$7+'Assumptions & Provenance'!$B$49)-'Investment & Financing'!$B$22*16 | R7: =('Investment & Financing'!$B$7+'Assumptions & Provenance'!$B$49)-'Investment & Financing'!$B$22*17 | S7: =('Investment & Financing'!$B$7+'Assumptions & Provenance'!$B$49)-'Investment & Financing'!$B$22*18 | T7: =('Investment & Financing'!$B$7+'Assumptions & Provenance'!$B$49)-'Investment & Financing'!$B$22*19 | U7: =('Investment & Financing'!$B$7+'Assumptions & Provenance'!$B$49)-'Investment & Financing'!$B$22*20 | V7: =('Investment & Financing'!$B$7+'Assumptions & Provenance'!$B$49)-'Investment & Financing'!$B$22*21 | W7: =('Investment & Financing'!$B$7+'Assumptions & Provenance'!$B$49)-'Investment & Financing'!$B$22*22 | X7: =('Investment & Financing'!$B$7+'Assumptions & Provenance'!$B$49)-'Investment & Financing'!$B$22*23 | Y7: =('Investment & Financing'!$B$7+'Assumptions & Provenance'!$B$49)-'Investment & Financing'!$B$22*24 | Z7: =('Investment & Financing'!$B$7+'Assumptions & Provenance'!$B$49)-'Investment & Financing'!$B$22*25 | AA7: =('Investment & Financing'!$B$7+'Assumptions & Provenance'!$B$49)-'Investment & Financing'!$B$22*26 | AB7: =('Investment & Financing'!$B$7+'Assumptions & Provenance'!$B$49)-'Investment & Financing'!$B$22*27 | AC7: =('Investment & Financing'!$B$7+'Assumptions & Provenance'!$B$49)-'Investment & Financing'!$B$22*28 | AD7: =('Investment & Financing'!$B$7+'Assumptions & Provenance'!$B$49)-'Investment & Financing'!$B$22*29 | AE7: =('Investment & Financing'!$B$7+'Assumptions & Provenance'!$B$49)-'Investment & Financing'!$B$22*30 | AF7: =('Investment & Financing'!$B$7+'Assumptions & Provenance'!$B$49)-'Investment & Financing'!$B$22*31 | AG7: =('Investment & Financing'!$B$7+'Assumptions & Provenance'!$B$49)-'Investment & Financing'!$B$22*32 | AH7: =('Investment & Financing'!$B$7+'Assumptions & Provenance'!$B$49)-'Investment & Financing'!$B$22*33 | AI7: =('Investment & Financing'!$B$7+'Assumptions & Provenance'!$B$49)-'Investment & Financing'!$B$22*34 | AJ7: =('Investment & Financing'!$B$7+'Assumptions & Provenance'!$B$49)-'Investment & Financing'!$B$22*35 | AK7: =('Investment & Financing'!$B$7+'Assumptions & Provenance'!$B$49)-'Investment & Financing'!$B$22*36
A8: TOTAL ASSETS | B8: =SUM(B4:B7) | C8: =SUM(C4:C7) | D8: =SUM(D4:D7) | E8: =SUM(E4:E7) | F8: =SUM(F4:F7) | G8: =SUM(G4:G7) | H8: =SUM(H4:H7) | I8: =SUM(I4:I7) | ... AK8: =SUM(AK4:AK7)
A10: Accounts payable | B10: ='Assumptions & Provenance'!$B$50 | C10: ='Assumptions & Provenance'!$B$50 | D10: ='Assumptions & Provenance'!$B$50 | E10: ='Assumptions & Provenance'!$B$50 | F10: ='Assumptions & Provenance'!$B$50 | G10: ='Assumptions & Provenance'!$B$50 | H10: ='Assumptions & Provenance'!$B$50 | I10: ='Assumptions & Provenance'!$B$50 | ... AK10: ='Assumptions & Provenance'!$B$50
A11: GST payable | B11: ='Assumptions & Provenance'!$B$51 | C11: ='Assumptions & Provenance'!$B$51 | D11: ='Assumptions & Provenance'!$B$51 | E11: ='Assumptions & Provenance'!$B$51 | F11: ='Assumptions & Provenance'!$B$51 | G11: ='Assumptions & Provenance'!$B$51 | H11: ='Assumptions & Provenance'!$B$51 | I11: ='Assumptions & Provenance'!$B$51 | ... AK11: ='Assumptions & Provenance'!$B$51
A12: Debt (SEFA outstanding) | B12: =IF(1>='Investment & Financing'!$B$25,'Investment & Financing'!$B$26-'Investment & Financing'!$B$28*MAX(0,1-'Investment & Financing'!$B$25),0) | C12: =IF(2>='Investment & Financing'!$B$25,'Investment & Financing'!$B$26-'Investment & Financing'!$B$28*MAX(0,2-'Investment & Financing'!$B$25),0) | D12: =IF(3>='Investment & Financing'!$B$25,'Investment & Financing'!$B$26-'Investment & Financing'!$B$28*MAX(0,3-'Investment & Financing'!$B$25),0) | E12: =IF(4>='Investment & Financing'!$B$25,'Investment & Financing'!$B$26-'Investment & Financing'!$B$28*MAX(0,4-'Investment & Financing'!$B$25),0) | F12: =IF(5>='Investment & Financing'!$B$25,'Investment & Financing'!$B$26-'Investment & Financing'!$B$28*MAX(0,5-'Investment & Financing'!$B$25),0) | G12: =IF(6>='Investment & Financing'!$B$25,'Investment & Financing'!$B$26-'Investment & Financing'!$B$28*MAX(0,6-'Investment & Financing'!$B$25),0) | H12: =IF(7>='Investment & Financing'!$B$25,'Investment & Financing'!$B$26-'Investment & Financing'!$B$28*MAX(0,7-'Investment & Financing'!$B$25),0) | I12: =IF(8>='Investment & Financing'!$B$25,'Investment & Financing'!$B$26-'Investment & Financing'!$B$28*MAX(0,8-'Investment & Financing'!$B$25),0) | J12: =IF(9>='Investment & Financing'!$B$25,'Investment & Financing'!$B$26-'Investment & Financing'!$B$28*MAX(0,9-'Investment & Financing'!$B$25),0) | K12: =IF(10>='Investment & Financing'!$B$25,'Investment & Financing'!$B$26-'Investment & Financing'!$B$28*MAX(0,10-'Investment & Financing'!$B$25),0) | L12: =IF(11>='Investment & Financing'!$B$25,'Investment & Financing'!$B$26-'Investment & Financing'!$B$28*MAX(0,11-'Investment & Financing'!$B$25),0) | M12: =IF(12>='Investment & Financing'!$B$25,'Investment & Financing'!$B$26-'Investment & Financing'!$B$28*MAX(0,12-'Investment & Financing'!$B$25),0) | N12: =IF(13>='Investment & Financing'!$B$25,'Investment & Financing'!$B$26-'Investment & Financing'!$B$28*MAX(0,13-'Investment & Financing'!$B$25),0) | O12: =IF(14>='Investment & Financing'!$B$25,'Investment & Financing'!$B$26-'Investment & Financing'!$B$28*MAX(0,14-'Investment & Financing'!$B$25),0) | P12: =IF(15>='Investment & Financing'!$B$25,'Investment & Financing'!$B$26-'Investment & Financing'!$B$28*MAX(0,15-'Investment & Financing'!$B$25),0) | Q12: =IF(16>='Investment & Financing'!$B$25,'Investment & Financing'!$B$26-'Investment & Financing'!$B$28*MAX(0,16-'Investment & Financing'!$B$25),0) | R12: =IF(17>='Investment & Financing'!$B$25,'Investment & Financing'!$B$26-'Investment & Financing'!$B$28*MAX(0,17-'Investment & Financing'!$B$25),0) | S12: =IF(18>='Investment & Financing'!$B$25,'Investment & Financing'!$B$26-'Investment & Financing'!$B$28*MAX(0,18-'Investment & Financing'!$B$25),0) | T12: =IF(19>='Investment & Financing'!$B$25,'Investment & Financing'!$B$26-'Investment & Financing'!$B$28*MAX(0,19-'Investment & Financing'!$B$25),0) | U12: =IF(20>='Investment & Financing'!$B$25,'Investment & Financing'!$B$26-'Investment & Financing'!$B$28*MAX(0,20-'Investment & Financing'!$B$25),0) | V12: =IF(21>='Investment & Financing'!$B$25,'Investment & Financing'!$B$26-'Investment & Financing'!$B$28*MAX(0,21-'Investment & Financing'!$B$25),0) | W12: =IF(22>='Investment & Financing'!$B$25,'Investment & Financing'!$B$26-'Investment & Financing'!$B$28*MAX(0,22-'Investment & Financing'!$B$25),0) | X12: =IF(23>='Investment & Financing'!$B$25,'Investment & Financing'!$B$26-'Investment & Financing'!$B$28*MAX(0,23-'Investment & Financing'!$B$25),0) | Y12: =IF(24>='Investment & Financing'!$B$25,'Investment & Financing'!$B$26-'Investment & Financing'!$B$28*MAX(0,24-'Investment & Financing'!$B$25),0) | Z12: =IF(25>='Investment & Financing'!$B$25,'Investment & Financing'!$B$26-'Investment & Financing'!$B$28*MAX(0,25-'Investment & Financing'!$B$25),0) | AA12: =IF(26>='Investment & Financing'!$B$25,'Investment & Financing'!$B$26-'Investment & Financing'!$B$28*MAX(0,26-'Investment & Financing'!$B$25),0) | AB12: =IF(27>='Investment & Financing'!$B$25,'Investment & Financing'!$B$26-'Investment & Financing'!$B$28*MAX(0,27-'Investment & Financing'!$B$25),0) | AC12: =IF(28>='Investment & Financing'!$B$25,'Investment & Financing'!$B$26-'Investment & Financing'!$B$28*MAX(0,28-'Investment & Financing'!$B$25),0) | AD12: =IF(29>='Investment & Financing'!$B$25,'Investment & Financing'!$B$26-'Investment & Financing'!$B$28*MAX(0,29-'Investment & Financing'!$B$25),0) | AE12: =IF(30>='Investment & Financing'!$B$25,'Investment & Financing'!$B$26-'Investment & Financing'!$B$28*MAX(0,30-'Investment & Financing'!$B$25),0) | AF12: =IF(31>='Investment & Financing'!$B$25,'Investment & Financing'!$B$26-'Investment & Financing'!$B$28*MAX(0,31-'Investment & Financing'!$B$25),0) | AG12: =IF(32>='Investment & Financing'!$B$25,'Investment & Financing'!$B$26-'Investment & Financing'!$B$28*MAX(0,32-'Investment & Financing'!$B$25),0) | AH12: =IF(33>='Investment & Financing'!$B$25,'Investment & Financing'!$B$26-'Investment & Financing'!$B$28*MAX(0,33-'Investment & Financing'!$B$25),0) | AI12: =IF(34>='Investment & Financing'!$B$25,'Investment & Financing'!$B$26-'Investment & Financing'!$B$28*MAX(0,34-'Investment & Financing'!$B$25),0) | AJ12: =IF(35>='Investment & Financing'!$B$25,'Investment & Financing'!$B$26-'Investment & Financing'!$B$28*MAX(0,35-'Investment & Financing'!$B$25),0) | AK12: =IF(36>='Investment & Financing'!$B$25,'Investment & Financing'!$B$26-'Investment & Financing'!$B$28*MAX(0,36-'Investment & Financing'!$B$25),0)
A13: TOTAL LIABILITIES | B13: =SUM(B10:B12) | C13: =SUM(C10:C12) | D13: =SUM(D10:D12) | E13: =SUM(E10:E12) | F13: =SUM(F10:F12) | G13: =SUM(G10:G12) | H13: =SUM(H10:H12) | I13: =SUM(I10:I12) | ... AK13: =SUM(AK10:AK12)
A15: Opening equity | B15: =$B$23 | C15: =$B$23 | D15: =$B$23 | E15: =$B$23 | F15: =$B$23 | G15: =$B$23 | H15: =$B$23 | I15: =$B$23 | ... AK15: =$B$23
A16: Retained earnings (cum P&L net) | B16: ='P&L'!B35 | C16: ='P&L'!C35 | D16: ='P&L'!D35 | E16: ='P&L'!E35 | F16: ='P&L'!F35 | G16: ='P&L'!G35 | H16: ='P&L'!H35 | I16: ='P&L'!I35 | ... AK16: ='P&L'!AK35
A17: Capital injections (grants/equity) | B17: =0 | C17: =0 | D17: =0 | E17: =0 | F17: =0 | G17: =0 | H17: =0 | I17: =0 | ... AK17: =0
A18: TOTAL EQUITY | B18: =B15+B16+B17 | C18: =C15+C16+C17 | D18: =D15+D16+D17 | E18: =E15+E16+E17 | F18: =F15+F16+F17 | G18: =G15+G16+G17 | H18: =H15+H16+H17 | I18: =I15+I16+I17 | ... AK18: =AK15+AK16+AK17
A20: BALANCE CHECK (TA - TL - TE) | B20: =B8-B13-B18 | C20: =C8-C13-C18 | D20: =D8-D13-D18 | E20: =E8-E13-E18 | F20: =F8-F13-F18 | G20: =G8-G13-G18 | H20: =H8-H13-H18 | I20: =I8-I13-I18 | ... AK20: =AK8-AK13-AK18
A22: Opening equity plug (so M1 opening balances)
A23: Opening equity = | B23: ='Control Panel'!$B$27+'Assumptions & Provenance'!$B$47+50000+'Assumptions & Provenance'!$B$49-'Assumptions & Provenance'!$B$50-'Assumptions & Provenance'!$B$51
A24: Seed inventory (beds-in-stock x marginal, placeholder $50K) | B24: 50000 | D24: Adjust to real standing inventory.
A26: BALANCE CHECK must read 0 in every month. The check cell for M1 is B20 (then C20..AK20).

Sheet Cashflow 36-month
A1: CASHFLOW 36-month — derived from P&L (not hand-keyed). Closing cash -> BS.
A2: Cumulative cash trough (the headline)
A4: Month | B4: M1 | C4: M2 | D4: M3 | E4: M4 | F4: M5 | G4: M6 | H4: M7 | I4: M8 | J4: M9 | K4: M10 | L4: M11 | M4: M12 | N4: M13 | O4: M14 | P4: M15 | Q4: M16 | R4: M17 | S4: M18 | T4: M19 | U4: M20 | V4: M21 | W4: M22 | X4: M23 | Y4: M24 | Z4: M25 | AA4: M26 | AB4: M27 | AC4: M28 | AD4: M29 | AE4: M30 | AF4: M31 | AG4: M32 | AH4: M33 | AI4: M34 | AJ4: M35 | AK4: M36
A5: Opening cash | B5: ='Control Panel'!$B$27 | C5: =B13 | D5: =C13 | E5: =D13 | F5: =E13 | G5: =F13 | H5: =G13 | I5: =H13 | J5: =I13 | ... AK5: =AJ13
A6: Net profit (P&L) | B6: ='P&L'!B34 | C6: ='P&L'!C34 | D6: ='P&L'!D34 | E6: ='P&L'!E34 | F6: ='P&L'!F34 | G6: ='P&L'!G34 | H6: ='P&L'!H34 | I6: ='P&L'!I34 | ... AK6: ='P&L'!AK34
A7: add back depreciation | B7: ='P&L'!B32 | C7: ='P&L'!C32 | D7: ='P&L'!D32 | E7: ='P&L'!E32 | F7: ='P&L'!F32 | G7: ='P&L'!G32 | H7: ='P&L'!H32 | I7: ='P&L'!I32 | ... AK7: ='P&L'!AK32
A8: working-capital movements | B8: =0 | C8: =0 | D8: =0 | E8: =0 | F8: =0 | G8: =0 | H8: =0 | I8: =0 | ... AK8: =0
A9: Operating cash flow | B9: =B6+B7+B8 | C9: =C6+C7+C8 | D9: =D6+D7+D8 | E9: =E6+E7+E8 | F9: =F6+F7+F8 | G9: =G6+G7+G8 | H9: =H6+H7+H8 | I9: =I6+I7+I8 | ... AK9: =AK6+AK7+AK8
A10: Investing (capex draw) | B10: =-'Investment & Financing'!$B$7 | C10: =0 | D10: =0 | E10: =0 | F10: =0 | G10: =0 | H10: =0 | I10: =0 | J10: =0 | ... AK10: =0
A11: Financing (draw - repay) | B11: =IF(1='Investment & Financing'!$B$25,'Investment & Financing'!$B$26,0)-IF(1>'Investment & Financing'!$B$25,'Investment & Financing'!$B$28,0) | C11: =IF(2='Investment & Financing'!$B$25,'Investment & Financing'!$B$26,0)-IF(2>'Investment & Financing'!$B$25,'Investment & Financing'!$B$28,0) | D11: =IF(3='Investment & Financing'!$B$25,'Investment & Financing'!$B$26,0)-IF(3>'Investment & Financing'!$B$25,'Investment & Financing'!$B$28,0) | E11: =IF(4='Investment & Financing'!$B$25,'Investment & Financing'!$B$26,0)-IF(4>'Investment & Financing'!$B$25,'Investment & Financing'!$B$28,0) | F11: =IF(5='Investment & Financing'!$B$25,'Investment & Financing'!$B$26,0)-IF(5>'Investment & Financing'!$B$25,'Investment & Financing'!$B$28,0) | G11: =IF(6='Investment & Financing'!$B$25,'Investment & Financing'!$B$26,0)-IF(6>'Investment & Financing'!$B$25,'Investment & Financing'!$B$28,0) | H11: =IF(7='Investment & Financing'!$B$25,'Investment & Financing'!$B$26,0)-IF(7>'Investment & Financing'!$B$25,'Investment & Financing'!$B$28,0) | I11: =IF(8='Investment & Financing'!$B$25,'Investment & Financing'!$B$26,0)-IF(8>'Investment & Financing'!$B$25,'Investment & Financing'!$B$28,0) | J11: =IF(9='Investment & Financing'!$B$25,'Investment & Financing'!$B$26,0)-IF(9>'Investment & Financing'!$B$25,'Investment & Financing'!$B$28,0) | K11: =IF(10='Investment & Financing'!$B$25,'Investment & Financing'!$B$26,0)-IF(10>'Investment & Financing'!$B$25,'Investment & Financing'!$B$28,0) | L11: =IF(11='Investment & Financing'!$B$25,'Investment & Financing'!$B$26,0)-IF(11>'Investment & Financing'!$B$25,'Investment & Financing'!$B$28,0) | M11: =IF(12='Investment & Financing'!$B$25,'Investment & Financing'!$B$26,0)-IF(12>'Investment & Financing'!$B$25,'Investment & Financing'!$B$28,0) | N11: =IF(13='Investment & Financing'!$B$25,'Investment & Financing'!$B$26,0)-IF(13>'Investment & Financing'!$B$25,'Investment & Financing'!$B$28,0) | O11: =IF(14='Investment & Financing'!$B$25,'Investment & Financing'!$B$26,0)-IF(14>'Investment & Financing'!$B$25,'Investment & Financing'!$B$28,0) | P11: =IF(15='Investment & Financing'!$B$25,'Investment & Financing'!$B$26,0)-IF(15>'Investment & Financing'!$B$25,'Investment & Financing'!$B$28,0) | Q11: =IF(16='Investment & Financing'!$B$25,'Investment & Financing'!$B$26,0)-IF(16>'Investment & Financing'!$B$25,'Investment & Financing'!$B$28,0) | R11: =IF(17='Investment & Financing'!$B$25,'Investment & Financing'!$B$26,0)-IF(17>'Investment & Financing'!$B$25,'Investment & Financing'!$B$28,0) | S11: =IF(18='Investment & Financing'!$B$25,'Investment & Financing'!$B$26,0)-IF(18>'Investment & Financing'!$B$25,'Investment & Financing'!$B$28,0) | T11: =IF(19='Investment & Financing'!$B$25,'Investment & Financing'!$B$26,0)-IF(19>'Investment & Financing'!$B$25,'Investment & Financing'!$B$28,0) | U11: =IF(20='Investment & Financing'!$B$25,'Investment & Financing'!$B$26,0)-IF(20>'Investment & Financing'!$B$25,'Investment & Financing'!$B$28,0) | V11: =IF(21='Investment & Financing'!$B$25,'Investment & Financing'!$B$26,0)-IF(21>'Investment & Financing'!$B$25,'Investment & Financing'!$B$28,0) | W11: =IF(22='Investment & Financing'!$B$25,'Investment & Financing'!$B$26,0)-IF(22>'Investment & Financing'!$B$25,'Investment & Financing'!$B$28,0) | X11: =IF(23='Investment & Financing'!$B$25,'Investment & Financing'!$B$26,0)-IF(23>'Investment & Financing'!$B$25,'Investment & Financing'!$B$28,0) | Y11: =IF(24='Investment & Financing'!$B$25,'Investment & Financing'!$B$26,0)-IF(24>'Investment & Financing'!$B$25,'Investment & Financing'!$B$28,0) | Z11: =IF(25='Investment & Financing'!$B$25,'Investment & Financing'!$B$26,0)-IF(25>'Investment & Financing'!$B$25,'Investment & Financing'!$B$28,0) | AA11: =IF(26='Investment & Financing'!$B$25,'Investment & Financing'!$B$26,0)-IF(26>'Investment & Financing'!$B$25,'Investment & Financing'!$B$28,0) | AB11: =IF(27='Investment & Financing'!$B$25,'Investment & Financing'!$B$26,0)-IF(27>'Investment & Financing'!$B$25,'Investment & Financing'!$B$28,0) | AC11: =IF(28='Investment & Financing'!$B$25,'Investment & Financing'!$B$26,0)-IF(28>'Investment & Financing'!$B$25,'Investment & Financing'!$B$28,0) | AD11: =IF(29='Investment & Financing'!$B$25,'Investment & Financing'!$B$26,0)-IF(29>'Investment & Financing'!$B$25,'Investment & Financing'!$B$28,0) | AE11: =IF(30='Investment & Financing'!$B$25,'Investment & Financing'!$B$26,0)-IF(30>'Investment & Financing'!$B$25,'Investment & Financing'!$B$28,0) | AF11: =IF(31='Investment & Financing'!$B$25,'Investment & Financing'!$B$26,0)-IF(31>'Investment & Financing'!$B$25,'Investment & Financing'!$B$28,0) | AG11: =IF(32='Investment & Financing'!$B$25,'Investment & Financing'!$B$26,0)-IF(32>'Investment & Financing'!$B$25,'Investment & Financing'!$B$28,0) | AH11: =IF(33='Investment & Financing'!$B$25,'Investment & Financing'!$B$26,0)-IF(33>'Investment & Financing'!$B$25,'Investment & Financing'!$B$28,0) | AI11: =IF(34='Investment & Financing'!$B$25,'Investment & Financing'!$B$26,0)-IF(34>'Investment & Financing'!$B$25,'Investment & Financing'!$B$28,0) | AJ11: =IF(35='Investment & Financing'!$B$25,'Investment & Financing'!$B$26,0)-IF(35>'Investment & Financing'!$B$25,'Investment & Financing'!$B$28,0) | AK11: =IF(36='Investment & Financing'!$B$25,'Investment & Financing'!$B$26,0)-IF(36>'Investment & Financing'!$B$25,'Investment & Financing'!$B$28,0)
A12: Net cash flow | B12: =B9+B10+B11 | C12: =C9+C10+C11 | D12: =D9+D10+D11 | E12: =E9+E10+E11 | F12: =F9+F10+F11 | G12: =G9+G10+G11 | H12: =H9+H10+H11 | I12: =I9+I10+I11 | ... AK12: =AK9+AK10+AK11
A13: Closing cash | B13: =B5+B12 | C13: =C5+C12 | D13: =D5+D12 | E13: =E5+E12 | F13: =F5+F12 | G13: =G5+G12 | H13: =H5+H12 | I13: =I5+I12 | ... AK13: =AK5+AK12
A20: Cumulative cash trough (MIN closing cash) | B20: =MIN(B13:AK13)
A21: Closing cash M36 | B21: =AK13
A22: WC movements held at 0 for a clean tie (seed inventory/AR static). Refine with monthly ΔAR/ΔInv/ΔGST when timing is known.

Sheet Investment & Financing
A1: INVESTMENT & FINANCING — the returnable-capital answer
A2: Capex / plant
A3: Gross capital ask LOW | B3: ='Assumptions & Provenance'!$B$53
A4: Gross capital ask HIGH | B4: ='Assumptions & Provenance'!$B$54
A5: Gross capex (midpoint used by model) | B5: =(B3+B4)/2 | D5: <- Control Panel dashboard reads this. Quote '$112K-$222K GROSS (firm quote pending)'. NEVER 90-200K.
A6: Container plant capex (total) | B6: ='Location & Containerisation'!$B$12
A7: Total new capex (shed + containers) | B7: =B5+B6
A8: Capex already invested (sunk) | B8: ='Assumptions & Provenance'!$B$49
A9: Net new cash needed (gross less invested) | B9: =B5-B8 | D9: ≈ ~1,954 (low) to ~111,954 (high). Net basis — a DIFFERENT quantity from QBE match cap.
A11: Annual saving & payback
A12: In-house legs saving /bed | B12: ='Assumptions & Provenance'!$B$59 | D12: ≈ 194.05 (BOM 469.79 -> factory 275.74). NOT the full 259 delta.
A13: Annual saving @ beds/yr | B13: ='Control Panel'!$B$15*B12
A14: Payback (yrs) @ beds/yr | B14: =B5/B13
A15: Guard band | B15: =IF('Control Panel'!$B$15<300,"Capex not sensible below ~300/yr committed — buy Defy kits","OK above ~300/yr")
A17: Use-of-funds line-items
A18: Instrument | B18: Type | C18: Amount | D18: Maps to
A19: QBE Catalysing Impact match | B19: Grant (contingent on raising $400K first) | C19: match cap | D19: capex + fixed block
A20: Anchor philanthropy | B20: Grant | C20: 500000 | D20: fixed block bridge
A21: SEFA | B21: Concessional debt | C21: 300000 | D21: working capital + plant
A22: Monthly depreciation (5-yr SL on total capex incl invested) | B22: =(B7+B8)/'Assumptions & Provenance'!$B$61 | C22: 110046 | D22: ≈ (new capex + invested) / 60. Constant monthly charge to P&L.
A24: SEFA financing schedule (illustrative)
A25: Draw month (M) | B25: 7 | D25: e.g. M7 = ~Nov-26
A26: Principal / rate / term | B26: ='Assumptions & Provenance'!$B$63 | C26: ='Assumptions & Provenance'!$B$64 | D26: ='Assumptions & Provenance'!$B$65 months
A27: Monthly interest (drawn) | B27: =B26*'Assumptions & Provenance'!$B$64/12 | D27: <- P&L interest line reads this. Simplified to interest-only (flat principal); see note.
A28: Monthly principal repayment | B28: =B26/'Assumptions & Provenance'!$B$65
A29: Coverage check (annual surplus / annual debt service) | B29: =('P&L'!$C$10)/((B27+B28)*12) | D29: (operating surplus before founder) / annual debt service. >1x = serviceable.

Sheet Scenarios
A1: SCENARIOS — presets. Set Control Panel 'Use scenario preset?' to 1-6 to load.
A2: Six presets. Control Panel can pull these via the 'Use scenario preset?' dial (1-6).
A3: Preset | B3: Beds Y1 | C3: Method | D3: Location | E3: Containerise | F3: Founder FTE | G3: Capital timing
A4: 1 Today (honest) | B4: 120 | C4: 1 | D4: 1 | E4: 0 | F4: 1 | G4: none
A5: 2 In-source assembly | B5: 250 | C5: 1 | D5: 2 | E5: 0 | F5: 1 | G5: $2K bench
A6: 3 Factory at target | B6: 500 | C6: 3 | D6: 2 | E6: 0 | F6: 1 | G6: $112-222K, M Sep-26
A7: 4 On-Country container | B7: 500 | C7: 3 | D7: 3 | E7: 1 | F7: 1 | G7: container plant
A8: 5 Community vision | B8: 1000 | C8: 4 | D8: 3 | E8: 1 | F8: 1 | G8: + free feedstock
A9: 6 Investor case (Matt) | G9: blank — Matt fills
A11: Selected preset (via Control Panel 'Use scenario preset?')
A12: Beds Y1 | B12: =IF('Control Panel'!$B$30=0,"(manual — using dials)",INDEX($B$4:$B$8,'Control Panel'!$B$30))
A13: Method | B13: =IF('Control Panel'!$B$30=0,"(manual — using dials)",INDEX($C$4:$C$8,'Control Panel'!$B$30))
A14: Location | B14: =IF('Control Panel'!$B$30=0,"(manual — using dials)",INDEX($D$4:$D$8,'Control Panel'!$B$30))
A15: Containerise | B15: =IF('Control Panel'!$B$30=0,"(manual — using dials)",INDEX($E$4:$E$8,'Control Panel'!$B$30))
A16: Founder FTE | B16: =IF('Control Panel'!$B$30=0,"(manual — using dials)",INDEX($F$4:$F$8,'Control Panel'!$B$30))
A18: TO ACTIVATE A PRESET: copy the row's values into the Control Panel yellow dials, OR wire the dials to =INDEX here.
A19: Opening cash reconciles to Control Panel B (the live engine). Displayed trough = Cashflow trough.

Sheet Assumptions & Provenance
A1: ASSUMPTIONS & PROVENANCE — canonical named values (the trust layer)
A2: START HERE: This is THE canonical Goods model. Archive v0.1, v0.2, Goods-Financial-Model, Bed-Cost-Model-v6, IAT.
A3: Assumption | B3: Value | C3: Confidence | D3: Source / note / recommended fix
A4: — BOM (verified ex invoices, supplier-quotes.ts) —
A5: HDPE kit (Defy) | B5: 344.05 | C5: verified | D5: Defy INV-1602/INV-1732, 19mm Jungle recycled HDPE kit, cut+finished, excl assembly+hardware.
A6: Steel poles (DNA Steel) | B6: 27 | C6: verified | D6: DNA Steel Direct Alice Springs, Notion BOM canonical.
A7: Canvas (Centre Canvas) | B7: 93.5 | C7: verified | D7: Centre Canvas Alice Springs, 3 invoices 2026. ACT-IN->ACT-GD retag $14,915 pending.
A8: End caps (4 x 0.80) | B8: 3.2 | C8: verified | D8: 4 x $0.80 round ribbed 27mm caps.
A9: Screws (16 x 0.065) | B9: 1.04 | C9: verified | D9: Coastal Fasteners INV RB20247673190 2026-04-16, $0.0645/screw.
A10: Bolts (2 x 0.50) | B10: 1 | C10: modelled | D10: 2 x ~$0.50 galv hex M8 bulk, pending line-item OCR.
A11: BOM direct materials (sum) | B11: =B5+B6+B7+B8+B9+B10 | C11: verified | D11: ≈ 469.79. Re-derives from the 6 lines above.
A12: — Factory path (raw shred -> press -> CNC -> assemble) —
A13: Raw HDPE (20kg x 2.75/kg incl freight) | B13: 55 | C13: modelled | D13: 20kg HDPE shred + transport. Factory-path plastic line.
A14: Diesel /bed | B14: 15 | C14: modelled | D14: 25L/day press+CNC over 5 beds/day.
A15: Factory hardware (caps+screws+bolts) | B15: 5.24 | C15: verified | D15: ≈ 3.20+1.04+1.00.
A16: Defy panel (each) | B16: 200 | C16: modelled | D16: Buy-Panels path: 2 panels/bed @ $200.
A17: Buy-Panels self-CNC labour add | B17: 58.33 | C17: modelled | D17: Reconciles Buy-Panels build-up to canonical 584.07 (2 panels 400 + 27 + 93.50 + 5.24 + 53.33 labour + 5 diesel).
A18: — Physics / idiot-index floor —
A19: HDPE mass per bed (kg) | B19: 20 | C19: verified | D19: 20kg HDPE diverted/bed (impact + COGS driver).
A20: Defy shred SELL price ($/kg) | B20: 2 | C20: verified | D20: Defy INV-1731 shred sell price. Idiot index vs shred basis.
A21: Raw recycled polymer floor ($/kg) | B21: 0.8 | C21: verified | D21: Envirobank recycled HDPE, supplier-quotes.ts. TRUE physics floor.
A22: HDPE floor vs shred ($/bed) | B22: =B19*B20 | C22: verified | D22: ≈ 40.00 (20kg x $2/kg shred).
A23: HDPE floor vs polymer ($/bed) | B23: =B19*B21 | C23: verified | D23: ≈ 16.00 (20kg x $0.80/kg polymer).
A24: — Founder time (LOCKED) —
A25: Founder day-rate ($/day) | B25: 560 | C25: locked | D25: LOCKED $560/day. NOT $1,000 (purge stale value).
A26: Founder days/yr on Goods | B26: 150 | C26: locked | D26: 30 production / 50 fundraising / 25 commercialisation / 45 governance.
A27: Founder production days/yr | B27: 30 | C27: locked | D27: Only this share touches unit cost (production fixed block).
A28: Founder cost/yr @100% FTE | B28: =B25*B26 | C28: locked | D28: ≈ 84,000.
A29: Founder production share/yr | B29: =B25*B27 | C29: locked | D29: ≈ 16,800. Part of the $109,500 headline fixed block.
A30: — Annual fixed block components —
A31: Kirmos facility (Sunshine Coast) /yr | B31: 27000 | C31: modelled | D31: $4,500/mo (Joseph Kirmos).
A32: Admin & overhead /yr | B32: 14700 | C32: modelled | D32: Software, insurance, accounting allocation.
A33: Field travel /yr | B33: 51000 | C33: modelled | D33: Community delivery + install travel.
A34: Non-founder fixed base /yr | B34: =B31+B32+B33 | C34: modelled | D34: ≈ 92,700. Founder line added SEPARATELY in P&L (FTE-scaled).
A35: Annual fixed block (headline) | B35: =B34+B29 | C35: modelled | D35: ≈ 109,500 incl founder-production share. Breakeven denominator basis.
A36: — Price, volume, freight, labour —
A37: Price per bed | B37: 750 | C37: verified | D37: Unified website price 2026-05-26 (shop stretch-bed-single).
A38: Local freight /bed | B38: 25 | C38: modelled | D38: Short-haul / last-leg. Marginal.
A39: Long-haul freight /bed | B39: 150 | C39: modelled | D39: Sydney->remote long-haul. Marginal, not overhead.
A40: Labour rate $/day | B40: 400 | C40: inferred | D40: Factory day rate (promoted from hardcode).
...
