Workbook

Sheet README & Assumptions
A1: Goods on Country — 3-Statement Financial Model v0.2
A2: QBE Catalysing Impact, Area 04 (Financial Management) P0 deliverable. v0.2 applies a live Xero mirror cross-check (2026-05-29). Workpaper — accountant sign-off still required.
A3: PROVENANCE BANNER — v0.2 corrections VERIFIED via live Xero mirror cross-check 2026-05-29 (ACT-infra xero_invoices/xero_transactions, synced 02:33): (1) revenue $732,210.79 billed / $649,710.79 received / $82,500 Rotary AR genuinely owed (no matching RECEIVE txn). (2) ALL ACT-GD bank spend made from ACT business accounts (NAB Visa ACT $177,633 + ACT Everyday $145,473 = $323,106); $0 from personal → NO director loan. (3) AP ≈ $0 owed — the ~$124,878 AUTHORISED ACCPAY bills are a Xero payment-MATCHING gap (paid from ACT accounts, never applied to the bill), NOT debt / NOT a working-capital squeeze. (4) Expenses on a SINGLE CASH BASIS = $323,106 bank spend (less $13,980 1300 Washer reclass to ACT-FM = $309,126 Goods cash out). Carla $11,180 'duplicate' is an accrual phantom (no cash).
A4: FOUNDER INPUTS LOCKED 2026-05-29 (Ben): day-rate $560/day · FTE 150 days/yr (30 production / 50 fundraising / 25 commercialisation / 45 governance) → founder cost $84,000/yr; production share $16,800/yr is the ONLY part in the bed fixed block. Opening cash @ 1 May 2026 = $50,000 WORKING figure pending the ACT-accounts carve-out (separate finance chat).
A5: READ THIS FIRST
A6: • This workbook consolidates the May-12 financial-model trail (Day 2/3/6/8/9), the v6 bed cost model (2026-05-29), and the Area 04 review into one founder/accountant-ready pack.
A7: • It is a v0.2 WORKPAPER. Revenue + receipts are VERIFIED off the live Xero mirror (2026-05-29 02:33). Expenses are now stated on a SINGLE CASH BASIS (ACT-GD bank spend), not bill+bank (which double-counted).
A8: • Every figure is provenance-labelled: VERIFIED (queried source), MODELLED (forecast/assumption), TARGET (future intent), TO CONFIRM (gap — scaffolded, not fabricated).
A9: • THREE LIVE DIAL cells (yellow) gate the model: Opening cash @ 1 May 2026 (now framed as the ACT-accounts carve-out), founder day-rate, founder production-days. The cashflow trough recomputes live off the opening-cash dial.
A10: • Where Area 04 lists a gap (inventory, GST/BAS finalisation, R&D refund timing, full carve-out), the row is scaffolded TO CONFIRM — value is never fabricated. No director loan exists (verified: $0 personal spend).
A12: LIVE DIALS (yellow = founder-confirm; these gate the model)
A13: Dial | B13: Value | C13: Unit | D13: Default / band | E13: Status | F13: Note
A14: Opening cash @ 1 May 2026 (ACT-accounts carve-out) | B14: 50000 | C14: AUD | D14: $50,000 WORKING figure | E14: WORKING — pending ACT-accounts carve-out (finance chat) | F14: WORKING figure, HELD at $50,000. Real number = balance of the ACT business accounts (NAB Visa ACT + ACT Everyday) attributable to Goods at 1 May 2026 — shared accounts, needs a carve-out, deferred to a separate finance chat. The carve-out re-bases the entire cashflow trough.
A15: Founder day-rate | B15: 560 | C15: AUD/day | D15: $560/day (LOCKED; was band $560–$1,000) | E15: LOCKED 2026-05-29 | F15: LOCKED 2026-05-29 (Ben). $560/day = $140,000/yr at 250 days (Day-3 fair-market basis). Supersedes the $560–$1,000 band (v6 cost model had used $1,000/day). Drives the founder-time P&L line, annual fixed block + breakeven. Dial stays interactive for sensitivity.
A16: Founder production days/yr (of 150 total) | B16: 30 | C16: days/yr | D16: 30 of 150 (LOCKED; working split 30 prod / 50 fundraising / 25 commercialisation / 45 governance) | E16: LOCKED 2026-05-29 (working split, adjustable) | F16: LOCKED 2026-05-29 (Ben), working split adjustable. 150 founder days/yr total → founder cost 150×$560 = $84,000/yr. ONLY the 30 production days touch unit cost ($16,800/yr in the bed fixed block). The other 120 days (50 fundraising / 25 commercialisation / 45 governance) = $67,200/yr are cost-of-capital + customer-acquisition + ACT-wide — NOT per-bed cost.
A18: PROVENANCE KEY
A19: VERIFIED | B19: Queried directly from a named source (ACT-GD Xero rows, supplier invoices, shop price). Usable externally with citation + founder/accountant sign-off.
A20: MODELLED | B20: Forecast or assumption (founder-time scenarios, 36-mo cashflow, unit cost at scale, capital close timing). Usable only as forecast.
A21: TARGET | B21: Future operating intent (factory cost, 6-mo buffer, accountant-reviewed pack).
A22: TO CONFIRM | B22: Area-04 gap. Row scaffolded, value NOT fabricated. Must be closed before the model is 'closed'.
A24: KEY ANCHOR FIGURES (cited)
A25: Metric | B25: Value | C25: Status | D25: Source
A26: Revenue billed (ACT-GD ACCREC, live 2026-05-29 pull) | B26: 732210.79 | C26: VERIFIED | D26: Live Xero mirror; project_code=ACT-GD
A27: Revenue received (16 PAID invoices) | B27: 649710.79 | C27: VERIFIED | D27: Live Xero mirror; matched RECEIVE txns
A28: Accounts receivable owed (Rotary INV-0222) | B28: 82500 | C28: VERIFIED | D28: Genuinely owed — NO matching RECEIVE txn exists
A29: Accounts payable genuinely owed | B29: 0 | C29: VERIFIED | D29: ~$124,878 AUTHORISED bills = payment-MATCHING gap, not debt
A30: Expenses — single cash basis (total ACT-GD bank spend) | B30: 323106 | C30: VERIFIED | D30: NAB Visa ACT $177,633 + ACT Everyday $145,473
A31: Goods cash out (after 1300 Washer reclass to ACT-FM −$13,980) | B31: 309126 | C31: VERIFIED | D31: $323,106 − $13,980 washing machine (belongs ACT-FM)
A32: Capex within cash spend (facility $100K + Carbatec tooling $10,046) | B32: 110046 | C32: VERIFIED | D32: opex/capex split inside cash spend is an accountant item
A33: GST net payable (rough; accountant to finalise BAS) | B33: 29657 | C33: MODELLED | D33: output GST $62,019 − input GST $32,362
A34: Website price per bed | B34: 750 | C34: VERIFIED | D34: shop stretch-bed-single
A35: Marginal cost / bed (Defy-kit path today) | B35: 684.79 | C35: MODELLED | D35: v6 cost model honest_marginal_cost
A36: Marginal cost / bed (factory path future) | B36: 425.74 | C36: MODELLED | D36: v6 cost model
A37: R&D Tax Incentive — modelled refund | B37: 80000 | C37: MODELLED | D37: ~$80K/yr; eligibility structural, treatment TBC by accountant
A38: Idiot index — HDPE kit (current $344 vs $40 raw floor) | B38: 8.6 | C38: VERIFIED | D38: v6 idiot_index; biggest lever
A41: TAB MAP
A42: Tab | B42: What it holds
A43: P&L (monthly) | B43: Revenue + expenses, Day 2/3 basis. FY rollup + founder-time sensitivity (rate-dial driven).
A44: Balance Sheet & WC | B44: Working-capital scaffold: known receivables/payables/capex + flagged gaps (inventory, AR/AP ageing, GST, R&D).
A45: Cashflow 36mo | B45: May-26→Apr-29 month-by-month. Trough is FORMULA-DRIVEN off the opening-cash dial. Capital injections mapped.
...

Sheet P&L (monthly)
A1: Profit & Loss — actuals basis (v0.2, single cash basis for expenses)
A2: Revenue VERIFIED (live Xero mirror 2026-05-29). Expenses now on a SINGLE CASH BASIS = ACT-GD bank spend (no bill+bank double-count). Founder time still a dial-driven sensitivity.
A4: FY ROLLUP
A5: FY | B5: Total Revenue | C5: Grant | D5: Commercial | E5: Expenses (bill basis) | F5: Net (bill basis, excl founder+capex) | G5: Status
A6: FY25 (Jul24–Jun25) | B6: 249885 | C6: 237885 | D6: 12000 | E6: 103519 | F6: 146366 | G6: VERIFIED rev / partial exp
A7: FY26 YTD (Jul25–Apr26) | B7: 435026 | C7: 373577 | D7: 61449 | E7: 246594 | F7: 188432 | G7: VERIFIED rev / partial exp
A8: Cumulative (cash basis) | B8: 732211 | C8: 611462 | D8: 73449 | E8: 309126 | F8: 423085 | G8: VERIFIED rev+spend
A10: NOTE: FY25/FY26 expense cells above are the historical ACCPAY (bill) basis. The cumulative row is restated on the v0.2 SINGLE CASH BASIS ($309,126 Goods cash out). Net excludes founder time + capex.
A12: EXPENSE — SINGLE CASH BASIS (v0.2 correction)
A13: Item | B13: Amount | C13: Status
A14: Total ACT-GD bank SPEND (NAB Visa ACT + ACT Everyday) | B14: 323106 | C14: VERIFIED
A15: Less: 1300 Washer (washing machine) reclass to ACT-FM | B15: -13980 | C15: VERIFIED
A16: =Goods cash out (single cash basis) | B16: 309126 | C16: VERIFIED
A17: Operating surplus BEFORE founder time (received − Goods cash out) | B17: =649711-309126 | C17: VERIFIED basis
A18: Operating margin before founder time (on received) | B18: =(649711-309126)/649711 | C18: MODELLED
A20: v0.1 used 'ACCPAY $350,112 + bank-only $86,499 = $436,612' — that DOUBLE-COUNTED ~$100K (AUTHORISED bills overlap the bank spend). v0.2 single cash basis = $323,106 spend, less $13,980 washer = $309,126. Capex ~$110,046 sits inside this; opex/capex split is an accountant item. NO bank spend came from a personal account ($0) → NO director loan.
A22: FOUNDER-TIME — LOCKED 2026-05-29 ($560/day x 150 days/yr = $84,000/yr). Sensitivity table below (250 days x combined FTE) kept as a reference only.
A23: Day-rate dial now README!B15 (LOCKED $560). HEADLINE founder cost = $560 x 150 founder-days = $84,000/yr: 30 production days = $16,800/yr (bed fixed block) + 120 days = $67,200/yr (fundraising/commercialisation/governance = cost-of-capital + customer-acquisition + ACT-wide, NOT unit cost).
A24: Scenario | B24: Ben FTE | C24: Nic FTE | D24: Combined FTE | E24: Annual founder cost | F24: Monthly | G24: Status
A25: Conservative | B25: 0.25 | C25: 0.25 | D25: 0.5 | E25: ='README & Assumptions'!$B$15*250*0.5 | F25: ='README & Assumptions'!$B$15*250*0.5/12 | G25: MODELLED
A26: Mid | B26: 0.5 | C26: 0.5 | D26: 1 | E26: ='README & Assumptions'!$B$15*250*1.0 | F26: ='README & Assumptions'!$B$15*250*1.0/12 | G26: MODELLED
A27: High | B27: 0.75 | C27: 0.5 | D27: 1.25 | E27: ='README & Assumptions'!$B$15*250*1.25 | F27: ='README & Assumptions'!$B$15*250*1.25/12 | G27: MODELLED
A28: All-in | B28: 0.8 | C28: 0.7 | D28: 1.5 | E28: ='README & Assumptions'!$B$15*250*1.5 | F28: ='README & Assumptions'!$B$15*250*1.5/12 | G28: MODELLED
A30: Day 3 honest read holds: at the Mid founder scenario the cumulative operating surplus is largely consumed by founder time. v0.2 changes the EXPENSE base (cash, not bill+bank) but not the founder-time mechanic.
A32: REVENUE MIX (Day 5, on $684,911 basis)
A33: Segment | B33: To date | C33: % of total | D33: Status
A34: Donor-funded institutional distribution | B34: 611461 | C34: 0.893 | D34: VERIFIED
A35: Direct institutional commercial | B35: 45499 | C35: 0.066 | D35: VERIFIED
A36: Corporate sponsorship / RAP | B36: 12000 | C36: 0.018 | D36: VERIFIED
A37: Community / maker partners | B37: 15950 | C37: 0.023 | D37: VERIFIED
A38: Government procurement | B38: 0 | C38: 0 | D38: TO CONFIRM
A39: Direct retail / B2C | B39: 0 | C39: 0 | D39: TO CONFIRM
A40: Adjacent markets | B40: 0 | C40: 0 | D40: TO CONFIRM
A42: Read: diversified early revenue, donor-funded institutional dominant. FLAG: $94,500 of ACT-GD revenue is currently UNTAGGED grant-vs-commercial — segment split above is provisional until tagged.
A44: FOUNDER-TIME LOCK + OPERATING SURPLUS AFTER FOUNDER TIME (headline — LOCKED 2026-05-29, Ben)
A45: Founder day-rate (LOCKED, README!B15) | B45: ='README & Assumptions'!$B$15 | C45: LOCKED
A46: Founder days/yr (LOCKED total) | B46: 150 | C46: LOCKED
A47: Founder cost per year (= $560 x 150) | B47: ='README & Assumptions'!$B$15*150 | C47: LOCKED
A48: of which production share (30 days — in bed fixed block) | B48: ='README & Assumptions'!$B$15*30 | C48: LOCKED
A49: of which fundraising/commercialisation/governance (120 days — NOT unit cost) | B49: ='README & Assumptions'!$B$15*120 | C49: LOCKED
...

Sheet Balance Sheet & WC
A1: Balance Sheet / Working-Capital Schedule — scaffold v0.2
A2: v0.2: AP genuinely owed ≈ $0 (AUTHORISED bills = payment-matching gap). NO director loan ($0 personal spend). Known items populated; remaining Area-04 gaps scaffolded TO CONFIRM (never fabricated).
A4: ASSETS
A5: Line item | B5: Amount | C5: Status | D5: Source / note
A6: Cash — opening @ 1 May 2026 | B6: ='README & Assumptions'!$B$13 | C6: FOUNDER-CONFIRM | D6: LIVE DIAL (README!B13). $50,000 placeholder = balance of ACT business accounts (NAB Visa ACT + ACT Everyday) attributable to Goods at 1 May 2026 — shared accounts, needs a carve-out.
A7: Accounts receivable — Rotary INV-0222 | B7: 82500 | C7: VERIFIED | D7: ACT-GD ACCREC genuinely owed — Rotary INV-0222. VERIFIED: no matching RECEIVE txn exists (not received-but-unmatched).
A8: Accounts receivable — full AR ageing | B8: — | C8: TO CONFIRM | D8: Need 30/60/90 ageing by invoice from accountant.
A9: Inventory — finished beds + materials WIP | B9: — | C9: TO CONFIRM | D9: Not yet valued. SIH flagged standing inventory for B2C. Day 6 modelled $50K one-time build.
A10: Plant & equipment (capex already invested) | B10: 110046 | C10: VERIFIED | D10: Carbatec tooling $10,046 + facility build to date; sits inside the $323,106 cash spend. Net of depreciation TBC by accountant.
A11: Plant & equipment — facility build (planned) | B11: 100000 | C11: TARGET | D11: v6 capex band $112K–$222K; net capital ask $90K–$200K after $110K invested.
A12: R&D Tax Incentive refund receivable | B12: — | C12: TO CONFIRM | D12: ~$80K/yr modelled (Day 6/8). Eligibility structural; accrual treatment TBC.
A14: LIABILITIES
A15: Line item | B15: Amount | C15: Status | D15: Source / note
A16: Accounts payable — genuinely owed | B16: 0 | C16: VERIFIED | D16: ≈ $0 owed. The ~$124,878 AUTHORISED ACCPAY bills are a Xero payment-MATCHING gap (paid from ACT accounts, never applied to the bill). NOT debt.
A17: AUTHORISED ACCPAY bills (payment-matching gap, NOT debt) | B17: 124878 | C17: VERIFIED | D17: Memo only — already paid from ACT accounts; apply the existing payments, do not pay again. Excludes Carla $11,180 accrual phantom.
A18: GST net payable (BAS position, rough) | B18: 29657 | C18: MODELLED | D18: output GST $62,019 − input GST $32,362. Accountant to finalise the BAS.
A19: Director loan / reimbursement | B19: 0 | C19: VERIFIED | D19: NONE. Verified: all ACT-GD bank spend came from ACT business accounts; $0 from personal NM Personal. The 'paid via Nic's personal account' framing was wrong.
A20: Debt — SEFA working capital (planned) | B20: 300000 | C20: MODELLED | D20: Day 8 concessional; ~4–6%, close target Nov 2026. NOT drawn.
A22: WORKING-CAPITAL SIGNAL (verified Xero basis — NOT a squeeze)
A23: Item | B23: Amount | C23: Status | D23: Note
A25: Receivables due (AR signal) | B25: 82500 | C25: VERIFIED | D25: ACT-GD ACCREC due
A26: Payables genuinely owed (AP signal) | B26: 0 | C26: VERIFIED | D26: ≈ $0 — matching gap, not debt
A27: Net working-capital signal (AR − AP) | B27: =B25-B26 | C27: MODELLED | D27: Net POSITIVE ≈ +$82,500 (Rotary AR owed, AP ≈ $0). v0.1's −$44.4K 'squeeze' was an artefact of treating the payment-matching gap as debt. There is NO working-capital squeeze.
A29: This remains a working-capital SCAFFOLD, not a balance sheet that balances. v0.2 corrects the AP and director-loan lines to $0 (verified) and reframes cash as the ACT-accounts carve-out. Inventory, full GST/BAS, depreciation + carve-out still TO CONFIRM with the accountant.

Sheet Cashflow 36mo
A1: Cashflow projection — 36 months (May 2026 → Apr 2029)
A2: MODELLED. Opening cash = LIVE DIAL (the ACT-accounts carve-out, README!B13). Cumulative-cash column is FORMULA-DRIVEN off that dial — the trough recomputes live. v0.2: no working-capital squeeze in the opening position (AP ≈ $0); the trough below is the modelled forward burn vs capital, not a payables overhang.
A4: Documented trough anchors (base case, $50K opening): −$94,483 Aug-2026 · downside −$171K Nov-2026 · upside −$15K Aug-2026 (Day 6/9).
A5: Net monthly cashflow below is the documented base-case monthly delta series implied by the Day-6 milestones (opening→trough→injections→FY closes). Change the opening-cash dial to re-base the cumulative line and trough.
A7: Month | B7: Net op cashflow | C7: Capital in | D7: Net monthly Δ | E7: Cumulative cash | F7: Buffer state | G7: Status
A8: May 2026 | B8: 0 | D8: =B8+C8 | E8: ='README & Assumptions'!$B$13+D8 | F8: BELOW_FLOOR | G8: MODELLED
A9: Jun 2026 | B9: -48161 | D9: =B9+C9 | E9: =E8+D9 | F9: NEGATIVE | G9: MODELLED
A10: Jul 2026 | B10: -48161 | D10: =B10+C10 | E10: =E9+D10 | F10: NEGATIVE | G10: MODELLED
A11: Aug 2026 | B11: -48161 | D11: =B11+C11 | E11: =E10+D11 | F11: NEGATIVE | G11: MODELLED
A12: Sep 2026 | B12: -2042 | C12: 400000 | D12: =B12+C12 | E12: =E11+D12 | F12: BELOW_TARGET | G12: MODELLED
A13: Oct 2026 | B13: -54208 | D13: =B13+C13 | E13: =E12+D13 | F13: BELOW_TARGET | G13: MODELLED
A14: Nov 2026 | B14: -54208 | C14: 300000 | D14: =B14+C14 | E14: =E13+D14 | F14: BELOW_FLOOR | G14: MODELLED
A15: Dec 2026 | B15: -12875 | D15: =B15+C15 | E15: =E14+D15 | F15: BELOW_TARGET | G15: MODELLED
A16: Jan 2027 | B16: -12875 | C16: 500000 | D16: =B16+C16 | E16: =E15+D16 | F16: OK | G16: MODELLED
A17: Feb 2027 | B17: 7681 | D17: =B17+C17 | E17: =E16+D17 | F17: OK | G17: MODELLED
A18: Mar 2027 | B18: 7681 | D18: =B18+C18 | E18: =E17+D18 | F18: OK | G18: MODELLED
A19: Apr 2027 | B19: 7681 | D19: =B19+C19 | E19: =E18+D19 | F19: OK | G19: MODELLED
A20: May 2027 | B20: 97281 | D20: =B20+C20 | E20: =E19+D20 | F20: OK | G20: MODELLED
A21: Jun 2027 | B21: 97281 | D21: =B21+C21 | E21: =E20+D21 | F21: OK | G21: MODELLED
A22: Jul 2027 | B22: 97281 | D22: =B22+C22 | E22: =E21+D22 | F22: OK | G22: MODELLED
A23: Aug 2027 | B23: 97281 | D23: =B23+C23 | E23: =E22+D23 | F23: OK | G23: MODELLED
A24: Sep 2027 | B24: 97281 | D24: =B24+C24 | E24: =E23+D24 | F24: OK | G24: MODELLED
A25: Oct 2027 | B25: 97281 | D25: =B25+C25 | E25: =E24+D25 | F25: OK | G25: MODELLED
A26: Nov 2027 | B26: 97281 | D26: =B26+C26 | E26: =E25+D26 | F26: OK | G26: MODELLED
A27: Dec 2027 | B27: 97281 | D27: =B27+C27 | E27: =E26+D27 | F27: OK | G27: MODELLED
A28: Jan 2028 | B28: 97281 | D28: =B28+C28 | E28: =E27+D28 | F28: OK | G28: MODELLED
... A43: Apr 2029 | B43: 97281 | D43: =B43+C43 | E43: =E42+D43 | F43: OK | G43: MODELLED
A45: Capital injection mapping (Day 8 — probability-weighted, NOT committed cash):
A46: Month | B46: Instrument | C46: Amount | D46: Probability | E46: Status
A47: Sep 2026 | B47: QBE Catalysing Impact match | C47: 400000 | D47: 90% IF match raised first | E47: MODELLED / match-contingent
A48: Nov 2026 | B48: SEFA working-capital loan (BOLD) | C48: 300000 | D48: 70% — LOI/term sheet in flight | E48: MODELLED
A49: Jan 2027 | B49: Anchor philanthropic raise | C49: 500000 | D49: 50% — conversations in flight | E49: MODELLED
A51: QBE is an OUTPUT of the stack, not an input: Goods must raise ~$400K to unlock the $400K match. v0.2 note: the opening cash is the ACT-accounts carve-out (shared NAB Visa ACT + ACT Everyday), so the trough depth is most sensitive to that carve-out figure, not to any payables overhang (AP ≈ $0).
A53: OPENING-CASH SENSITIVITY (Day 6) — illustrates how the dial moves the trough:
A54: Opening cash | B54: Trough cash | C54: Trough month | D54: Implication
A55: 50000 | B55: -94000 | C55: Aug 2026 | D55: Insolvency without immediate capital
A56: 100000 | B56: -44000 | C56: Aug 2026 | D56: Still insolvent; need capital by Sep
A57: 200000 | B57: 56000 | C57: Aug 2026 | D57: Survives but at risk; capital by Oct
A58: 400000 | B58: 256000 | C58: Sep 2026 | D58: Comfortable bridge to capital injections

Sheet Cost Ladder
A1: Stretch Bed cost ladder + unit economics (v6, 2026-05-29)
A2: Marginal vs fixed reframing. Founder-time block driven by the day-rate dial. Price held flat $750 (VERIFIED).
A4: MARGINAL COST PER BED (the bit a buyer pays for)
A5: Path | B5: Direct materials | C5: Assembly | D5: Local freight | E5: Long-haul freight | F5: Marginal total | G5: Status
A6: Defy-kit (today, no capex) | B6: 469.79 | C6: 40 | D6: 25 | E6: 150 | F6: 684.79 | G6: MODELLED (verified inputs)
A7: Factory (future, in-house legs) | B7: 275.74 | C7: — | D7: — | E7: 150 | F7: 425.74 | G7: TARGET / future
A9: Factory direct $275.74 = in-house legs $150 (plastic $55 + diesel $15 + labour $80) + steel $27 + canvas $93.50 + caps/screws/bolts. Defy margin captured by in-sourcing ≈ $289/bed.
A11: IDIOT INDEX (current paid ÷ raw-material floor)
A12: Element | B12: Raw floor | C12: Current paid | D12: Idiot index | E12: Biggest lever? | F12: Status
A13: HDPE kit (Defy cut+finished) | B13: 40 | C13: 344.05 | D13: 8.6 | E13: YES | F13: VERIFIED
A14: HDPE pre-pressed panel (alt) | B14: 40 | C14: 400 | D14: 10 | E14: avoid | F14: VERIFIED
A15: Canvas (Centre Canvas) | B15: 38.5 | C15: 93.5 | D15: 2.4 | E15: no | F15: VERIFIED
A16: Steel poles (DNA Steel) | B16: 12.67 | C16: 27 | D16: 2.1 | E16: no | F16: VERIFIED
A17: End caps | B17: 2.6 | C17: 3.2 | D17: 1.2 | E17: no | F17: VERIFIED
A18: Screws | B18: 1.04 | C18: 1.04 | D18: 1 | E18: no | F18: VERIFIED
A19: Bolts | B19: 0.6 | C19: 1 | D19: 1.7 | E19: no | F19: INFERRED
A20: Defy assembly labour | B20: 60 | C20: 55.95 | D20: 0.9 | E20: no | F20: VERIFIED
A22: HDPE kit at 8.6x is THE lever: in-sourcing shred+press+CNC moves ~$194/bed and captures ~$289 Defy margin. Annual prize at 500 beds/yr ≈ $144,525.
A24: ANNUAL FIXED BLOCK (founder production line = day-rate dial × production-days dial)
A25: Line | B25: Amount/yr | C25: Status | D25: Note
A26: Kirmos facility (50% of $4,500/mo) | B26: 27000 | C26: MODELLED | D26: 50% split estimate; confirm beds-vs-other with Nic.
A27: Founder production time | B27: ='README & Assumptions'!$B$15*'README & Assumptions'!$B$16 | C27: MODELLED | D27: DIAL-DRIVEN & LOCKED 2026-05-29: day-rate (README!B15 $560) x production-days (README!B16, 30 of 150) = $16,800/yr. Supersedes v6 $1,000x30=$30,000. ONLY founder share in the bed fixed block.
A28: Admin | B28: 14700 | C28: MODELLED | D28: Not itemised; tie to actual admin spend.
A29: Field travel | B29: 51000 | C29: MODELLED | D29: Lumpy relationship cost; treat as fixed block, not per-bed.
A30: =Total annual fixed block | B30: =B26+B27+B28+B29 | C30: MODELLED | D30: v6 published $122,700 at $1,000/day. At the LOCKED $560/day the founder line = $16,800, so total fixed block ~ $109,500 (locked basis). Cell moves with the dials.
A31: LOCKED 2026-05-29: founder block = day-rate $560 x 30 production days = $16,800/yr. Deliberately EXCLUDED from unit cost: fundraising (50) / commercialisation (25) / governance (45) days = $67,200/yr — only the 30 production days (of 150 total) touch per-bed cost.
A33: BREAKEVEN VOLUME (price $750 held flat)
A34: Path | B34: Price | C34: Marginal | D34: Contribution | E34: Fixed block | F34: Breakeven beds/yr | G34: Status
A35: Factory path | B35: 750 | C35: 425.74 | D35: =B35-C35 | E35: =B30 | F35: =ROUND(E35/D35,0) | G35: MODELLED
A36: Defy-kit path | B36: 750 | C36: 684.79 | D36: =B36-C36 | E36: =B30 | F36: =ROUND(E36/D36,0) | G36: MODELLED
A37: Published anchors: factory breakeven ≈ 378 beds/yr (contribution $324); Defy-kit ≈ 1,882 beds/yr (contribution only $65 — bought-in path cannot cover fixed costs; in-sourcing closes the economics). Cells recompute off the fixed-block dial → factory breakeven band ≈ 338–378.
A39: COST-DOWN TRAJECTORY
A40: Stage | B40: Trigger | C40: Plastic legs/bed | D40: Direct total | E40: Marginal w/ freight | F40: Status
A41: 0 — Defy kits | B41: today ~100/yr, no plant | C41: 344.05 | D41: 469.79 | E41: 685 | F41: VERIFIED
A42: 1 — In-source assembly | B42: ~150–300/yr, $2K bench | C42: 344.05 | D42: 469.79 | E42: 660 | F42: TARGET
A43: 2 — In-source press+CNC (factory) | B43: ~300–500/yr, $90–200K capex | C43: 150 | D43: 275.74 | E43: 426 | F43: TARGET / future
A44: 3 — Community + free waste plastic | B44: ~1,000/yr, CDP labour + council feedstock | C44: 27 | D44: 140.74 | E44: 291 | F44: FUTURE

Sheet Scenarios
A1: Scenarios — Base / Upside / Downside (Day 9)
A2: MODELLED. The cash trough appears in ALL THREE scenarios — depth/timing varies with the opening ACT-accounts carve-out + capital timing. v0.2: opening position has NO working-capital squeeze (AP ≈ $0, AR $82,500 genuinely owed).
A4: Metric | B4: Downside | C4: Base | D4: Upside | E4: Status
A5: Opening cash (ACT-accounts carve-out) | B5: 30000 | C5: 50000 | D5: 100000 | E5: MODELLED
A6: Cash first negative | B6: May 2026 | C6: Jun 2026 | D6: Aug 2026 | E6: MODELLED
A7: Trough (worst cash) | B7: -171000 | C7: -94000 | D7: -15000 | E7: MODELLED
A8: Trough month | B8: Nov 2026 | C8: Aug 2026 | D8: Aug 2026 | E8: MODELLED
A9: Capital injections total | B9: 650000 | C9: 1200000 | D9: 3540000 | E9: MODELLED
A10: Year 1 (FY27) revenue | B10: 690000 | C10: 1130000 | D10: 1580000 | E10: MODELLED
A11: Year 1 close cash | B11: 0 | C11: 992000 | D11: 2200000 | E11: MODELLED
A12: Year 3 close cash (36mo) | B12: 867000 | C12: 3327100 | D12: 7960000 | E12: MODELLED
A13: Probability of scenario | B13: 0.3 | C13: 0.3 | D13: 0.125 | E13: MODELLED
A15: DEFINITIONS
A16: Base | B16: Day 5 segment midpoints; QBE $400K Sep-26 + SEFA $300K Nov-26 + anchor $500K Jan-27; COGS 70%→45%; founder Mid ($140K/yr).
A17: Upside | B17: Ramps ~40% above midpoint; +Butterfly DGR $200K Y1 +PFI $640K +Minderoo $1.5M; SEFA/anchor ~3mo earlier; COGS 68%→40%.
A18: Downside | B18: Ramps ~40% below; QBE cut to $200K & slipped to Dec-26; SEFA $150K; anchor $300K Q2-27; founder All-in ($210K/yr); hires deferred.
A20: Honest investor story: structurally cash-tight May→Sep 2026; the $1.2M stack exists to bridge the trough; viable past Year 1 in all three; even downside closes Year 3 at $867K (survivable, not catastrophic).

Sheet Founder Inputs to Close
A1: Exact founder/accountant inputs still needed to CLOSE the model
A2: These are the gates. UPDATE 2026-05-29: day-rate (#2) and founder FTE/split (#3) are LOCKED by Ben (day-rate $560/day, 150 days/yr split 30/50/25/45). Opening cash (#1) is held at $50K as a working figure; the ACT-accounts carve-out and all accountant items (#4-#11) are being handled in a separate finance chat. Until those close, the model stays a v0.2 workpaper.
A4: # | B4: Input needed | C4: Default in model | D4: Owner | E4: Why it gates | F4: Status (2026-05-29)
A5: 1 | B5: Opening cash @ 1 May 2026 — ACT-accounts carve-out (NAB Visa ACT + ACT Everyday attributable to Goods) | C5: $50,000 PLACEHOLDER | D5: Ben | E5: Single biggest unknown — re-bases the entire cashflow trough. Shared ACT accounts; needs a Goods carve-out. | F5: WORKING — opening cash held $50K, ACT-accounts carve-out deferred to finance chat
A6: 2 | B6: Founder day-rate (and reconcile $560 vs $1,000) | C6: $560/day (LOCKED 2026-05-29) | D6: Ben + Nic | E6: Drives founder-time P&L line + annual fixed block + breakeven. | F6: DONE — day-rate LOCKED $560/day (2026-05-29, Ben)
A7: 3 | B7: Ben & Nic Goods FTE % (and production-days split) | C7: 150 days/yr; 30 prod / 50 fund / 25 comm / 45 gov (LOCKED) | D7: Ben + Nic | E7: Sets which founder-time scenario is real; touches unit cost. | F7: DONE — FTE LOCKED 150 days/yr, 30/50/25/45 split (2026-05-29, Ben)
A8: 4 | B8: ACT-GD revenue carve-out from ACT-ST | C8: Not carved out | D8: Accountant | E8: All revenue currently sits in ACT-ST incl. commercial — entity cleanliness. | F8: Remaining — finance chat (ACT-ST→ACT-GD carve-out)
A9: 5 | B9: Expense classification + de-duplication (opex vs capex) | C9: Cash basis $309,126; capex ~$110,046 inside | D9: Accountant | E9: Single cash basis now ($323,106 spend − $13,980 washer). Need opex vs capex split inside it (capex ~$110,046). | F9: Remaining — finance chat (opex/capex split, accountant)
A10: 6 | B10: Reconcile the AUTHORISED ACCPAY bills (apply existing ACT-account payments — do NOT pay again); void the Carla phantom ($11,180 duplicate bill); retag 1300 Washer to ACT-FM; confirm Defy INV-1507 status | C10: AP shows ~$124,878 AUTHORISED (matching gap) | D10: Accountant | E10: Clears the false AP/working-capital signal. These are matching/tagging fixes, not payments. | F10: Remaining — finance chat (apply payments, void Carla phantom, retag washer, Defy INV-1507)
A11: 7 | B11: Inventory & capex treatment (valuation + depreciation) | C11: Capex $110K invested; inventory unvalued | D11: Accountant | E11: Balance sheet won't balance without it. | F11: Remaining — finance chat (inventory valuation + depreciation)
A12: 8 | B12: GST / BAS net position | C12: Not modelled | D12: Accountant | E12: Funder pages ex-GST vs Xero inc-GST — net GST TBC. | F12: Remaining — finance chat (GST/BAS net position)
A13: 9 | B13: R&D Tax Incentive refund treatment + timing | C13: ~$80K/yr modelled | D13: Accountant | E13: Affects cashflow timing + Snow INV-0227 grant-vs-R&D split. | F13: Remaining — finance chat (R&D refund treatment + timing)
A14: 10 | B14: Tag $94,500 of ACT-GD revenue currently UNTAGGED grant-vs-commercial | C14: $94,500 untagged | D14: Accountant | E14: Firms up the revenue-mix split (grant vs commercial) on the P&L tab. NO director loan exists — verified $0 personal spend. | F14: Remaining — finance chat (tag $94,500 untagged grant-vs-commercial)
A15: 11 | B15: Accountant/bookkeeper sign-off note | C15: None — management accounts | D15: Accountant | E15: Required before SEFA/IBA covenants and external diligence. | F15: Remaining — finance chat (accountant/bookkeeper Xero sign-off)
A17: LOCKED 2026-05-29: founder day-rate $560/day + FTE 150 days/yr (30/50/25/45) = $84,000/yr founder cost (production share $16,800/yr). Remaining to unblock (separate finance chat): opening-cash ACT-accounts carve-out, opex/capex split, GST/BAS, R&D treatment, ACT-ST→ACT-GD carve-out, the $94,500 untagged revenue split, reconcile AUTHORISED bills + void Carla phantom + retag washer, bookkeeper Xero cleanups.
