Workbook

Sheet README & Assumptions
A1: Goods on Country — 3-Statement Financial Model v0.1
A2: QBE Catalysing Impact, Area 04 (Financial Management) P0 deliverable. Built 2026-05-29. MANAGEMENT ACCOUNTS — NOT AUDITED.
A4: READ THIS FIRST
A5: • This workbook consolidates the May-12 financial-model trail (Day 2/3/6/8/9), the v6 bed cost model (2026-05-29), and the Area 04 review into one founder/accountant-ready pack.
A6: • It is a v0.1 WORKPAPER built from Xero-linked pulls and modelled forecasts. It is NOT accountant-reviewed statutory accounts. Do not present externally as audited.
A7: • Every figure is provenance-labelled: VERIFIED (queried source), MODELLED (forecast/assumption), TARGET (future intent), TO CONFIRM (gap — scaffolded, not fabricated).
A8: • TWO LIVE DIAL cells (yellow) gate the whole model: Opening cash @ 1 May 2026, and Founder day-rate. Change them and the Cashflow + Cost-ladder tabs recompute.
A9: • Where Area 04 lists a gap (inventory, full AR/AP ageing, GST, R&D refund timing, ACT-GD carve-out), the row is scaffolded and marked TO CONFIRM rather than guessed.
A11: LIVE DIALS (yellow = founder-confirm; these gate the model)
A12: Dial | B12: Value | C12: Unit | D12: Default / band | E12: Status | F12: Note
A13: Opening cash @ 1 May 2026 | B13: 50000 | C13: AUD | D13: $50,000 PLACEHOLDER | E13: TO CONFIRM | F13: Single biggest unknown. If genuine Goods-earmarked cash is $300K+, the trough disappears. Drives Cashflow tab.
A14: Founder day-rate | B14: 560 | C14: AUD/day | D14: $560 (band $560–$1,000) | E14: TO CONFIRM | F14: $560/day = $140K/yr at 250 days (Day 3 basis). v6 cost model used $1,000/day — reconcile. Drives founder-time + fixed block.
A15: Founder production days/yr (Goods unit-cost share) | B15: 30 | C15: days/yr | D15: 30 (v6 split, of 150 total) | E15: TO CONFIRM | F15: Only the production share touches unit cost. Fundraising/commercialisation/governance days are cost-of-capital, not unit cost.
A17: PROVENANCE KEY
A18: VERIFIED | B18: Queried directly from a named source (ACT-GD Xero rows, supplier invoices, shop price). Usable externally with citation + founder/accountant sign-off.
A19: MODELLED | B19: Forecast or assumption (founder-time scenarios, 36-mo cashflow, unit cost at scale, capital close timing). Usable only as forecast.
A20: TARGET | B20: Future operating intent (factory cost, 6-mo buffer, accountant-reviewed pack).
A21: TO CONFIRM | B21: Area-04 gap. Row scaffolded, value NOT fabricated. Must be closed before the model is 'closed'.
A23: KEY ANCHOR FIGURES (cited)
A24: Metric | B24: Value | C24: Status | D24: Source
A25: Cumulative revenue (May-12 model basis, Ingkerreke excluded) | B25: 684911 | C25: VERIFIED | D25: Day 2 P&L; ACT-infra xero_invoices
A26: ACT-GD ACCREC total (fresh 2026-05-29 pull) | B26: 732210.79 | C26: VERIFIED | D26: Area 04; xero_invoices project_code=ACT-GD
A27: ACT-GD ACCREC paid | B27: 649710.79 | C27: VERIFIED | D27: Area 04 fresh pull
A28: ACT-GD ACCREC due (receivable signal) | B28: 82500 | C28: VERIFIED | D28: Area 04 — Rotary INV-0222 authorised
A29: ACCPAY invoiced expense (Day 2) | B29: 350112.34 | C29: VERIFIED | D29: Day 2/3; ACCPAY Goods-tagged
A30: True total operating expense (Day 3, incl bank-only spend) | B30: 436611.83 | C30: MODELLED | D30: Day 3 reconciliation (+$86,499 bank-only)
A31: Operating surplus before founder time | B31: 248299 | C31: MODELLED | D31: Day 3 (rev − true opex)
A32: ACCPAY due (payable signal) | B32: 126877.78 | C32: VERIFIED | D32: Area 04 fresh pull
A33: Website price per bed | B33: 750 | C33: VERIFIED | D33: shop stretch-bed-single
A34: Marginal cost / bed (Defy-kit path today) | B34: 684.79 | C34: MODELLED | D34: v6 cost model honest_marginal_cost
A35: Marginal cost / bed (factory path future) | B35: 425.74 | C35: MODELLED | D35: v6 cost model
A36: Annual fixed block (at $1,000/day founder basis) | B36: 122700 | C36: MODELLED | D36: v6 annual_fixed_block
A37: Idiot index — HDPE kit (current $344 vs $40 raw floor) | B37: 8.6 | C37: VERIFIED | D37: v6 idiot_index; biggest lever
A40: TAB MAP
A41: Tab | B41: What it holds
A42: P&L (monthly) | B42: Revenue + expenses, Day 2/3 basis. FY rollup + founder-time sensitivity (rate-dial driven).
A43: Balance Sheet & WC | B43: Working-capital scaffold: known receivables/payables/capex + flagged gaps (inventory, AR/AP ageing, GST, R&D).
A44: Cashflow 36mo | B44: May-26→Apr-29 month-by-month. Trough is FORMULA-DRIVEN off the opening-cash dial. Capital injections mapped.
A45: Cost Ladder | B45: v6 marginal vs fixed, breakeven, idiot index. Founder-time block driven by the day-rate dial.
A46: Scenarios | B46: Base / Upside / Downside summary (Day 9).
...

Sheet P&L (monthly)
A1: Profit & Loss — actuals basis (Day 2 / Day 3)
A2: Revenue VERIFIED (Xero income_type). Expense partial: ACCPAY VERIFIED, bank-only spend MODELLED. Founder time = day-rate dial. Period 2025-01→2026-03.
A4: FY ROLLUP
A5: FY | B5: Total Revenue | C5: Grant | D5: Commercial | E5: Expenses (ACCPAY) | F5: Net (excl founder + capex) | G5: Status
A6: FY25 (Jul24–Jun25) | B6: 249885 | C6: 237885 | D6: 12000 | E6: 103519 | F6: 146366 | G6: VERIFIED rev / partial exp
A7: FY26 YTD (Jul25–Apr26) | B7: 435026 | C7: 373577 | D7: 61449 | E7: 246594 | F7: 188432 | G7: VERIFIED rev / partial exp
A8: Cumulative | B8: 684911 | C8: 611462 | D8: 73449 | E8: 350112 | F8: 334799 | G8: VERIFIED rev / partial exp
A10: Expense ratio = ACCPAY / revenue = 51% — EXCLUDES founder time, bank-only spend (+$86,499) and capex. Once those land, margin worsens (Day 3).
A12: TRUE OPERATING EXPENSE BRIDGE (Day 3)
A13: Item | B13: Amount | C13: Status
A14: ACCPAY invoiced (Goods-tagged, 225 invoices) | B14: 350112.34 | C14: VERIFIED
A15: Plus: incremental bank SPEND (56 txns, no ACCPAY match) | B15: 86499.49 | C15: MODELLED
A16: =True total operating expense | B16: 436611.83 | C16: MODELLED
A17: Operating surplus BEFORE founder time | B17: 248299 | C17: MODELLED
A18: Operating margin before founder time | B18: 0.363 | C18: MODELLED
A20: Largest single bank-only items: Samuel Hafer $19,500 (design consultancy, 2025-09-11); Defy ×5; freight (Peak Up, Loadshift). Paid via 'NJ Marchesi T/as ACT Everyday' (Nic personal) + NAB Visa ACT — entity-cleanliness flag for carve-out.
A22: FOUNDER-TIME SENSITIVITY (annual cost = day-rate dial × 250 days × combined FTE)
A23: Day-rate dial currently → see README!B (yellow). 250 working days/yr assumed. All-in below uses combined FTE multiples of one full founder-year.
A24: Scenario | B24: Ben FTE | C24: Nic FTE | D24: Combined FTE | E24: Annual founder cost | F24: Monthly | G24: Status
A25: Conservative | B25: 0.25 | C25: 0.25 | D25: 0.5 | E25: ='README & Assumptions'!$B$14*250*0.5 | F25: ='README & Assumptions'!$B$14*250*0.5/12 | G25: MODELLED
A26: Mid | B26: 0.5 | C26: 0.5 | D26: 1 | E26: ='README & Assumptions'!$B$14*250*1.0 | F26: ='README & Assumptions'!$B$14*250*1.0/12 | G26: MODELLED
A27: High | B27: 0.75 | C27: 0.5 | D27: 1.25 | E27: ='README & Assumptions'!$B$14*250*1.25 | F27: ='README & Assumptions'!$B$14*250*1.25/12 | G27: MODELLED
A28: All-in | B28: 0.8 | C28: 0.7 | D28: 1.5 | E28: ='README & Assumptions'!$B$14*250*1.5 | F28: ='README & Assumptions'!$B$14*250*1.5/12 | G28: MODELLED
A30: Day 3 honest read: at Mid scenario incl. founder time, cumulative operating margin lands ≈ −11% (≈ −$78,400 over 27 months). Conservative is positive; All-in deeper negative. This is the truthful early-stage social-enterprise picture, and justifies patient/concessional capital.
A32: REVENUE MIX (Day 5, on $684,911 basis)
A33: Segment | B33: To date | C33: % of total | D33: Status
A34: Donor-funded institutional distribution | B34: 611461 | C34: 0.893 | D34: VERIFIED
A35: Direct institutional commercial | B35: 45499 | C35: 0.066 | D35: VERIFIED
A36: Corporate sponsorship / RAP | B36: 12000 | C36: 0.018 | D36: VERIFIED
A37: Community / maker partners | B37: 15950 | C37: 0.023 | D37: VERIFIED
A38: Government procurement | B38: 0 | C38: 0 | D38: TO CONFIRM
A39: Direct retail / B2C | B39: 0 | C39: 0 | D39: TO CONFIRM
A40: Adjacent markets | B40: 0 | C40: 0 | D40: TO CONFIRM
A42: Read: 'diversified early revenue with strong donor-funded institutional validation' — NOT 'self-sustaining trading business' (Area 04).

Sheet Balance Sheet & WC
A1: Balance Sheet / Working-Capital Schedule — scaffold v0.1
A2: Known items populated; Area-04 gaps scaffolded as TO CONFIRM (NOT fabricated). Needs accountant-reviewed ACT-GD carve-out to complete.
A4: ASSETS
A5: Line item | B5: Amount | C5: Status | D5: Source / note
A6: Cash — opening @ 1 May 2026 | B6: ='README & Assumptions'!$B$13 | C6: TO CONFIRM | D6: LIVE DIAL (README!B). $50,000 placeholder; confirm Goods-earmarked cash.
A7: Accounts receivable — Rotary INV-0222 | B7: 82500 | C7: VERIFIED | D7: ACT-GD ACCREC due, authorised (Area 04 fresh pull).
A8: Accounts receivable — full AR ageing | B8: — | C8: TO CONFIRM | D8: Need 30/60/90 ageing by invoice from accountant.
A9: Inventory — finished beds + materials WIP | B9: — | C9: TO CONFIRM | D9: Not yet valued. SIH flagged standing inventory for B2C. Day 6 modelled $50K one-time build.
A10: Plant & equipment (capex already invested) | B10: 110046 | C10: VERIFIED | D10: v6 factory_economics already_invested; net of depreciation TBC.
A11: Plant & equipment — facility build (planned) | B11: 100000 | C11: TARGET | D11: v6 capex band $112K–$222K; net capital ask $90K–$200K after $110K invested.
A12: R&D Tax Incentive refund receivable | B12: — | C12: TO CONFIRM | D12: ~$80K/yr modelled (Day 6/8). Eligibility structural; accrual treatment TBC.
A14: LIABILITIES
A15: Line item | B15: Amount | C15: Status | D15: Source / note
A16: Accounts payable — ACT-GD ACCPAY due | B16: 126877.78 | C16: VERIFIED | D16: Fresh 2026-05-29 pull (Area 04). Bill basis, not deduplicated cash.
A17: Accounts payable — full AP ageing | B17: — | C17: TO CONFIRM | D17: Need 30/60/90 supplier ageing from accountant.
A18: GST payable / receivable (BAS position) | B18: — | C18: TO CONFIRM | D18: Funder pages are ex-GST; Xero cash pull is inc-GST. Net GST position TBC.
A19: Director loan / reimbursement (Nic personal acct) | B19: — | C19: TO CONFIRM | D19: Goods opex paid via 'NJ Marchesi T/as ACT Everyday'. May create director-loan obligation (Mint Ellison).
A20: Debt — SEFA working capital (planned) | B20: 300000 | C20: MODELLED | D20: Day 8 concessional; ~4–6%, close target Nov 2026. NOT drawn.
A22: WORKING-CAPITAL SIGNAL (verified Xero invoice basis, not statutory)
A23: Item | B23: Amount | C23: Status | D23: Note
A25: Receivables due (AR signal) | B25: 82500 | C25: VERIFIED | D25: ACT-GD ACCREC due
A26: Payables due (AP signal) | B26: 126877.78 | C26: VERIFIED | D26: ACT-GD ACCPAY due
A27: Net working-capital signal (AR − AP) | B27: =B25-B26 | C27: MODELLED | D27: Negative ≈ −$44.4K: payables exceed authorised receivables. Underlines the cash-tightness the cashflow tab models.
A29: This is a working-capital SCAFFOLD, not a balance sheet that balances. A full balance sheet requires the accountant-reviewed ACT-GD carve-out, equity/retained-earnings, depreciation schedule, GST and inventory valuation (Area 04 'minimum inputs to close').

Sheet Cashflow 36mo
A1: Cashflow projection — 36 months (May 2026 → Apr 2029)
A2: MODELLED. Opening cash = LIVE DIAL. Cumulative-cash column is FORMULA-DRIVEN so the trough moves with the dial. Capital injections per Day 8.
A4: Documented trough anchors (base case, $50K opening): −$94,483 Aug-2026 · downside −$171K Nov-2026 · upside −$15K Aug-2026 (Day 6/9).
A5: Net monthly cashflow below is the documented base-case monthly delta series implied by the Day-6 milestones (opening→trough→injections→FY closes). Change the opening-cash dial to re-base the cumulative line and trough.
A7: Month | B7: Net op cashflow | C7: Capital in | D7: Net monthly Δ | E7: Cumulative cash | F7: Buffer state | G7: Status
A8: May 2026 | B8: 0 | D8: =B8+C8 | E8: ='README & Assumptions'!$B$13+D8 | F8: BELOW_FLOOR | G8: MODELLED
A9: Jun 2026 | B9: -48161 | D9: =B9+C9 | E9: =E8+D9 | F9: NEGATIVE | G9: MODELLED
A10: Jul 2026 | B10: -48161 | D10: =B10+C10 | E10: =E9+D10 | F10: NEGATIVE | G10: MODELLED
A11: Aug 2026 | B11: -48161 | D11: =B11+C11 | E11: =E10+D11 | F11: NEGATIVE | G11: MODELLED
A12: Sep 2026 | B12: -2042 | C12: 400000 | D12: =B12+C12 | E12: =E11+D12 | F12: BELOW_TARGET | G12: MODELLED
A13: Oct 2026 | B13: -54208 | D13: =B13+C13 | E13: =E12+D13 | F13: BELOW_TARGET | G13: MODELLED
A14: Nov 2026 | B14: -54208 | C14: 300000 | D14: =B14+C14 | E14: =E13+D14 | F14: BELOW_FLOOR | G14: MODELLED
A15: Dec 2026 | B15: -12875 | D15: =B15+C15 | E15: =E14+D15 | F15: BELOW_TARGET | G15: MODELLED
A16: Jan 2027 | B16: -12875 | C16: 500000 | D16: =B16+C16 | E16: =E15+D16 | F16: OK | G16: MODELLED
A17: Feb 2027 | B17: 7681 | D17: =B17+C17 | E17: =E16+D17 | F17: OK | G17: MODELLED
A18: Mar 2027 | B18: 7681 | D18: =B18+C18 | E18: =E17+D18 | F18: OK | G18: MODELLED
A19: Apr 2027 | B19: 7681 | D19: =B19+C19 | E19: =E18+D19 | F19: OK | G19: MODELLED
A20: May 2027 | B20: 97281 | D20: =B20+C20 | E20: =E19+D20 | F20: OK | G20: MODELLED
A21: Jun 2027 | B21: 97281 | D21: =B21+C21 | E21: =E20+D21 | F21: OK | G21: MODELLED
A22: Jul 2027 | B22: 97281 | D22: =B22+C22 | E22: =E21+D22 | F22: OK | G22: MODELLED
A23: Aug 2027 | B23: 97281 | D23: =B23+C23 | E23: =E22+D23 | F23: OK | G23: MODELLED
A24: Sep 2027 | B24: 97281 | D24: =B24+C24 | E24: =E23+D24 | F24: OK | G24: MODELLED
A25: Oct 2027 | B25: 97281 | D25: =B25+C25 | E25: =E24+D25 | F25: OK | G25: MODELLED
A26: Nov 2027 | B26: 97281 | D26: =B26+C26 | E26: =E25+D26 | F26: OK | G26: MODELLED
A27: Dec 2027 | B27: 97281 | D27: =B27+C27 | E27: =E26+D27 | F27: OK | G27: MODELLED
A28: Jan 2028 | B28: 97281 | D28: =B28+C28 | E28: =E27+D28 | F28: OK | G28: MODELLED
... A43: Apr 2029 | B43: 97281 | D43: =B43+C43 | E43: =E42+D43 | F43: OK | G43: MODELLED
A45: Capital injection mapping (Day 8 — probability-weighted, NOT committed cash):
A46: Month | B46: Instrument | C46: Amount | D46: Probability | E46: Status
A47: Sep 2026 | B47: QBE Catalysing Impact match | C47: 400000 | D47: 90% IF match raised first | E47: MODELLED / match-contingent
A48: Nov 2026 | B48: SEFA working-capital loan (BOLD) | C48: 300000 | D48: 70% — LOI/term sheet in flight | E48: MODELLED
A49: Jan 2027 | B49: Anchor philanthropic raise | C49: 500000 | D49: 50% — conversations in flight | E49: MODELLED
A51: QBE is an OUTPUT of the stack, not an input: Goods must raise ~$400K of non-QBE capital by 31 Aug 2026 to trigger the match (Day 8). Full-stack joint probability ≈ 30%.
A53: OPENING-CASH SENSITIVITY (Day 6) — illustrates how the dial moves the trough:
A54: Opening cash | B54: Trough cash | C54: Trough month | D54: Implication
A55: 50000 | B55: -94000 | C55: Aug 2026 | D55: Insolvency without immediate capital
A56: 100000 | B56: -44000 | C56: Aug 2026 | D56: Still insolvent; need capital by Sep
A57: 200000 | B57: 56000 | C57: Aug 2026 | D57: Survives but at risk; capital by Oct
A58: 400000 | B58: 256000 | C58: Sep 2026 | D58: Comfortable bridge to capital injections

Sheet Cost Ladder
A1: Stretch Bed cost ladder + unit economics (v6, 2026-05-29)
A2: Marginal vs fixed reframing. Founder-time block driven by the day-rate dial. Price held flat $750 (VERIFIED).
A4: MARGINAL COST PER BED (the bit a buyer pays for)
A5: Path | B5: Direct materials | C5: Assembly | D5: Local freight | E5: Long-haul freight | F5: Marginal total | G5: Status
A6: Defy-kit (today, no capex) | B6: 469.79 | C6: 40 | D6: 25 | E6: 150 | F6: 684.79 | G6: MODELLED (verified inputs)
A7: Factory (future, in-house legs) | B7: 275.74 | C7: — | D7: — | E7: 150 | F7: 425.74 | G7: TARGET / future
A9: Factory direct $275.74 = in-house legs $150 (plastic $55 + diesel $15 + labour $80) + steel $27 + canvas $93.50 + caps/screws/bolts. Defy margin captured by in-sourcing ≈ $289/bed.
A11: IDIOT INDEX (current paid ÷ raw-material floor)
A12: Element | B12: Raw floor | C12: Current paid | D12: Idiot index | E12: Biggest lever? | F12: Status
A13: HDPE kit (Defy cut+finished) | B13: 40 | C13: 344.05 | D13: 8.6 | E13: YES | F13: VERIFIED
A14: HDPE pre-pressed panel (alt) | B14: 40 | C14: 400 | D14: 10 | E14: avoid | F14: VERIFIED
A15: Canvas (Centre Canvas) | B15: 38.5 | C15: 93.5 | D15: 2.4 | E15: no | F15: VERIFIED
A16: Steel poles (DNA Steel) | B16: 12.67 | C16: 27 | D16: 2.1 | E16: no | F16: VERIFIED
A17: End caps | B17: 2.6 | C17: 3.2 | D17: 1.2 | E17: no | F17: VERIFIED
A18: Screws | B18: 1.04 | C18: 1.04 | D18: 1 | E18: no | F18: VERIFIED
A19: Bolts | B19: 0.6 | C19: 1 | D19: 1.7 | E19: no | F19: INFERRED
A20: Defy assembly labour | B20: 60 | C20: 55.95 | D20: 0.9 | E20: no | F20: VERIFIED
A22: HDPE kit at 8.6x is THE lever: in-sourcing shred+press+CNC moves ~$194/bed and captures ~$289 Defy margin. Annual prize at 500 beds/yr ≈ $144,525.
A24: ANNUAL FIXED BLOCK (founder production line = day-rate dial × production-days dial)
A25: Line | B25: Amount/yr | C25: Status | D25: Note
A26: Kirmos facility (50% of $4,500/mo) | B26: 27000 | C26: MODELLED | D26: 50% split estimate; confirm beds-vs-other with Nic.
A27: Founder production time | B27: ='README & Assumptions'!$B$14*'README & Assumptions'!$B$15 | C27: MODELLED | D27: DIAL-DRIVEN: day-rate × production-days. v6 used $1,000×30=$30,000; Day 3 rate $560→$16,800. Reconcile.
A28: Admin | B28: 14700 | C28: MODELLED | D28: Not itemised; tie to actual admin spend.
A29: Field travel | B29: 51000 | C29: MODELLED | D29: Lumpy relationship cost; treat as fixed block, not per-bed.
A30: =Total annual fixed block | B30: =B26+B27+B28+B29 | C30: MODELLED | D30: v6 published $122,700 at $1,000/day founder basis. This cell moves with the founder dials → band ≈ $110K–$123K.
A31: Deliberately EXCLUDED from unit cost: founder fundraising (50 days) + commercialisation (25 days) = cost-of-capital + customer acquisition, NOT unit cost.
A33: BREAKEVEN VOLUME (price $750 held flat)
A34: Path | B34: Price | C34: Marginal | D34: Contribution | E34: Fixed block | F34: Breakeven beds/yr | G34: Status
A35: Factory path | B35: 750 | C35: 425.74 | D35: =B35-C35 | E35: =B30 | F35: =ROUND(E35/D35,0) | G35: MODELLED
A36: Defy-kit path | B36: 750 | C36: 684.79 | D36: =B36-C36 | E36: =B30 | F36: =ROUND(E36/D36,0) | G36: MODELLED
A37: Published anchors: factory breakeven ≈ 378 beds/yr (contribution $324); Defy-kit ≈ 1,882 beds/yr (contribution only $65 — bought-in path cannot cover fixed costs; in-sourcing closes the economics). Cells recompute off the fixed-block dial → factory breakeven band ≈ 338–378.
A39: COST-DOWN TRAJECTORY
A40: Stage | B40: Trigger | C40: Plastic legs/bed | D40: Direct total | E40: Marginal w/ freight | F40: Status
A41: 0 — Defy kits | B41: today ~100/yr, no plant | C41: 344.05 | D41: 469.79 | E41: 685 | F41: VERIFIED
A42: 1 — In-source assembly | B42: ~150–300/yr, $2K bench | C42: 344.05 | D42: 469.79 | E42: 660 | F42: TARGET
A43: 2 — In-source press+CNC (factory) | B43: ~300–500/yr, $90–200K capex | C43: 150 | D43: 275.74 | E43: 426 | F43: TARGET / future
A44: 3 — Community + free waste plastic | B44: ~1,000/yr, CDP labour + council feedstock | C44: 27 | D44: 140.74 | E44: 291 | F44: FUTURE

Sheet Scenarios
A1: Scenarios — Base / Upside / Downside (Day 9)
A2: MODELLED. The cash trough appears in ALL THREE scenarios — depth/timing differ. Opening cash is the most-critical input regardless of scenario.
A4: Metric | B4: Downside | C4: Base | D4: Upside | E4: Status
A5: Opening cash (assumption) | B5: 30000 | C5: 50000 | D5: 100000 | E5: MODELLED
A6: Cash first negative | B6: May 2026 | C6: Jun 2026 | D6: Aug 2026 | E6: MODELLED
A7: Trough (worst cash) | B7: -171000 | C7: -94000 | D7: -15000 | E7: MODELLED
A8: Trough month | B8: Nov 2026 | C8: Aug 2026 | D8: Aug 2026 | E8: MODELLED
A9: Capital injections total | B9: 650000 | C9: 1200000 | D9: 3540000 | E9: MODELLED
A10: Year 1 (FY27) revenue | B10: 690000 | C10: 1130000 | D10: 1580000 | E10: MODELLED
A11: Year 1 close cash | B11: 0 | C11: 992000 | D11: 2200000 | E11: MODELLED
A12: Year 3 close cash (36mo) | B12: 867000 | C12: 3327100 | D12: 7960000 | E12: MODELLED
A13: Probability of scenario | B13: 0.3 | C13: 0.3 | D13: 0.125 | E13: MODELLED
A15: DEFINITIONS
A16: Base | B16: Day 5 segment midpoints; QBE $400K Sep-26 + SEFA $300K Nov-26 + anchor $500K Jan-27; COGS 70%→45%; founder Mid ($140K/yr).
A17: Upside | B17: Ramps ~40% above midpoint; +Butterfly DGR $200K Y1 +PFI $640K +Minderoo $1.5M; SEFA/anchor ~3mo earlier; COGS 68%→40%.
A18: Downside | B18: Ramps ~40% below; QBE cut to $200K & slipped to Dec-26; SEFA $150K; anchor $300K Q2-27; founder All-in ($210K/yr); hires deferred.
A20: Honest investor story: structurally cash-tight May→Sep 2026; the $1.2M stack exists to bridge the trough; viable past Year 1 in all three; even downside closes Year 3 at $867K (survivable, not catastrophic).

Sheet Founder Inputs to Close
A1: Exact founder/accountant inputs still needed to CLOSE the model
A2: These are the gates. Until they are answered, the model stays v0.1 management-accounts WORKPAPER.
A4: # | B4: Input needed | C4: Default in model | D4: Owner | E4: Why it gates
A5: 1 | B5: Opening cash @ 1 May 2026 (genuine Goods-earmarked) | C5: $50,000 PLACEHOLDER | D5: Ben | E5: Single biggest unknown — re-bases the entire cashflow trough.
A6: 2 | B6: Founder day-rate (and reconcile $560 vs $1,000) | C6: $560/day (band to $1,000) | D6: Ben + Nic | E6: Drives founder-time P&L line + annual fixed block + breakeven.
A7: 3 | B7: Ben & Nic Goods FTE % (and production-days split) | C7: 50%/50%; 30 prod days | D7: Ben + Nic | E7: Sets which founder-time scenario is real; touches unit cost.
A8: 4 | B8: ACT-GD revenue carve-out from ACT-ST | C8: Not carved out | D8: Accountant | E8: All revenue currently sits in ACT-ST incl. commercial — entity cleanliness.
A9: 5 | B9: Expense classification + de-duplication (opex vs capex) | C9: ACCPAY + bank-only lumped | D9: Accountant | E9: Day 3 bank-only $86,499 needs opex/capex split; avoid double counts.
A10: 6 | B10: Receivables & payables ageing (30/60/90) | C10: AR $82,500 / AP $126,878 totals only | D10: Accountant | E10: Completes balance sheet + working-capital schedule.
A11: 7 | B11: Inventory & capex treatment (valuation + depreciation) | C11: Capex $110K invested; inventory unvalued | D11: Accountant | E11: Balance sheet won't balance without it.
A12: 8 | B12: GST / BAS net position | C12: Not modelled | D12: Accountant | E12: Funder pages ex-GST vs Xero inc-GST — net GST TBC.
A13: 9 | B13: R&D Tax Incentive refund treatment + timing | C13: ~$80K/yr modelled | D13: Accountant | E13: Affects cashflow timing + Snow INV-0227 grant-vs-R&D split.
A14: 10 | B14: Director-loan / reimbursement (Nic personal account) | C14: Not booked | D14: Accountant + Mint Ellison | E14: Goods opex paid via 'NJ Marchesi T/as ACT Everyday'.
A15: 11 | B15: Accountant/bookkeeper sign-off note | C15: None — management accounts | D15: Accountant | E15: Required before SEFA/IBA covenants and external diligence.
A17: Top 3 to unblock first: (1) opening cash, (2) founder day-rate reconciliation, (3) Ben/Nic FTE %. These three alone re-base the cashflow trough and the founder-time P&L line.
