Workbook

Sheet Read me
A1: Goods on Country, financial model for funders
A3: Goods on Country is a registered business name of The Butterfly Movement Ltd, which applies for and receives the grants. This workbook was built from the repository's guarded data modules on 2026-09-15. Every number is a module constant looked up by name, or a formula over cells that are. The Sources sheet lists each one.
A5: What it does: one bed (price, cost, contribution, break-even), the year to June 2027 (three jobs, who is asked, the gap), a monthly cash scenario for FY27, a three-year shape for the Tim Fairfax application, and the yield improvements list.
A7: What it does not do: no GST, no balance sheet, no tax, no depreciation, no receivables. Bed sales are counted only where a buyer has a dated paid order inside FY27. Grant receipt months are scenario months and no receipt date exists for any of them.
A9: The bed is $750 and nothing is added to it. The organisation absorbs freight at $100 a bed and facilitation at $100 a bed out of its share, so a buyer is never charged freight and no funder is asked for a freight line. Ben, 15 September 2026, as a director.
A11: Provisional lines: the making cost and every figure derived from it (contribution, break-even, the beds line of the year) until Nic confirms the bought leg-panel yield; the bought leg panel yield itself, which is unknown; and whether the founders line includes superannuation, which is unconfirmed. Opening cash is Butterfly whole-entity FY26 closing cash and is unaudited.
A13: Colours: pale turquoise cells are inputs, turquoise bars are sections, dark grey figures are formulas. Change an input on the Inputs sheet and the One bed, The year and Monthly cash sheets recompute. Module values sit beside the formulas on One bed so a reviewer can see they agree.
A15: Nothing in the raise is secured. Every line is an invitation, an application or a conversation. An invitation is not an award.
A17: Version 2026-09-15. Regenerate from v2 with FUNDER_MODEL_BUILD=1 npx vitest run src/lib/finance/build-funder-model.test.ts. Do not edit the numbers by hand; change the module and rebuild.

Sheet Inputs
A1: Inputs. Every driver in the model, with where it comes from. Built 2026-09-15.
A2: Driver | B2: Id | C2: Value | D2: Unit | E2: Status | F2: Notes | G2: Source (module and constant)
A3: The bed
A4: Bed price | B4: bed.price | C4: 750 | D4: AUD | E4: settled | F4: The published price. Every invoice since INV-0303 has carried it or more. | G4: the-year-and-the-raise:BED_PRICE_AUD
A5: Plastic | B5: bed.plastic | C5: 55 | D5: AUD a bed | E5: provisional | F5: Legacy 20 kg at $2.75 a kg. Provisional until Nic confirms the bought leg-panel yield. | G5: the-year-and-the-raise:PLASTIC_AUD
A6: Poles | B6: bed.poles | C6: 27 | D6: AUD a bed | E6: settled | F6: Two galvanised steel poles. | G6: the-year-and-the-raise:POLES_AUD
A7: Canvas | B7: bed.canvas | C7: 93.5 | D7: AUD a bed | E7: settled | F7: Canvas with sewn sleeves. The canvas is structural. | G7: the-year-and-the-raise:CANVAS_AUD
A8: Hardware | B8: bed.hardware | C8: 5.24 | D8: AUD a bed | E8: settled | F8: Fixings. | G8: the-year-and-the-raise:HARDWARE_AUD
A9: Power | B9: bed.power | C9: 15 | D9: AUD a bed | E9: settled | F9: Press and router power for one kit. | G9: the-year-and-the-raise:POWER_AUD
A10: Factory labour a day | B10: bed.labourADay | C10: 400 | D10: AUD a day | E10: settled | F10: One paid day on the press and router. | G10: the-year-and-the-raise:FACTORY_LABOUR_A_DAY_AUD
A11: Tab sheets pressed a day | B11: prod.sheetsADay | C11: 6 | D11: sheets | E11: settled | F11: Ben, 12 September 2026. | G11: production-route:PRESS_SHEETS_A_DAY
A12: Pressed sheets a kit | B12: prod.sheetsPerKit | C12: 1 | D12: sheets | E12: settled | F12: One tab sheet makes one kit. | G12: production-route:PRESSED_SHEETS_PER_KIT
A13: Kits a day | B13: bed.kitsADay | C13: ='Inputs'!C11/'Inputs'!C12 -> 6 | D13: kits | E13: settled | F13: Ben, 15 September 2026: six, the tab press rate. | G13: formula of the-year-and-the-raise:KITS_A_DAY
A14: Labour a bed | B14: bed.labour | C14: ='Inputs'!C10/'Inputs'!C13 -> 66.666667 | D14: AUD a bed | E14: settled | F14: Factory labour a day over the kits a day. | G14: formula of the-year-and-the-raise:LABOUR_AUD
A15: Making cost, a bed | B15: bed.make | C15: =SUM('Inputs'!C5,'Inputs'!C6,'Inputs'!C7,'Inputs'!C8,'Inputs'!C9,'Inputs'!C14) -> 262.40667 | D15: AUD a bed | E15: provisional | F15: provisional: bought leg panels and tab pressing need costing (Nic, panel yield) | G15: formula of the-year-and-the-raise:BED_MAKE_AUD
A16: Freight a bed, absorbed | B16: bed.freight | C16: 100 | D16: AUD a bed | E16: settled | F16: All up. The organisation absorbs it out of its share of the $750; no buyer pays it. Ben, 15 September 2026. | G16: the-year-and-the-raise:BED_FREIGHT_AUD
A17: Facilitation a bed, absorbed | B17: bed.facilitation | C17: 100 | D17: AUD a bed | E17: settled | F17: $40,000 over 400 beds. The organisation absorbs it out of its share of the $750. Ben, 15 September 2026. | G17: the-year-and-the-raise:FACILITATION_PER_BED_AUD
A18: Contribution a bed | B18: bed.contribution | C18: ='Inputs'!C4-'Inputs'!C15-'Inputs'!C16-'Inputs'!C17 -> 287.59333 | D18: AUD a bed | E18: provisional | F18: What reaches the organisation from a $750 bed after making, freight and facilitation. Ben, 15 September 2026. | G18: formula of the-year-and-the-raise:CONTRIBUTION_AUD
A19: The year
A20: Beds of first stock | B20: year.beds | C20: 400 | D20: beds | E20: settled | F20: Four pools of one hundred. | G20: the-year-and-the-raise:BEDS_YEAR_ONE
A21: Community pools | B21: year.pools | C21: 4 | D21: pools | E21: settled | F21: Ruling 7. | G21: the-year-and-the-raise:FACILITATION_COMMUNITIES
A22: Beds in a pool | B22: year.poolSize | C22: ='Inputs'!C20/'Inputs'!C21 -> 100 | D22: beds | E22: settled | F22: Derived. | G22: formula of the-year-and-the-raise:BEDS_YEAR_ONE, the-year-and-the-raise:FACILITATION_COMMUNITIES
A23: Freight on the year, absorbed | B23: year.freight | C23: ='Inputs'!C20*'Inputs'!C16 -> 40000 | D23: AUD | E23: settled | F23: Beds of first stock at the freight a bed. Paid by the organisation. | G23: formula of the-year-and-the-raise:FREIGHT_ON_THE_YEAR_AUD
A24: Months in a year | B24: cal.months | C24: 12 | D24: months | E24: settled | F24: Calendar. | G24: calendar:MONTHS_IN_A_YEAR
A25: Facilitation
A26: Communities | B26: fac.communities | C26: 4 | D26: communities | E26: settled | F26: Four community pools in year one. | G26: the-year-and-the-raise:FACILITATION_COMMUNITIES
A27: Facilitation a community | B27: fac.each | C27: 10000 | D27: AUD | E27: settled | F27: Billed and paid at this rate on four invoices already. | G27: three-year-plan:FACILITATION_PER_COMMUNITY_AUD
A28: Facilitation, the year, absorbed | B28: fac.total | C28: ='Inputs'!C17*'Inputs'!C20 -> 40000 | D28: AUD | E28: settled | F28: Facilitation a bed across the beds of first stock, which is also four communities at $10,000. Paid by the organisation. | G28: formula of the-year-and-the-raise:FACILITATION_AUD
A29: Running the organisation
A30: Founders | B30: run.0 | C30: 151200 | D30: AUD a year | E30: unconfirmed | F30: Two founders beyond the days they spend on production. Whether this includes superannuation is unconfirmed. Superannuation status: unconfirmed. | G30: the-year-and-the-raise:RUNNING_LINES[0].amountAud
A31: Getting to communities | B31: run.1 | C31: 51000 | D31: AUD a year | E31: settled | F31: Travel to eleven communities. Being on country costs what a call does not. | G31: the-year-and-the-raise:RUNNING_LINES[1].amountAud
A32: Accounting and advice | B32: run.2 | C32: 3674 | D32: AUD a year | E32: settled | F32: What Butterfly actually paid for its FY26 accountancy and audit, from the JAQ Minns FY26 statements. | G32: the-year-and-the-raise:RUNNING_LINES[2].amountAud
A33: Witta rent | B33: run.3 | C33: 27000 | D33: AUD a year | E33: settled | F33: The Harvest shed, where the press and the router live. | G33: the-year-and-the-raise:RUNNING_LINES[3].amountAud
A34: Marketing | B34: run.4 | C34: 10000 | D34: AUD a year | E34: settled | F34: The site, the deck, the print. Confirmed by Ben on 15 September 2026. | G34: the-year-and-the-raise:RUNNING_LINES[4].amountAud
A35: Maintenance | B35: run.5 | C35: 8350 | D35: AUD a year | E35: settled | F35: Press, router and shredder upkeep. | G35: the-year-and-the-raise:RUNNING_LINES[5].amountAud
A36: Running the organisation, a year | B36: run.total | C36: =SUM('Inputs'!C30,'Inputs'!C31,'Inputs'!C32,'Inputs'!C33,'Inputs'!C34,'Inputs'!C35) -> 251224 | D36: AUD a year | E36: settled | F36: Ben's provision of 9 September 2026, cut 15 September 2026. | G36: formula of the-year-and-the-raise:RUNNING_AUD
A37: The organisation pays, a year | B37: org.need | C37: ='Inputs'!C36+'Inputs'!C28+'Inputs'!C23 -> 331224 | D37: AUD a year | E37: settled | F37: Running, plus the facilitation and freight it absorbs. | G37: formula of the-year-and-the-raise:ORGANISATION_NEED_AUD
A38: What the beds hand the organisation | B38: org.fromBeds | C38: ='Inputs'!C20*'Inputs'!C18 -> 115037.33 | D38: AUD a year | E38: provisional | F38: Beds of first stock at the contribution, which already has freight and facilitation taken out. | G38: formula of the-year-and-the-raise:ORGANISATION_FROM_BEDS_AUD
A39: Running cost less what the beds hand back | B39: org.short | C39: ='Inputs'!C36-'Inputs'!C38 -> 136186.67 | D39: AUD a year | E39: provisional | F39: Measured against running alone, because freight and facilitation are already out of the contribution. Taking them off twice was the kind of error that produced the $937,550. | G39: formula of the-year-and-the-raise:ORGANISATION_SHORT_AUD
A40: Facilities
...

Sheet One bed
A1: One bed. Price, cost, contribution and the number of beds a year that carries the organisation.
A2: Line | B2: Module value | C2: Sheet formula | D2: Notes
A3: Price
A4: Bed price | B4: 750 | C4: ='Inputs'!C4 -> 750 | D4: Published, and paid on every invoice since INV-0303.
A5: Cost to make
A6: Plastic | B6: 55 | C6: ='Inputs'!C5 -> 55 | D6: Provisional.
A7: Poles | B7: 27 | C7: ='Inputs'!C6 -> 27
A8: Canvas | B8: 93.5 | C8: ='Inputs'!C7 -> 93.5
A9: Hardware | B9: 5.24 | C9: ='Inputs'!C8 -> 5.24
A10: Power | B10: 15 | C10: ='Inputs'!C9 -> 15
A11: Labour | B11: 66.666667 | C11: ='Inputs'!C14 -> 66.666667 | D11: Factory labour a day over kits a day.
A12: Making cost | B12: 262.40667 | C12: ='Inputs'!C15 -> 262.40667 | D12: provisional: bought leg panels and tab pressing need costing (Nic, panel yield)
A13: What the organisation absorbs out of its share
A14: Freight, absorbed | B14: 100 | C14: ='Inputs'!C16 -> 100 | D14: All up. No buyer pays it and no funder is asked for it. Ben, 15 September 2026.
A15: Facilitation, absorbed | B15: 100 | C15: ='Inputs'!C17 -> 100 | D15: $40,000 over 400 beds. Ben, 15 September 2026.
A16: What a bed hands to the organisation
A17: Contribution | B17: 287.59333 | C17: ='Inputs'!C18 -> 287.59333 | D17: Price less making, freight and facilitation.
A18: Break-even
A19: Running the organisation, a year | B19: 251224 | C19: ='Inputs'!C36 -> 251224 | D19: From Inputs.
A20: Beds a year that carry it | B20: 874 | C20: =CEILING('Inputs'!C36/'Inputs'!C18,1) -> 874 | D20: Running cost over contribution, rounded up. Recomputes from the Inputs cells.

Sheet The year
A1: The year to June 2027. Three jobs, who is asked to pay for each, and what is still to find.
A2: The three jobs
A3: Job | B3: Need | C3: Asked | D3: Short | G3: Funded by
A4: Facilities: two community plants | B4: ='Inputs'!C45 -> 300000 | C4: =SUM(B11) -> 300000 | D4: =MAX(0,B4-C4) -> 0 | G4: QBE Foundation, Stage 2.
A5: Beds: making 400 of first stock | B5: ='Inputs'!C20*'Inputs'!C15 -> 104962.67 | C5: =SUM(B12,B13,B14) -> 299750 | D5: =MAX(0,B5-C5) -> 0 | G5: Tim Fairfax (invited, year one of three), Brian M. Davis (invited), Snow (not sent), each 133 beds at $750. Bed money is asked at the price, so this line over-covers the making cost and the surplus carries the organisation.
A6: Organisation: running it, and the freight and facilitation it absorbs | B6: ='Inputs'!C37 -> 331224 | C6: =SUM(B15) -> 150000 | D6: =MAX(0,B6-C6) -> 181224 | G6: No grant is asked for this line. The $150,000 SEFA loan inside the ask carries the first-year gap (Ben, 15 September 2026); the rest is carried by 400 beds at the contribution.
A7: The year needs | B7: =SUM(B4,B5,B6) -> 736186.67 | C7: =SUM(C4,C5,C6) -> 749750 | D7: =B7-C7 -> -13563.333 | G7: Plants, beds at cost, and the organisation with the freight and facilitation it absorbs. Never beds at price plus running: that counts the bed money twice.
A9: Who is asked
A10: Funder | B10: Amount | C10: Job | D10: Stage | E10: Beds at price | F10: In the ask | G10: Source
A11: QBE Foundation, Stage 2 | B11: 300000 | C11: plant | D11: applying | E11: not beds | F11: yes | G11: QBE!D14 and Funding F01. Two plants at the $150,000 allowance. Closes 25 September, noon.
A12: Tim Fairfax Family Foundation | B12: 100000 | C12: beds | D12: invited | E12: =FLOOR(B12/'Inputs'!C4,1) -> 133 | F12: yes | G12: Katie Norman, 31 August 2026: a three-year grant of $300,000 in three equal payments under General Operating Support. Ben, 15 September 2026: year one buys 133 beds at $750; the organisation's share is the contribution those beds hand back. The form's operating framing is a flag, not a job.
A13: Brian M. Davis Charitable Foundation | B13: 99750 | C13: beds | D13: invited | E13: =FLOOR(B13/'Inputs'!C4,1) -> 133 | F13: yes | G13: Miranda Campbell, 1 September 2026: up to $100,000 for twelve months. Ben, 15 September 2026: 133 beds at $750, facilitation inside, one budget line. The old 80 beds plus $40,000 facilitation split is withdrawn.
A14: Snow Foundation | B14: 100000 | C14: beds | D14: not-sent | E14: =FLOOR(B14/'Inputs'!C4,1) -> 133 | F14: yes | G14: Ben wrote $100,000 on 10 September and ruled it counts as beds, 133 at $750. The ask has not been sent.
A15: SEFA, Backing the Bold | B15: 150000 | C15: operating | D15: not-sent | E15: not counted | F15: yes | G15: Ben, 15 September 2026: the first-year running gap is carried by a SEFA loan of $150,000, inside the ask, repaid from the $288 each bed hands back. Jay's steer for QBE 2026 is philanthropy that unlocks capital, and this is the capital. EOI drafted; Joel Bird reviews the financials before it goes.
A16: Dusseldorp Forum | B16: 50000 | C16: beds | D16: not-sent | E16: =FLOOR(B16/'Inputs'!C4,1) -> 66 | F16: no | G16: Top-up. $50,000 is our number, nothing from the funder yet.
A18: Totals
A19: Line | B19: As it stands | C19: No Snow, no Dusseldorp | G19: Notes
A20: Asked | B20: =SUM(B11,B12,B13,B14,B15) -> 749750 | C20: =SUM(B11,B12,B13) -> 499750 | G20: Four grants and one loan. Dusseldorp is outside the ask.
A21: Secured | B21: 0 | C21: 0 | G21: Nothing is secured. An invitation is not an award.
A22: Gap to the year | B22: =B7-B20 -> -13563.333 | C22: =B7-C20 -> 236436.67 | G22: Need less asked. The gap is beds of first stock and a year of running the organisation. Plant money never leaves a hole.
A23: Beds covered by asks at the price | B23: =FLOOR(SUM(B12,B13,B14)/'Inputs'!C4,1) -> 399 | C23: =FLOOR(SUM(B12,B13)/'Inputs'!C4,1) -> 266 | G23: Bed asks divided by the price. The first column counts Snow, the second only asks that have been sent.
A24: Beds to find (sent asks only) | B24: ='Inputs'!C20-C23 -> 134 | C24: ='Inputs'!C20-C23 -> 134 | G24: The figure every funder-facing surface prints. An unsent ask covers no bed. Ben, 12 September 2026.
A25: Beds unfunded (every bed ask counted) | B25: ='Inputs'!C20-B23 -> 1 | C25: ='Inputs'!C20-C23 -> 134 | G25: The position after Snow lands. Same as beds to find in the second column, because Snow is the only unsent bed ask.
A26: Organisation line, short | B26: 181224 | G26: The organisation need less the operating and facilitation asks.
A27: Bed money over the making line | B27: 194787.33 | G27: The contribution doing its job. Organisation short less this surplus is the gap, seen from the other end.
A29: The organisation and the beds
A30: Line | B30: Amount | G30: Notes
A31: The organisation pays | B31: ='Inputs'!C37 -> 331224 | G31: Running, plus the freight and facilitation it absorbs at $100 a bed each.
A32: What 400 beds hand it | B32: ='Inputs'!C38 -> 115037.33 | G32: Beds at the contribution, after making, freight and facilitation.
A33: Running cost less what the beds hand back | B33: ='Inputs'!C39 -> 136186.67 | G33: Against running alone, because the contribution already carries the freight and facilitation. No grant goes against this line; the SEFA loan inside the ask carries it.

Sheet Monthly cash FY27
A1: Monthly cash, July 2026 to June 2027. A scenario laid out from the Inputs sheet. Nobody has forecast these months. Built 2026-09-15.
A2: Line | B2: July 2026 | C2: Aug 2026 | D2: Sept 2026 | E2: Oct 2026 | F2: Nov 2026 | G2: Dec 2026 | H2: Jan 2027 | I2: Feb 2027 | J2: Mar 2027 | K2: Apr 2027 | L2: May 2027 | M2: June 2027 | N2: FY27 | O2: Notes
A3: Receipts
A4: Grants for facilities (QBE) | B4: 0 | C4: 0 | D4: 0 | E4: 0 | F4: 0 | G4: 300000 | H4: 0 | I4: 0 | J4: 0 | K4: 0 | L4: 0 | M4: 0 | N4: =SUM(B4:M4) -> 300000 | O4: Scenario month only. No receipt date exists. Applying; closes 25 September.
A5: Grants for beds (Brian M. Davis, 133 beds) | B5: 0 | C5: 0 | D5: 0 | E5: 0 | F5: 0 | G5: 99750 | H5: 0 | I5: 0 | J5: 0 | K5: 0 | L5: 0 | M5: 0 | N5: =SUM(B5:M5) -> 99750 | O5: Scenario month only. No receipt date exists. Invited; board 19 November. One line, facilitation inside the bed.
A6: Grants for beds (Snow, Dusseldorp) | B6: 0 | C6: 0 | D6: 0 | E6: 0 | F6: 0 | G6: 0 | H6: 0 | I6: 0 | J6: 0 | K6: 0 | L6: 0 | M6: 0 | N6: =SUM(B6:M6) -> 0 | O6: Untimed and zero. Neither ask has been sent, so no month is honest.
A7: Grants for beds (Tim Fairfax, year one, 133 beds) | B7: 0 | C7: 0 | D7: 0 | E7: 0 | F7: 0 | G7: 100000 | H7: 0 | I7: 0 | J7: 0 | K7: 0 | L7: 0 | M7: 0 | N7: =SUM(B7:M7) -> 100000 | O7: Scenario month only. No receipt date exists. Invited; SmartyGrants closes 9 October, board late November. Ben, 15 September 2026: buys beds, not the running cost.
A8: Loan drawn (SEFA, inside the ask) | B8: 0 | C8: 0 | D8: 0 | E8: 0 | F8: 0 | G8: 150000 | H8: 0 | I8: 0 | J8: 0 | K8: 0 | L8: 0 | M8: 0 | N8: =SUM(B8:M8) -> 150000 | O8: Scenario month only. Ben, 15 September 2026: $150,000 inside the ask, repaid from the contribution. EOI drafted, unsent; Joel Bird reviews first.
A9: Bed sales to buyers | B9: =SUM('Inputs'!C57) -> 30000 | C9: =SUM('Inputs'!C58) -> 80000 | D9: 0 | E9: 0 | F9: 0 | G9: 0 | H9: 0 | I9: 0 | J9: 0 | K9: 0 | L9: 0 | M9: 0 | N9: =SUM(B9:M9) -> 110000 | O9: Only orders with a dated payment inside FY27: INV-0303 Homeland School Company, 40 beds, paid 2026-07-23; INV-0342 ALIVE National Centre, University of Melbourne, 100 beds, paid 2026-08-20. Bed line net of GST; facilitation billed on the same invoice is cost neutral and left out. No other buyer has a dated order.
A10: Total receipts | B10: =SUM(B4:B9) -> 30000 | C10: =SUM(C4:C9) -> 80000 | D10: =SUM(D4:D9) -> 0 | E10: =SUM(E4:E9) -> 0 | F10: =SUM(F4:F9) -> 0 | G10: =SUM(G4:G9) -> 649750 | H10: =SUM(H4:H9) -> 0 | I10: =SUM(I4:I9) -> 0 | ... M10: =SUM(M4:M9) -> 0 | N10: =SUM(B10:M10) -> 609750 | O10: Sent asks plus dated bed sales.
A11: Payments
A12: Plant capex (two plants) | B12: 0 | C12: 0 | D12: 0 | E12: 0 | F12: 0 | G12: ='Inputs'!C45 -> 300000 | H12: 0 | I12: 0 | J12: 0 | K12: 0 | L12: 0 | M12: 0 | N12: =SUM(B12:M12) -> 300000 | O12: Spent in the QBE scenario month. A plant costs what its grant brings, so this line never moves the gap.
A13: Making beds (400 at the making cost) | B13: 0 | C13: 0 | D13: 0 | E13: 0 | F13: 0 | G13: 0 | H13: ='Inputs'!C50*'Inputs'!C15 -> 25191.04 | I13: ='Inputs'!C50*'Inputs'!C15 -> 25191.04 | J13: ='Inputs'!C50*'Inputs'!C15 -> 25191.04 | K13: ='Inputs'!C50*'Inputs'!C15 -> 25191.04 | L13: =('Inputs'!C20-4*'Inputs'!C50)*'Inputs'!C15 -> 4198.5067 | M13: 0 | N13: =SUM(B13:M13) -> 104962.67 | O13: Kits a month capacity from January 2027, the month after the scenario receipts, until 400 are made (5 months). Making cost is provisional.
A14: Facilitation, absorbed by the organisation | B14: ='Inputs'!C28/'Inputs'!C24 -> 3333.3333 | C14: ='Inputs'!C28/'Inputs'!C24 -> 3333.3333 | D14: ='Inputs'!C28/'Inputs'!C24 -> 3333.3333 | E14: ='Inputs'!C28/'Inputs'!C24 -> 3333.3333 | F14: ='Inputs'!C28/'Inputs'!C24 -> 3333.3333 | G14: ='Inputs'!C28/'Inputs'!C24 -> 3333.3333 | H14: ='Inputs'!C28/'Inputs'!C24 -> 3333.3333 | I14: ='Inputs'!C28/'Inputs'!C24 -> 3333.3333 | J14: ='Inputs'!C28/'Inputs'!C24 -> 3333.3333 | K14: ='Inputs'!C28/'Inputs'!C24 -> 3333.3333 | L14: ='Inputs'!C28/'Inputs'!C24 -> 3333.3333 | M14: ='Inputs'!C28/'Inputs'!C24 -> 3333.3333 | N14: =SUM(B14:M14) -> 40000 | O14: Spread evenly. $100 a bed, paid by the organisation out of its share of the $750. Ben, 15 September 2026.
A15: Running the organisation | B15: ='Inputs'!C36/'Inputs'!C24 -> 20935.333 | C15: ='Inputs'!C36/'Inputs'!C24 -> 20935.333 | D15: ='Inputs'!C36/'Inputs'!C24 -> 20935.333 | E15: ='Inputs'!C36/'Inputs'!C24 -> 20935.333 | F15: ='Inputs'!C36/'Inputs'!C24 -> 20935.333 | G15: ='Inputs'!C36/'Inputs'!C24 -> 20935.333 | H15: ='Inputs'!C36/'Inputs'!C24 -> 20935.333 | I15: ='Inputs'!C36/'Inputs'!C24 -> 20935.333 | J15: ='Inputs'!C36/'Inputs'!C24 -> 20935.333 | K15: ='Inputs'!C36/'Inputs'!C24 -> 20935.333 | L15: ='Inputs'!C36/'Inputs'!C24 -> 20935.333 | M15: ='Inputs'!C36/'Inputs'!C24 -> 20935.333 | N15: =SUM(B15:M15) -> 251224 | O15: One twelfth each month. Founders line includes superannuation: unconfirmed.
A16: Freight, absorbed by the organisation (400 beds) | B16: 0 | C16: 0 | D16: 0 | E16: 0 | F16: 0 | G16: 0 | H16: ='Inputs'!C50*'Inputs'!C16 -> 9600 | I16: ='Inputs'!C50*'Inputs'!C16 -> 9600 | J16: ='Inputs'!C50*'Inputs'!C16 -> 9600 | K16: ='Inputs'!C50*'Inputs'!C16 -> 9600 | L16: =('Inputs'!C20-4*'Inputs'!C50)*'Inputs'!C16 -> 1600 | M16: 0 | N16: =SUM(B16:M16) -> 40000 | O16: Follows the making months. $100 a bed, paid by the organisation out of its share of the $750. Nothing comes back through sales. Ben, 15 September 2026.
A17: Total payments | B17: =SUM(B12:B16) -> 24268.667 | C17: =SUM(C12:C16) -> 24268.667 | D17: =SUM(D12:D16) -> 24268.667 | E17: =SUM(E12:E16) -> 24268.667 | F17: =SUM(F12:F16) -> 24268.667 | G17: =SUM(G12:G16) -> 324268.67 | H17: =SUM(H12:H16) -> 59059.707 | I17: =SUM(I12:I16) -> 59059.707 | ... M17: =SUM(M12:M16) -> 24268.667 | N17: =SUM(B17:M17) -> 736186.67 | O17: Equals the year's need: plants, beds at cost, facilitation, running and freight.
A19: Net cash | B19: =B10-B17 -> 5731.3333 | C19: =C10-C17 -> 55731.333 | D19: =D10-D17 -> -24268.667 | E19: =E10-E17 -> -24268.667 | F19: =F10-F17 -> -24268.667 | G19: =G10-G17 -> 325481.33 | H19: =H10-H17 -> -59059.707 | I19: =I10-I17 -> -59059.707 | ... M19: =M10-M17 -> -24268.667 | N19: =SUM(B19:M19) -> 23563.333 | O19: Receipts less payments.
A20: Opening cash | B20: ='Inputs'!C60 -> 4041 | C20: =B21 -> 9772.3333 | D20: =C21 -> 65503.667 | E20: =D21 -> 41235 | F20: =E21 -> 16966.333 | G20: =F21 -> -7302.3333 | H20: =G21 -> 318179 | I20: =H21 -> 259119.29 | J20: =I21 -> 200059.59 | ... M20: =L21 -> 51873 | O20: Butterfly whole entity, unaudited. Butterfly FY26 closing cash from the Inputs sheet.
A21: Closing cash | B21: =B20+B19 -> 9772.3333 | C21: =C20+C19 -> 65503.667 | D21: =D20+D19 -> 41235 | E21: =E20+E19 -> 16966.333 | F21: =F20+F19 -> -7302.3333 | G21: =G20+G19 -> 318179 | H21: =H20+H19 -> 259119.29 | I21: =I20+I19 -> 200059.59 | ... M21: =M20+M19 -> 27604.333 | O21: Opening plus net. Negative months mean the making runs ahead of the money and need either earlier receipts, a loan, or later making.
A22: Runway at June 2027, months of running cost | M22: =M21/('Inputs'!C36/'Inputs'!C24) -> 1.3185524 | O22: Closing cash over one month of running the organisation. Beds already made and unsold are not counted as cash.

Sheet Three years
A1: Three years, for the Tim Fairfax application. Bed volumes are targets inside modelled capacity. No buyer has ordered them.
A2: Line | B2: Year one, to June 2027 | C2: Year two, to June 2028 | D2: Year three, to June 2029 | E2: Notes
A3: Plants making beds | B3: 0 | C3: 2 | D3: 3 | E3: Witta not counted.
A4: Capacity, beds | B4: 1152 | C4: 1552 | D4: 2792 | E4: Witta plus plants at first-year and mature rates.
A5: Beds sold (target) | B5: 400 | C5: 874 | D5: 900 | E5: Targets, capacity-checked. Year two is the break-even number.
A6: Contribution from trade | B6: 115037.33 | C6: 251356.57 | D6: 258834 | E6: Beds sold at the contribution, after making, freight and facilitation.
A7: Running the organisation | B7: 251224 | C7: 251224 | D7: 251224 | E7: Held flat across three years. An assumption nobody has ruled on.
A8: Trade share of running cost | B8: 46 | C8: 100 | D8: 103 | E8: Contribution over running cost, in percent.
A9: Grant sought | B9: 100000 | C9: 100000 | D9: 100000 | E9: Tim Fairfax, three equal payments.
A10: Shortfall before grant (positive is short) | B10: 136186.67 | C10: -132.57333 | D10: -7610 | E10: Running less contribution.
A11: After grant (positive is surplus) | B11: -36186.667 | C11: 100132.57 | D11: 107610 | E11: Contribution plus grant less running.
A13: Break-even beds a year | B13: 874 | E13: Running cost over contribution, rounded up.
A14: Grant sought over three years | B14: 300000 | E14: The invitation is $300,000 in three equal payments.

Sheet Yield improvements
A1: Yield improvements. Ben, 15 September 2026: no second press. Nothing here is quoted, so nothing here enters a total.
A2: Item | B2: Amount | C2: Status | D2: Owner | E2: What it does
A3: A second press die | C3: needs-quote | D3: Nic | E3: Two tab sheets press per cycle on the press already in the shed.
A4: CNC tooling and a cutting jig for bought leg panels | C4: needs-quote | D4: Nic | E4: More leg sets cut from each bought panel, and faster.
A5: Shred handling: a bulka bag lifter and bins | C5: needs-quote | D5: Nic | E5: Moves shred from bag to press without hand-shovelling or spillage.
A6: Dust and fume extraction | C6: needs-quote | D6: Nic | E6: Keeps the router and press running through a full day safely.
A7: A cold press for canvas sleeves | C7: needs-quote | D7: Nic | E7: Takes sleeve making off the bench and shortens the canvas step.
A8: Genset or power upgrade | C8: needs-quote | D8: Nic | E8: Lets the press and the router run at the same time.
A9: Quoted items, total | B9: 0 | E9: An unquoted item never enters a total.

Sheet Sources
A1: Every constant the workbook uses, by module. Model version 2026-09-15.
A2: Constant | B2: Module | C2: Value | D2: Version
A3: MONTHS_IN_A_YEAR | B3: calendar | C3: 12 | D3: 2026-09-15
A4: ZERO | B4: calendar | C4: 0 | D4: 2026-09-15
A5: GAP_AUD | B5: v2/src/lib/data/capital-stack-flex.ts | C5: -13563.333 | D5: 2026-09-15
A6: OPERATING_SHORTFALL_AUD | B6: v2/src/lib/data/capital-stack-flex.ts | C6: 181224 | D6: 2026-09-15
A7: SEFA_LOAN_MAX_AUD | B7: v2/src/lib/data/capital-stack-flex.ts | C7: 200000 | D7: 2026-09-15
A8: SEFA_LOAN_MIN_AUD | B8: v2/src/lib/data/capital-stack-flex.ts | C8: 50000 | D8: 2026-09-15
A9: bedSurplusAud() | B9: v2/src/lib/data/capital-stack-flex.ts | C9: 194787.33 | D9: 2026-09-15
A10: PAID_TRADE[INV-0303].bedLineNetAud | B10: v2/src/lib/data/demand-and-buyers.ts | C10: 30000 | D10: 2026-09-15
A11: PAID_TRADE[INV-0342].bedLineNetAud | B11: v2/src/lib/data/demand-and-buyers.ts | C11: 80000 | D11: 2026-09-15
A12: PAID_TRADE[fullyPaidOn in FY27].bedLineNetAud | B12: v2/src/lib/data/demand-and-buyers.ts | C12: 110000 | D12: 2026-09-15
A13: BUTTERFLY_FY26_CLOSING_CASH_AUD | B13: external (Butterfly whole entity, unaudited) | C13: 4041 | D13: 2026-09-15
A14: AVAILABILITY | B14: v2/src/lib/data/production-route.ts | C14: 0.8 | D14: 2026-09-15
... A97: shortfallAud(fy29) | B97: v2/src/lib/data/three-year-plan.ts | C97: -7610 | D97: 2026-09-15
