Workbook
Name InvestorType: Dropdowns!$D$1:$D$15
Name Priority: Dropdowns!$A$1:$A$5

Sheet Introduction
B1: Triaging Investors
B3: Investor Alignment Tool
B5: This tool is designed to help you take the broad world of capital providers and filter down to the top investor targets that truly meet the needs of your venture. This process will help you spend your valuable time strategically, so you avoid pursuing investors that don't match your needs and have a greater chance of success with those investors that do.
B6: There are three steps to this process:
B7: Tab 1: Identify your needs
B8: Understand and document your own filter criteria in Tab 1. These are the criteria on which you'll judge potential investor matches. The knockout criteria are those on which you must match for an investment to be possible. These include investment geography, size, financial return expectations, and more. The fit criteria are those where you may be able to compromise or negotiate. These include governance expectations, impact evidence expectations, industry, and more.
B9: Tab 2: Track investors you encounter
B10: Use Tab 2 to keep an organized list of all the potential investor targets you encounter. Make notes if you've interacted with them and if you've identified next steps to keep the relationship warm. Use this tab to also brainstorm potential individuals in your own network that can introduce you to investors you are interested in.
B11: Tab 3: Evaluate your alignment with potential investors
B12: Use Tab 3 to filter all the potential investors you've identified down to the top targets that are most worth your time and energy to pursue. The knockout and fit criteria you identified will appear at the top of the tool. Use the investor rows to document what you know about the investors. For all criteria, decide if you align with the investor or not. Check the results columns to easily see which investors you are most aligned with - these are your top investor targets.
B13: Take a look at the Example tab to see how the Alignment Tool looks when completed by an early stage health venture with a set of fictional investors.
B14: After using this tool you will have identified your top investor targets - those worth spending your time and energy pursuing. Next you can move to Module 7 to create a plan for cultivating relationships with your top targets that may lead to investment.

Sheet Tab 1. Our Needs
B1: Triaging Investors
B3: Document here the filter criteria you will use to judge potential investor matches. Knockout criteria are those on which you must match for an investment to be possible. Fit criteria are those where you may be able to negotiate. Also, decide which fit criteria are high, medium, or low priority for matching with investors.
D5: KNOCKOUT CRITERIA - must be aligned on these | J5: FIT CRITERIA: Mission and Vision | L5: FIT CRITERIA: Expected From Us | O5: FIT CRITERIA: Expected From Our Investors
D6: Investment Geography | E6: Legal Structure | F6: Investment Size | G6: Return Expectations | H6: Capital Type | I6: Stage of Growth | J6: Social Mission | K6: Company Vision | L6: Governance | M6: Restrictions | N6: Impact Evidence | O6: Connections | P6: Geography experience | Q6: Industry experience | R6: Business challenge experience | S6: Impact on future investments
B7: Information on your venture: | D7: Invests in places we operate or our head-quartered | E7: Invest in our legal structure (i.e. for profit, nonprofit, hybrid) | F7: Generally invests the amount we are seeking | G7: Aligns on financial/ social return expectations (i.e., timeframe, exit) | H7: Offers type of capital (e.g. debt, equity, recoverable grant) we seek | I7: Invests in ventures at our stage of growth | J7: Understands and supports our social mission | K7: Understands and supports our vision | L7: Governance expectations (if any) match ours | M7: Any restrictions on use of funds (project, geography, etc.) work for us | N7: We can provide the level of impact evidence expected | O7: Able and willing to make useful connections for us | P7: Has experience in the locations we operate and want to enter | Q7: Has experience in our industry and/or market segment | R7: Has experience with the specific issues we are facing | S7: Any potential positive or negative impact on future capital raise works for us
B8: Our needs | C8: Document your needs: | D8: Remote Aboriginal & Torres Strait Islander communities / remote Australia (NT, QLD, WA, SA). National mandates qualify. | E8: Sole trader (N. Marchesi) migrating into A Curious Tractor Pty Ltd (t/a Goods on Country) this FY; DGR via The Butterfly Movement Ltd (FY2026-27). Hybrid/Pty Ltd/NFP OK; equity into eventual structure complex. | F8: First ~AU$400K signed within a AU$900K–1M blended raise. Grants ~$50–200K; concessional debt ~$300K; IBA blend up to $5M later. | G8: Concessional / social-first. Non-equity. Repayable preferred (QBE match rule), grants welcome. 5–10 yr horizon; exit = community ownership of production, not investor liquidity. | H8: Grants + concessional / recoverable / patient debt. NO conventional equity in 2026 (equity only inside a future community-ownership model). | I8: Early commercial — proven delivery (496 beds / 9 communities, tracked), pre-revenue commercial engine. A de-risking round (~89% grant-funded by design). Not seed; not growth-stage. | J8: Washable, repairable goods that prevent disease, built WITH communities, moving toward community ownership. | K8: Endgame is to become unnecessary — local people making, owning and repairing the goods themselves. | L8: Advisory board today, not yet fiduciary. Debt funders needing an independent-majority board are a real gate; grant funders comfortable with an advisory group are not. | M8: Geography-restricted money is workable (we deploy there anyway), but it shapes what each dollar can fund (e.g. not the in-source R&D run). | N8: Strong delivery evidence (tracked register, consented stories); MEL framework + longitudinal outcomes are draft. Catalytic funders accept the de-risking framing. | O8: Want introductions to procurement, government, finance and governance expertise. First-signature signalling value (Snow -> the rest of the stack) sits here. | P8: Remote-Australia experience helps (won't panic at freight/timelines). National funders willing to learn properly still qualify. | Q8: Few funders have direct sector experience (remote household goods, recycled-plastic manufacture, Indigenous procurement); not weighted heavily. | R8: Helpful if they've backed early-commercial social enterprises through the prove-the-engine stage; not applied strictly given the pipeline. | S8: A marquee catalytic name de-risks the next raise and the community-ownership transition. Negative-signal risk low; upside real.
C9: Choose priority level (dropdown menu): | D9: High - MOST IMPORTANT to be aligned on these | J9: High | K9: High | L9: Medium | M9: Medium | N9: Medium | O9: High | P9: Medium | Q9: Low | R9: Low | S9: Medium

Sheet Tab 2. Investor Tracking
B1: Triaging Investors
B3: List all potential investor targets here. Make notes on your interactions, next steps, and individuals in your network that can introduce you.
G4: Notes on correspondence | K4: Connectors
C5: Contact Name | E5: Contact Email | F5: Contact Phone | H5: Date | I5: Notes | J5: Next Steps | K5: Connector Name | M5: Connector email | N5: Connector phone | O5: Notes on correspondence
B6: QBE Foundation | C6: Jay Boolkin (program coordinator) | G6: Most recent: | K6: 1:
B7: Private Foundation | C7: 2: | G7: Historic: | K7: 2:
B8: qbefoundation.com.au | C8: 3: | K8: 3:
B10: Snow Foundation | C10: Sally Grimsley-Ballard (advisory group; confirm grants lead) | G10: Most recent: | K10: 1:
B11: Community or Family Foundation | C11: 2: | G11: Historic: | K11: 2:
B12: snowfoundation.org.au | C12: 3: | K12: 3:
B14: SEFA (Social Enterprise Finance Australia) | C14: Hannah Ebeling (CEO) — open by email | G14: Most recent: | K14: 1:
B15: CDFI or DFI | C15: 2: | G15: Historic: | K15: 2:
B16: sefa.com.au | C16: 3: | K16: 3:
B18: IBA (Indigenous Business Australia) | C18: (business plan pathway; Nicholas) | G18: Most recent: | K18: 1:
B19: Government | C19: 2: | G19: Historic: | K19: 2:
B20: iba.gov.au | C20: 3: | K20: 3:
B22: PFI (Paul Ramsay Foundation) | C22: (EOI submitted; awaiting feedback) | G22: Most recent: | K22: 1:
B23: Private Foundation | C23: 2: | G23: Historic: | K23: 2:
B24: paulramsayfoundation.org.au | C24: 3: | K24: 3:
B26: First Australians Capital | C26: (intro via IBA / SIH) | G26: Most recent: | K26: 1:
B27: CDFI or DFI | C27: 2: | G27: Historic: | K27: 2:
B28: firstaustralianscapital.org | C28: 3: | K28: 3:
B30: Minderoo Foundation | C30: Lucy Stronach | E30: lstronach@minderoo.org | G30: Most recent: | K30: 1:
B31: Private Foundation | C31: 2: | G31: Historic: | K31: 2:
B32: minderoo.org | C32: 3: | K32: 3:
B34: Tim Fairfax Family Foundation | C34: Katie Norman | G34: Most recent: | K34: 1:
B35: Community or Family Foundation | C35: 2: | G35: Historic: | K35: 2:
B36: timfairfax.com.au | C36: 3: | K36: 3:
B38: Dusseldorp Forum | C38: Teya Dusseldorp / Jess Wilson (NOT a Goods funder)
B39: Private Foundation | C39: 1: | G39: Most recent: | K39: 1:
B40: dusseldorp.org.au | C40: 2: | G40: Historic: | K40: 2:
B41: [Enter Website] | C41: 3: | K41: 3:
B42: TFN (The Funding Network) | C42: (alumni-network connector)
B43: Crowdfunding platform | C43: 1: | G43: Most recent: | K43: 1:
B44: thefundingnetwork.com.au | C44: 2: | G44: Historic: | K44: 2:
B45: [Enter Website] | C45: 3: | K45: 3:
B46: FRRR (Foundation for Rural & Regional Renewal) | C46: Steph Pearson | E46: s.pearson@frrr.org.au
B47: Community or Family Foundation | C47: 1: | G47: Most recent: | K47: 1:
B48: frrr.org.au | C48: 2: | G48: Historic: | K48: 2:
B49: [Enter Website] | C49: 3: | K49: 3:
...

Sheet Tab 3. Alignment Tool
B1: Triaging Investors
B3: From your research, note how potential investors match your knockout and fit criteria from Tab 1. Check the results columns on the right to easily see which investors you most align with - these are your top investor targets. Information on your venture:
D5: KNOCKOUT CRITERIA - must be aligned on these | J5: FIT CRITERIA: Mission and Vision | L5: FIT CRITERIA: Expected From Us | O5: FIT CRITERIA: Expected From Our Investors | U5: RESULTS
D6: Investment Geography | E6: Legal Structure | F6: Investment Size | G6: Return Expectations | H6: Capital Type | I6: Stage of Growth | J6: Social Mission | K6: Company Vision | L6: Governance | M6: Restrictions | N6: Impact Evidence | O6: Connections | P6: Geography experience | Q6: Industry experience | R6: Business challenge experience | S6: Impact on future investments
D7: Invests in places we operate or our head-quartered | E7: Invests in our legal structure (i.e. for profit, nonprofit, hybrid) | F7: Generally invests the amount we are seeking | G7: Aligns on financial/ social return expectations (i.e., timeframe, exit) | H7: Offers type of capital (e.g. debt, equity, recoverable grant) we seek | I7: Invests in ventures at our stage of growth | J7: Understands and supports our social mission | K7: Understands and supports our vision | L7: Governance expectations (if any) match ours | M7: Any restrictions on use of funds (project, geography, etc.) work for us | N7: We can provide the level of impact evidence expected | O7: Able and willing to make useful connections for us | P7: Has experience in the locations we operate and want to enter | Q7: Has experience in our industry and/or market segment | R7: Has experience with the specific issues we are facing | S7: Any potential positive or negative impact on future capital raise works for us | U7: Knockout Criteria | V7: High Priority Fit Criteria | W7: All Fit Criteria | AG7: High Priority total
B8: Our needs | C8: Document your needs: | D8: ='Tab 1. Our Needs'!D8 | E8: ='Tab 1. Our Needs'!E8 | F8: ='Tab 1. Our Needs'!F8 | G8: ='Tab 1. Our Needs'!G8 | H8: ='Tab 1. Our Needs'!H8 | I8: ='Tab 1. Our Needs'!I8 | J8: ='Tab 1. Our Needs'!J8 | K8: ='Tab 1. Our Needs'!K8 | ... S8: ='Tab 1. Our Needs'!S8 | U8: For all 6 knockout criteria are you somewhat or very aligned? | V8: For how many high priority fit criteria are you somewhat or very aligned? | W8: For how many overall fit criteria are you somewhat or very aligned? | AG8: J | AH8: K | AI8: L | AJ8: M | AK8: N | AL8: O | AM8: P | AN8: Q | AO8: R | AP8: S | AQ8: Total
C9: Choose priority level (dropdown menu): | D9: High - MOST IMPORTANT to be aligned on these | J9: ='Tab 1. Our Needs'!J9 | K9: ='Tab 1. Our Needs'!K9 | L9: ='Tab 1. Our Needs'!L9 | M9: ='Tab 1. Our Needs'!M9 | N9: ='Tab 1. Our Needs'!N9 | O9: ='Tab 1. Our Needs'!O9 | P9: ='Tab 1. Our Needs'!P9 | Q9: ='Tab 1. Our Needs'!Q9 | ... S9: ='Tab 1. Our Needs'!S9 | Y9: Knockout criteria results formula work | AG9: =IF(J9=Dropdowns!$A$1,1,0) | AH9: =IF(K9=Dropdowns!$A$1,1,0) | AI9: =IF(L9=Dropdowns!$A$1,1,0) | AJ9: =IF(M9=Dropdowns!$A$1,1,0) | AK9: =IF(N9=Dropdowns!$A$1,1,0) | AL9: =IF(O9=Dropdowns!$A$1,1,0) | AM9: =IF(P9=Dropdowns!$A$1,1,0) | AN9: =IF(Q9=Dropdowns!$A$1,1,0) | ... AP9: =IF(S9=Dropdowns!$A$1,1,0) | AQ9: =SUM(AG9:AP9)
B10: Information on potential investors: | Y10: D | Z10: E | AA10: F | AB10: G | AC10: H | AD10: I | AE10: Total | AG10: Very or somewhat aligned
B11: QBE Foundation | C11: Rate alignment (dropdown menu): | D11: Very Aligned | E11: Very Aligned | F11: Very Aligned | G11: Very Aligned | H11: Very Aligned | I11: Very Aligned | J11: Very Aligned | K11: Very Aligned | L11: Somewhat Aligned | M11: Somewhat Aligned | N11: Somewhat Aligned | O11: Very Aligned | P11: Somewhat Aligned | Q11: Somewhat Aligned | R11: Somewhat Aligned | S11: Very Aligned | U11: =IF(AE11=6,"Yes","No") | V11: =CONCATENATE(AQ12,"/", AQ9) | W11: =CONCATENATE(AQ11,"/", "10") | Y11: =IF(OR(D11=Dropdowns!$B$1,D11=Dropdowns!$B$2),1,0) | Z11: =IF(OR(E11=Dropdowns!$B$1,E11=Dropdowns!$B$2),1,0) | AA11: =IF(OR(F11=Dropdowns!$B$1,F11=Dropdowns!$B$2),1,0) | AB11: =IF(OR(G11=Dropdowns!$B$1,G11=Dropdowns!$B$2),1,0) | AC11: =IF(OR(H11=Dropdowns!$B$1,H11=Dropdowns!$B$2),1,0) | AD11: =IF(OR(I11=Dropdowns!$B$1,I11=Dropdowns!$B$2),1,0) | AE11: =SUM(Y11:AD11) | AG11: =IF(OR(J11=Dropdowns!$B$1,J11=Dropdowns!$B$2),1,0) | AH11: =IF(OR(K11=Dropdowns!$B$1,K11=Dropdowns!$B$2),1,0) | AI11: =IF(OR(L11=Dropdowns!$B$1,L11=Dropdowns!$B$2),1,0) | AJ11: =IF(OR(M11=Dropdowns!$B$1,M11=Dropdowns!$B$2),1,0) | AK11: =IF(OR(N11=Dropdowns!$B$1,N11=Dropdowns!$B$2),1,0) | AL11: =IF(OR(O11=Dropdowns!$B$1,O11=Dropdowns!$B$2),1,0) | AM11: =IF(OR(P11=Dropdowns!$B$1,P11=Dropdowns!$B$2),1,0) | AN11: =IF(OR(Q11=Dropdowns!$B$1,Q11=Dropdowns!$B$2),1,0) | ... AP11: =IF(OR(S11=Dropdowns!$B$1,S11=Dropdowns!$B$2),1,0) | AQ11: =SUM(AG11:AP11)
C12: Make notes on investor alignment: | D12: Program anchor (host). Stage 1 committed; Stage 2 up to AU$400K match-contingent, Sept 2026. Minor gaps: our board formalisation; longitudinal impact metrics. | AG12: =IF(AG$9=1,AG11,0) | AH12: =IF(AH$9=1,AH11,0) | AI12: =IF(AI$9=1,AI11,0) | AJ12: =IF(AJ$9=1,AJ11,0) | AK12: =IF(AK$9=1,AK11,0) | AL12: =IF(AL$9=1,AL11,0) | AM12: =IF(AM$9=1,AM11,0) | AN12: =IF(AN$9=1,AN11,0) | ... AP12: =IF(AP$9=1,AP11,0) | AQ12: =SUM(AG12:AP12)
Y13: D | Z13: E | AA13: F | AB13: G | AC13: H | AD13: I | AE13: Total | AG13: Very or somewhat aligned
B14: Snow Foundation | C14: Rate alignment (dropdown menu): | D14: Very Aligned | E14: Very Aligned | F14: Very Aligned | G14: Very Aligned | H14: Very Aligned | I14: Very Aligned | J14: Very Aligned | K14: Very Aligned | L14: Very Aligned | M14: Very Aligned | N14: Very Aligned | O14: Very Aligned | P14: Very Aligned | Q14: Very Aligned | R14: Very Aligned | S14: Very Aligned | U14: =IF(AE14=6,"Yes","No") | V14: =CONCATENATE(AQ15,"/", AQ9) | W14: =CONCATENATE(AQ14,"/", "10") | Y14: =IF(OR(D14=Dropdowns!$B$1,D14=Dropdowns!$B$2),1,0) | Z14: =IF(OR(E14=Dropdowns!$B$1,E14=Dropdowns!$B$2),1,0) | AA14: =IF(OR(F14=Dropdowns!$B$1,F14=Dropdowns!$B$2),1,0) | AB14: =IF(OR(G14=Dropdowns!$B$1,G14=Dropdowns!$B$2),1,0) | AC14: =IF(OR(H14=Dropdowns!$B$1,H14=Dropdowns!$B$2),1,0) | AD14: =IF(OR(I14=Dropdowns!$B$1,I14=Dropdowns!$B$2),1,0) | AE14: =SUM(Y14:AD14) | AG14: =IF(OR(J14=Dropdowns!$B$1,J14=Dropdowns!$B$2),1,0) | AH14: =IF(OR(K14=Dropdowns!$B$1,K14=Dropdowns!$B$2),1,0) | AI14: =IF(OR(L14=Dropdowns!$B$1,L14=Dropdowns!$B$2),1,0) | AJ14: =IF(OR(M14=Dropdowns!$B$1,M14=Dropdowns!$B$2),1,0) | AK14: =IF(OR(N14=Dropdowns!$B$1,N14=Dropdowns!$B$2),1,0) | AL14: =IF(OR(O14=Dropdowns!$B$1,O14=Dropdowns!$B$2),1,0) | AM14: =IF(OR(P14=Dropdowns!$B$1,P14=Dropdowns!$B$2),1,0) | AN14: =IF(OR(Q14=Dropdowns!$B$1,Q14=Dropdowns!$B$2),1,0) | ... AP14: =IF(OR(S14=Dropdowns!$B$1,S14=Dropdowns!$B$2),1,0) | AQ14: =SUM(AG14:AP14)
C15: Notes/comments on investor alignment: | D15: Anchor partner, ~AU$493K since 2023; Sally on advisory group; Jigsaw co-investor. Asked to be the FIRST match-eligible signature (note 08). Near-perfect on every dimension. | AG15: =IF(AG$9=1,AG14,0) | AH15: =IF(AH$9=1,AH14,0) | AI15: =IF(AI$9=1,AI14,0) | AJ15: =IF(AJ$9=1,AJ14,0) | AK15: =IF(AK$9=1,AK14,0) | AL15: =IF(AL$9=1,AL14,0) | AM15: =IF(AM$9=1,AM14,0) | AN15: =IF(AN$9=1,AN14,0) | ... AP15: =IF(AP$9=1,AP14,0) | AQ15: =SUM(AG15:AP15)
Y16: D | Z16: E | AA16: F | AB16: G | AC16: H | AD16: I | AE16: Total | AG16: Very or somewhat aligned
B17: SEFA (Social Enterprise Finance Australia) | C17: Rate alignment (dropdown menu): | D17: Very Aligned | E17: Very Aligned | F17: Very Aligned | G17: Very Aligned | H17: Very Aligned | I17: Very Aligned | J17: Very Aligned | K17: Somewhat Aligned | L17: Very Aligned | M17: Very Aligned | N17: Somewhat Aligned | O17: Very Aligned | P17: Somewhat Aligned | Q17: Very Aligned | R17: Very Aligned | S17: Very Aligned | U17: =IF(AE17=6,"Yes","No") | V17: =CONCATENATE(AQ18,"/", AQ9) | W17: =CONCATENATE(AQ17,"/", "10") | Y17: =IF(OR(D17=Dropdowns!$B$1,D17=Dropdowns!$B$2),1,0) | Z17: =IF(OR(E17=Dropdowns!$B$1,E17=Dropdowns!$B$2),1,0) | AA17: =IF(OR(F17=Dropdowns!$B$1,F17=Dropdowns!$B$2),1,0) | AB17: =IF(OR(G17=Dropdowns!$B$1,G17=Dropdowns!$B$2),1,0) | AC17: =IF(OR(H17=Dropdowns!$B$1,H17=Dropdowns!$B$2),1,0) | AD17: =IF(OR(I17=Dropdowns!$B$1,I17=Dropdowns!$B$2),1,0) | AE17: =SUM(Y17:AD17) | AG17: =IF(OR(J17=Dropdowns!$B$1,J17=Dropdowns!$B$2),1,0) | AH17: =IF(OR(K17=Dropdowns!$B$1,K17=Dropdowns!$B$2),1,0) | AI17: =IF(OR(L17=Dropdowns!$B$1,L17=Dropdowns!$B$2),1,0) | AJ17: =IF(OR(M17=Dropdowns!$B$1,M17=Dropdowns!$B$2),1,0) | AK17: =IF(OR(N17=Dropdowns!$B$1,N17=Dropdowns!$B$2),1,0) | AL17: =IF(OR(O17=Dropdowns!$B$1,O17=Dropdowns!$B$2),1,0) | AM17: =IF(OR(P17=Dropdowns!$B$1,P17=Dropdowns!$B$2),1,0) | AN17: =IF(OR(Q17=Dropdowns!$B$1,Q17=Dropdowns!$B$2),1,0) | ... AP17: =IF(OR(S17=Dropdowns!$B$1,S17=Dropdowns!$B$2),1,0) | AQ17: =SUM(AG17:AP17)
C18: Notes/comments on investor alignment: | D18: Dedicated social-enterprise lender; ~AU$300K working-capital sub-debt; syndicate-agent option (Jigsaw). Gate: independent-majority fiduciary board (covenant) + completed model + serviceable covenant. | AG18: =IF(AG$9=1,AG17,0) | AH18: =IF(AH$9=1,AH17,0) | AI18: =IF(AI$9=1,AI17,0) | AJ18: =IF(AJ$9=1,AJ17,0) | AK18: =IF(AK$9=1,AK17,0) | AL18: =IF(AL$9=1,AL17,0) | AM18: =IF(AM$9=1,AM17,0) | AN18: =IF(AN$9=1,AN17,0) | ... AP18: =IF(AP$9=1,AP17,0) | AQ18: =SUM(AG18:AP18)
Y19: D | Z19: E | AA19: F | AB19: G | AC19: H | AD19: I | AE19: Total | AG19: Very or somewhat aligned
B20: IBA (Indigenous Business Australia) | C20: Rate alignment (dropdown menu): | D20: Very Aligned | E20: Very Aligned | F20: Very Aligned | G20: Very Aligned | H20: Very Aligned | I20: Very Aligned | J20: Very Aligned | K20: Very Aligned | L20: Somewhat Aligned | M20: Somewhat Aligned | N20: Somewhat Aligned | O20: Very Aligned | P20: Very Aligned | Q20: Somewhat Aligned | R20: Somewhat Aligned | S20: Very Aligned | U20: =IF(AE20=6,"Yes","No") | V20: =CONCATENATE(AQ21,"/", AQ9) | W20: =CONCATENATE(AQ20,"/", "10") | Y20: =IF(OR(D20=Dropdowns!$B$1,D20=Dropdowns!$B$2),1,0) | Z20: =IF(OR(E20=Dropdowns!$B$1,E20=Dropdowns!$B$2),1,0) | AA20: =IF(OR(F20=Dropdowns!$B$1,F20=Dropdowns!$B$2),1,0) | AB20: =IF(OR(G20=Dropdowns!$B$1,G20=Dropdowns!$B$2),1,0) | AC20: =IF(OR(H20=Dropdowns!$B$1,H20=Dropdowns!$B$2),1,0) | AD20: =IF(OR(I20=Dropdowns!$B$1,I20=Dropdowns!$B$2),1,0) | AE20: =SUM(Y20:AD20) | AG20: =IF(OR(J20=Dropdowns!$B$1,J20=Dropdowns!$B$2),1,0) | AH20: =IF(OR(K20=Dropdowns!$B$1,K20=Dropdowns!$B$2),1,0) | AI20: =IF(OR(L20=Dropdowns!$B$1,L20=Dropdowns!$B$2),1,0) | AJ20: =IF(OR(M20=Dropdowns!$B$1,M20=Dropdowns!$B$2),1,0) | AK20: =IF(OR(N20=Dropdowns!$B$1,N20=Dropdowns!$B$2),1,0) | AL20: =IF(OR(O20=Dropdowns!$B$1,O20=Dropdowns!$B$2),1,0) | AM20: =IF(OR(P20=Dropdowns!$B$1,P20=Dropdowns!$B$2),1,0) | AN20: =IF(OR(Q20=Dropdowns!$B$1,Q20=Dropdowns!$B$2),1,0) | ... AP20: =IF(OR(S20=Dropdowns!$B$1,S20=Dropdowns!$B$2),1,0) | AQ20: =SUM(AG20:AP20)
C21: Notes/comments on investor alignment: | D21: Govt Indigenous business finance; eligibility confirmed; up to AU$5M (30% grant / 70% debt). Later senior anchor, NOT first tranche. Govt capital always has use restrictions. Gated on business plan + entity/Indigenous-ownership decision. | AG21: =IF(AG$9=1,AG20,0) | AH21: =IF(AH$9=1,AH20,0) | AI21: =IF(AI$9=1,AI20,0) | AJ21: =IF(AJ$9=1,AJ20,0) | AK21: =IF(AK$9=1,AK20,0) | AL21: =IF(AL$9=1,AL20,0) | AM21: =IF(AM$9=1,AM20,0) | AN21: =IF(AN$9=1,AN20,0) | ... AP21: =IF(AP$9=1,AP20,0) | AQ21: =SUM(AG21:AP21)
Y22: D | Z22: E | AA22: F | AB22: G | AC22: H | AD22: I | AE22: Total | AG22: Very or somewhat aligned
B23: PFI (Paul Ramsay Foundation) | C23: Alignment (dropdown menu): | D23: Very Aligned | E23: Very Aligned | F23: Very Aligned | G23: Very Aligned | H23: Very Aligned | I23: Very Aligned | J23: Very Aligned | K23: Very Aligned | L23: Somewhat Aligned | M23: Somewhat Aligned | N23: Somewhat Aligned | O23: Somewhat Aligned | P23: Somewhat Aligned | Q23: Somewhat Aligned | R23: Somewhat Aligned | S23: Very Aligned | U23: =IF(AE23=6,"Yes","No") | V23: =CONCATENATE(AQ24,"/", AQ9) | W23: =CONCATENATE(AQ23,"/", "10") | Y23: =IF(OR(D23=Dropdowns!$B$1,D23=Dropdowns!$B$2),1,0) | Z23: =IF(OR(E23=Dropdowns!$B$1,E23=Dropdowns!$B$2),1,0) | AA23: =IF(OR(F23=Dropdowns!$B$1,F23=Dropdowns!$B$2),1,0) | AB23: =IF(OR(G23=Dropdowns!$B$1,G23=Dropdowns!$B$2),1,0) | AC23: =IF(OR(H23=Dropdowns!$B$1,H23=Dropdowns!$B$2),1,0) | AD23: =IF(OR(I23=Dropdowns!$B$1,I23=Dropdowns!$B$2),1,0) | AE23: =SUM(Y23:AD23) | AG23: =IF(OR(J23=Dropdowns!$B$1,J23=Dropdowns!$B$2),1,0) | AH23: =IF(OR(K23=Dropdowns!$B$1,K23=Dropdowns!$B$2),1,0) | AI23: =IF(OR(L23=Dropdowns!$B$1,L23=Dropdowns!$B$2),1,0) | AJ23: =IF(OR(M23=Dropdowns!$B$1,M23=Dropdowns!$B$2),1,0) | AK23: =IF(OR(N23=Dropdowns!$B$1,N23=Dropdowns!$B$2),1,0) | AL23: =IF(OR(O23=Dropdowns!$B$1,O23=Dropdowns!$B$2),1,0) | AM23: =IF(OR(P23=Dropdowns!$B$1,P23=Dropdowns!$B$2),1,0) | AN23: =IF(OR(Q23=Dropdowns!$B$1,Q23=Dropdowns!$B$2),1,0) | ... AP23: =IF(OR(S23=Dropdowns!$B$1,S23=Dropdowns!$B$2),1,0) | AQ23: =SUM(AG23:AP23)
C24: Notes/comments on investor alignment: | D24: Recoverable-grant EOI in; AU$640K target; awaiting feedback. Jigsaw co-investor. One fit gap: confirm they will open doors, not only write a cheque. | AG24: =IF(AG$9=1,AG23,0) | AH24: =IF(AH$9=1,AH23,0) | AI24: =IF(AI$9=1,AI23,0) | AJ24: =IF(AJ$9=1,AJ23,0) | AK24: =IF(AK$9=1,AK23,0) | AL24: =IF(AL$9=1,AL23,0) | AM24: =IF(AM$9=1,AM23,0) | AN24: =IF(AN$9=1,AN23,0) | ... AP24: =IF(AP$9=1,AP23,0) | AQ24: =SUM(AG24:AP24)
Y25: D | Z25: E | AA25: F | AB25: G | AC25: H | AD25: I | AE25: Total | AG25: Very or somewhat aligned
B26: First Australians Capital | C26: Alignment (dropdown menu): | D26: Very Aligned | E26: Very Aligned | F26: Very Aligned | G26: Very Aligned | H26: Very Aligned | I26: Very Aligned | J26: Very Aligned | K26: Very Aligned | L26: Somewhat Aligned | M26: Somewhat Aligned | N26: Somewhat Aligned | O26: Somewhat Aligned | P26: Very Aligned | Q26: Somewhat Aligned | R26: Somewhat Aligned | S26: Very Aligned | U26: =IF(AE26=6,"Yes","No") | V26: =CONCATENATE(AQ27,"/", AQ9) | W26: =CONCATENATE(AQ26,"/", "10") | Y26: =IF(OR(D26=Dropdowns!$B$1,D26=Dropdowns!$B$2),1,0) | Z26: =IF(OR(E26=Dropdowns!$B$1,E26=Dropdowns!$B$2),1,0) | AA26: =IF(OR(F26=Dropdowns!$B$1,F26=Dropdowns!$B$2),1,0) | AB26: =IF(OR(G26=Dropdowns!$B$1,G26=Dropdowns!$B$2),1,0) | AC26: =IF(OR(H26=Dropdowns!$B$1,H26=Dropdowns!$B$2),1,0) | AD26: =IF(OR(I26=Dropdowns!$B$1,I26=Dropdowns!$B$2),1,0) | AE26: =SUM(Y26:AD26) | AG26: =IF(OR(J26=Dropdowns!$B$1,J26=Dropdowns!$B$2),1,0) | AH26: =IF(OR(K26=Dropdowns!$B$1,K26=Dropdowns!$B$2),1,0) | AI26: =IF(OR(L26=Dropdowns!$B$1,L26=Dropdowns!$B$2),1,0) | AJ26: =IF(OR(M26=Dropdowns!$B$1,M26=Dropdowns!$B$2),1,0) | AK26: =IF(OR(N26=Dropdowns!$B$1,N26=Dropdowns!$B$2),1,0) | AL26: =IF(OR(O26=Dropdowns!$B$1,O26=Dropdowns!$B$2),1,0) | AM26: =IF(OR(P26=Dropdowns!$B$1,P26=Dropdowns!$B$2),1,0) | AN26: =IF(OR(Q26=Dropdowns!$B$1,Q26=Dropdowns!$B$2),1,0) | ... AP26: =IF(OR(S26=Dropdowns!$B$1,S26=Dropdowns!$B$2),1,0) | AQ26: =SUM(AG26:AP26)
C27: Notes/comments on investor alignment: | D27: Indigenous-led CDFI; provided the AU$1M debt facility in the Dismantle deal. Indicative AU$100–500K. Research-stage: deal terms need confirming. Complementary to IBA. | AG27: =IF(AG$9=1,AG26,0) | AH27: =IF(AH$9=1,AH26,0) | AI27: =IF(AI$9=1,AI26,0) | AJ27: =IF(AJ$9=1,AJ26,0) | AK27: =IF(AK$9=1,AK26,0) | AL27: =IF(AL$9=1,AL26,0) | AM27: =IF(AM$9=1,AM26,0) | AN27: =IF(AN$9=1,AN26,0) | ... AP27: =IF(AP$9=1,AP26,0) | AQ27: =SUM(AG27:AP27)
Y28: D | Z28: E | AA28: F | AB28: G | AC28: H | AD28: I | AE28: Total | AG28: Very or somewhat aligned
B29: Minderoo Foundation | C29: Alignment (dropdown menu): | D29: Don't Know | E29: Very Aligned | F29: Very Aligned | G29: Very Aligned | H29: Very Aligned | I29: Very Aligned | J29: Somewhat Aligned | K29: Somewhat Aligned | L29: Somewhat Aligned | M29: Somewhat Aligned | N29: Somewhat Aligned | O29: Somewhat Aligned | P29: Don't Know | Q29: Don't Know | R29: Don't Know | S29: Very Aligned | U29: =IF(AE29=6,"Yes","No") | V29: =CONCATENATE(AQ30,"/", AQ9) | W29: =CONCATENATE(AQ29,"/", "10") | Y29: =IF(OR(D29=Dropdowns!$B$1,D29=Dropdowns!$B$2),1,0) | Z29: =IF(OR(E29=Dropdowns!$B$1,E29=Dropdowns!$B$2),1,0) | AA29: =IF(OR(F29=Dropdowns!$B$1,F29=Dropdowns!$B$2),1,0) | AB29: =IF(OR(G29=Dropdowns!$B$1,G29=Dropdowns!$B$2),1,0) | AC29: =IF(OR(H29=Dropdowns!$B$1,H29=Dropdowns!$B$2),1,0) | AD29: =IF(OR(I29=Dropdowns!$B$1,I29=Dropdowns!$B$2),1,0) | AE29: =SUM(Y29:AD29) | AG29: =IF(OR(J29=Dropdowns!$B$1,J29=Dropdowns!$B$2),1,0) | AH29: =IF(OR(K29=Dropdowns!$B$1,K29=Dropdowns!$B$2),1,0) | AI29: =IF(OR(L29=Dropdowns!$B$1,L29=Dropdowns!$B$2),1,0) | AJ29: =IF(OR(M29=Dropdowns!$B$1,M29=Dropdowns!$B$2),1,0) | AK29: =IF(OR(N29=Dropdowns!$B$1,N29=Dropdowns!$B$2),1,0) | AL29: =IF(OR(O29=Dropdowns!$B$1,O29=Dropdowns!$B$2),1,0) | AM29: =IF(OR(P29=Dropdowns!$B$1,P29=Dropdowns!$B$2),1,0) | AN29: =IF(OR(Q29=Dropdowns!$B$1,Q29=Dropdowns!$B$2),1,0) | ... AP29: =IF(OR(S29=Dropdowns!$B$1,S29=Dropdowns!$B$2),1,0) | AQ29: =SUM(AG29:AP29)
C30: Notes/comments on investor alignment: | D30: Catalytic capital bucket; recoverable instrument; AU$200K target. GEOGRAPHY/MANDATE FIT UNCONFIRMED (priorities = oceans, modern slavery) -> Don't Know on Geography, so no knockout pass yet. Relationship-only; gated on June 2026 Minderoo Board. | AG30: =IF(AG$9=1,AG29,0) | AH30: =IF(AH$9=1,AH29,0) | AI30: =IF(AI$9=1,AI29,0) | AJ30: =IF(AJ$9=1,AJ29,0) | AK30: =IF(AK$9=1,AK29,0) | AL30: =IF(AL$9=1,AL29,0) | AM30: =IF(AM$9=1,AM29,0) | AN30: =IF(AN$9=1,AN29,0) | ... AP30: =IF(AP$9=1,AP29,0) | AQ30: =SUM(AG30:AP30)
Y31: D | Z31: E | AA31: F | AB31: G | AC31: H | AD31: I | AE31: Total | AG31: Very or somewhat aligned
B32: Tim Fairfax Family Foundation | C32: Alignment (dropdown menu): | D32: Very Aligned | E32: Very Aligned | F32: Don't Know | G32: Very Aligned | H32: Don't Know | I32: Don't Know | J32: Very Aligned | K32: Somewhat Aligned | L32: Don't Know | M32: Don't Know | N32: Somewhat Aligned | O32: Somewhat Aligned | P32: Very Aligned | Q32: Don't Know | R32: Don't Know | S32: Somewhat Aligned | U32: =IF(AE32=6,"Yes","No") | V32: =CONCATENATE(AQ33,"/", AQ9) | W32: =CONCATENATE(AQ32,"/", "10") | Y32: =IF(OR(D32=Dropdowns!$B$1,D32=Dropdowns!$B$2),1,0) | Z32: =IF(OR(E32=Dropdowns!$B$1,E32=Dropdowns!$B$2),1,0) | AA32: =IF(OR(F32=Dropdowns!$B$1,F32=Dropdowns!$B$2),1,0) | AB32: =IF(OR(G32=Dropdowns!$B$1,G32=Dropdowns!$B$2),1,0) | AC32: =IF(OR(H32=Dropdowns!$B$1,H32=Dropdowns!$B$2),1,0) | AD32: =IF(OR(I32=Dropdowns!$B$1,I32=Dropdowns!$B$2),1,0) | AE32: =SUM(Y32:AD32) | AG32: =IF(OR(J32=Dropdowns!$B$1,J32=Dropdowns!$B$2),1,0) | AH32: =IF(OR(K32=Dropdowns!$B$1,K32=Dropdowns!$B$2),1,0) | AI32: =IF(OR(L32=Dropdowns!$B$1,L32=Dropdowns!$B$2),1,0) | AJ32: =IF(OR(M32=Dropdowns!$B$1,M32=Dropdowns!$B$2),1,0) | AK32: =IF(OR(N32=Dropdowns!$B$1,N32=Dropdowns!$B$2),1,0) | AL32: =IF(OR(O32=Dropdowns!$B$1,O32=Dropdowns!$B$2),1,0) | AM32: =IF(OR(P32=Dropdowns!$B$1,P32=Dropdowns!$B$2),1,0) | AN32: =IF(OR(Q32=Dropdowns!$B$1,Q32=Dropdowns!$B$2),1,0) | ... AP32: =IF(OR(S32=Dropdowns!$B$1,S32=Dropdowns!$B$2),1,0) | AQ32: =SUM(AG32:AP32)
C33: Notes/comments on investor alignment: | D33: Qld / remote / Indigenous community development; indicative AU$50–150K. CAPITAL TYPE / STAGE / SIZE FIT NOT CONFIRMED -> Don't Know, no knockout pass yet. Advisory relationship (Katie Norman). Lead with Palm Island proof. | AG33: =IF(AG$9=1,AG32,0) | AH33: =IF(AH$9=1,AH32,0) | AI33: =IF(AI$9=1,AI32,0) | AJ33: =IF(AJ$9=1,AJ32,0) | AK33: =IF(AK$9=1,AK32,0) | AL33: =IF(AL$9=1,AL32,0) | AM33: =IF(AM$9=1,AM32,0) | AN33: =IF(AN$9=1,AN32,0) | ... AP33: =IF(AP$9=1,AP32,0) | AQ33: =SUM(AG33:AP33)
Y34: D | Z34: E | AA34: F | AB34: G | AC34: H | AD34: I | AE34: Total | AG34: Very or somewhat aligned
B35: Dusseldorp Forum | C35: Alignment (dropdown menu): | D35: Don't Know | E35: Don't Know | F35: Don't Know | G35: Don't Know | H35: Don't Know | I35: Don't Know | J35: Very Aligned | K35: Somewhat Aligned | L35: Don't Know | M35: Don't Know | N35: Don't Know | O35: Somewhat Aligned | P35: Somewhat Aligned | Q35: Don't Know | R35: Don't Know | S35: Somewhat Aligned | U35: =IF(AE35=6,"Yes","No") | V35: =CONCATENATE(AQ36,"/", AQ9) | W35: =CONCATENATE(AQ35,"/", "10") | Y35: =IF(OR(D35=Dropdowns!$B$1,D35=Dropdowns!$B$2),1,0) | Z35: =IF(OR(E35=Dropdowns!$B$1,E35=Dropdowns!$B$2),1,0) | AA35: =IF(OR(F35=Dropdowns!$B$1,F35=Dropdowns!$B$2),1,0) | AB35: =IF(OR(G35=Dropdowns!$B$1,G35=Dropdowns!$B$2),1,0) | AC35: =IF(OR(H35=Dropdowns!$B$1,H35=Dropdowns!$B$2),1,0) | AD35: =IF(OR(I35=Dropdowns!$B$1,I35=Dropdowns!$B$2),1,0) | AE35: =SUM(Y35:AD35) | AG35: =IF(OR(J35=Dropdowns!$B$1,J35=Dropdowns!$B$2),1,0) | AH35: =IF(OR(K35=Dropdowns!$B$1,K35=Dropdowns!$B$2),1,0) | AI35: =IF(OR(L35=Dropdowns!$B$1,L35=Dropdowns!$B$2),1,0) | AJ35: =IF(OR(M35=Dropdowns!$B$1,M35=Dropdowns!$B$2),1,0) | AK35: =IF(OR(N35=Dropdowns!$B$1,N35=Dropdowns!$B$2),1,0) | AL35: =IF(OR(O35=Dropdowns!$B$1,O35=Dropdowns!$B$2),1,0) | AM35: =IF(OR(P35=Dropdowns!$B$1,P35=Dropdowns!$B$2),1,0) | AN35: =IF(OR(Q35=Dropdowns!$B$1,Q35=Dropdowns!$B$2),1,0) | ... AP35: =IF(OR(S35=Dropdowns!$B$1,S35=Dropdowns!$B$2),1,0) | AQ35: =SUM(AG35:AP35)
C36: Notes/comments on investor alignment: | D36: NOT a Goods funder — the known AU$15K is Mounty Backyard / Contained / JusticeHub. No Goods-specific mandate to score -> Don't Know on all knockouts. Possible relationship context only. | AG36: =IF(AG$9=1,AG35,0) | AH36: =IF(AH$9=1,AH35,0) | AI36: =IF(AI$9=1,AI35,0) | AJ36: =IF(AJ$9=1,AJ35,0) | AK36: =IF(AK$9=1,AK35,0) | AL36: =IF(AL$9=1,AL35,0) | AM36: =IF(AM$9=1,AM35,0) | AN36: =IF(AN$9=1,AN35,0) | ... AP36: =IF(AP$9=1,AP35,0) | AQ36: =SUM(AG36:AP36)
Y37: D | Z37: E | AA37: F | AB37: G | AC37: H | AD37: I | AE37: Total | AG37: Very or somewhat aligned
B38: TFN (The Funding Network) | C38: Alignment (dropdown menu): | D38: Very Aligned | E38: Very Aligned | F38: Very Aligned | G38: Very Aligned | H38: Very Aligned | I38: Very Aligned | J38: Very Aligned | K38: Very Aligned | L38: Very Aligned | M38: Very Aligned | N38: Very Aligned | O38: Very Aligned | P38: Somewhat Aligned | Q38: Somewhat Aligned | R38: Very Aligned | S38: Very Aligned | U38: =IF(AE38=6,"Yes","No") | V38: =CONCATENATE(AQ39,"/", AQ12) | W38: =CONCATENATE(AQ38,"/", "10") | Y38: =IF(OR(D38=Dropdowns!$B$1,D38=Dropdowns!$B$2),1,0) | Z38: =IF(OR(E38=Dropdowns!$B$1,E38=Dropdowns!$B$2),1,0) | AA38: =IF(OR(F38=Dropdowns!$B$1,F38=Dropdowns!$B$2),1,0) | AB38: =IF(OR(G38=Dropdowns!$B$1,G38=Dropdowns!$B$2),1,0) | AC38: =IF(OR(H38=Dropdowns!$B$1,H38=Dropdowns!$B$2),1,0) | AD38: =IF(OR(I38=Dropdowns!$B$1,I38=Dropdowns!$B$2),1,0) | AE38: =SUM(Y38:AD38) | AG38: =IF(OR(J38=Dropdowns!$B$1,J38=Dropdowns!$B$2),1,0) | AH38: =IF(OR(K38=Dropdowns!$B$1,K38=Dropdowns!$B$2),1,0) | AI38: =IF(OR(L38=Dropdowns!$B$1,L38=Dropdowns!$B$2),1,0) | AJ38: =IF(OR(M38=Dropdowns!$B$1,M38=Dropdowns!$B$2),1,0) | AK38: =IF(OR(N38=Dropdowns!$B$1,N38=Dropdowns!$B$2),1,0) | AL38: =IF(OR(O38=Dropdowns!$B$1,O38=Dropdowns!$B$2),1,0) | AM38: =IF(OR(P38=Dropdowns!$B$1,P38=Dropdowns!$B$2),1,0) | AN38: =IF(OR(Q38=Dropdowns!$B$1,Q38=Dropdowns!$B$2),1,0) | ... AP38: =IF(OR(S38=Dropdowns!$B$1,S38=Dropdowns!$B$2),1,0) | AQ38: =SUM(AG38:AP38)
C39: Notes/comments on investor alignment: | D39: Received AU$130K (Dec 2025). Live-pitch model. Best used as an alumni-network CONNECTOR to downstream funders rather than a follow-on cheque. | AG39: =IF(AG$9=1,AG38,0) | AH39: =IF(AH$9=1,AH38,0) | AI39: =IF(AI$9=1,AI38,0) | AJ39: =IF(AJ$9=1,AJ38,0) | AK39: =IF(AK$9=1,AK38,0) | AL39: =IF(AL$9=1,AL38,0) | AM39: =IF(AM$9=1,AM38,0) | AN39: =IF(AN$9=1,AN38,0) | ... AP39: =IF(AP$9=1,AP38,0) | AQ39: =SUM(AG39:AP39)
Y40: D | Z40: E | AA40: F | AB40: G | AC40: H | AD40: I | AE40: Total | AG40: Very or somewhat aligned
B41: FRRR (Foundation for Rural & Regional Renewal) | C41: Alignment (dropdown menu): | D41: Very Aligned | E41: Very Aligned | F41: Very Aligned | G41: Very Aligned | H41: Very Aligned | I41: Very Aligned | J41: Very Aligned | K41: Very Aligned | L41: Very Aligned | M41: Very Aligned | N41: Very Aligned | O41: Somewhat Aligned | P41: Somewhat Aligned | Q41: Somewhat Aligned | R41: Somewhat Aligned | S41: Somewhat Aligned | U41: =IF(AE41=6,"Yes","No") | V41: =CONCATENATE(AQ42,"/", AQ15) | W41: =CONCATENATE(AQ41,"/", "10") | Y41: =IF(OR(D41=Dropdowns!$B$1,D41=Dropdowns!$B$2),1,0) | Z41: =IF(OR(E41=Dropdowns!$B$1,E41=Dropdowns!$B$2),1,0) | AA41: =IF(OR(F41=Dropdowns!$B$1,F41=Dropdowns!$B$2),1,0) | AB41: =IF(OR(G41=Dropdowns!$B$1,G41=Dropdowns!$B$2),1,0) | AC41: =IF(OR(H41=Dropdowns!$B$1,H41=Dropdowns!$B$2),1,0) | AD41: =IF(OR(I41=Dropdowns!$B$1,I41=Dropdowns!$B$2),1,0) | AE41: =SUM(Y41:AD41) | AG41: =IF(OR(J41=Dropdowns!$B$1,J41=Dropdowns!$B$2),1,0) | AH41: =IF(OR(K41=Dropdowns!$B$1,K41=Dropdowns!$B$2),1,0) | AI41: =IF(OR(L41=Dropdowns!$B$1,L41=Dropdowns!$B$2),1,0) | AJ41: =IF(OR(M41=Dropdowns!$B$1,M41=Dropdowns!$B$2),1,0) | AK41: =IF(OR(N41=Dropdowns!$B$1,N41=Dropdowns!$B$2),1,0) | AL41: =IF(OR(O41=Dropdowns!$B$1,O41=Dropdowns!$B$2),1,0) | AM41: =IF(OR(P41=Dropdowns!$B$1,P41=Dropdowns!$B$2),1,0) | AN41: =IF(OR(Q41=Dropdowns!$B$1,Q41=Dropdowns!$B$2),1,0) | ... AP41: =IF(OR(S41=Dropdowns!$B$1,S41=Dropdowns!$B$2),1,0) | AQ41: =SUM(AG41:AP41)
C42: Notes/comments on investor alignment: | D42: Received AU$50K Backing the Future (joint with VFFF — ONE grant, not two); Palm Island acquittal complete Mar 2026. Already a QBE Local Division Partnership -> may be receptive to a coordinated second ask. | AG42: =IF(AG$9=1,AG41,0) | AH42: =IF(AH$9=1,AH41,0) | AI42: =IF(AI$9=1,AI41,0) | AJ42: =IF(AJ$9=1,AJ41,0) | AK42: =IF(AK$9=1,AK41,0) | AL42: =IF(AL$9=1,AL41,0) | AM42: =IF(AM$9=1,AM41,0) | AN42: =IF(AN$9=1,AN41,0) | ... AP42: =IF(AP$9=1,AP41,0) | AQ42: =SUM(AG42:AP42)
...

Sheet Example
B1: Triaging Investors
B3: In this example a health venture in India has evaluated four fictional investors for alignment. The results on the right help this venture prioritize which investors to pursue at this time, and which investors may be a good fit in the future. Information on your venture:
D5: KNOCKOUT CRITERIA - must be aligned on these | J5: FIT CRITERIA: Mission and Vision | L5: FIT CRITERIA: Expected From Us | O5: FIT CRITERIA: Expected From Our Investors | U5: RESULTS
D6: Investment Geography | E6: Legal Structure | F6: Investment Size | G6: Return Expectations | H6: Capital Type | I6: Stage of Growth | J6: Social Mission | K6: Company Vision | L6: Governance | M6: Restrictions | N6: Impact Evidence | O6: Connections | P6: Geography experience | Q6: Industry experience | R6: Business challenge experience | S6: Impact on future investments
D7: Invests in places we operate or are head-quartered | E7: Invests in our legal structure (i.e. for profit, nonprofit, hybrid) | F7: Generally invests the amount we are seeking | G7: Aligns on financial/ social return expectations (i.e., timeframe, exit) | H7: Offers type of capital (e.g. debt, equity, recoverable grant) we seek | I7: Invests in ventures at our stage of growth | J7: Understands and supports our social mission | K7: Understands and supports our vision | L7: Governance expectations (if any) match ours | M7: Any restrictions on use of funds (project, geography, etc.) work for us | N7: We can provide the level of impact evidence expected | O7: Able and willing to make useful connections for us | P7: Has experience in the locations we operate and want to enter | Q7: Has experience in our industry and/or market segment | R7: Has experience with the specific issues we are facing | S7: Any potential positive or negative impact on future capital raise works for us | U7: Knockout Criteria | V7: High Priority Fit Criteria | W7: All Fit Criteria | AG7: High Priority total
B8: Our needs | C8: Document your needs: | D8: India | E8: For profit | F8: $200,000-$500,000 | G8: Lower financial return given our customer base, more impact focused | H8: Grant, recoverable grant, equity | I8: Early stage | J8: Providing affordable preventative healthcare to India's rural poor | K8: Employ our hub-and-spoke model in 3 villages, then expand to more | L8: Willing to put someone on our board | M8: Need someone focused on our geography and rural population | N8: We can collect data on income level of customers served | O8: This is somewhat useful to us, but not critical at this point | P8: Have our own experience in our geography, so this isn't critical | Q8: This would be helpful, but isn't critical | R8: Experience supporting early stage venture testing a model would be helpful | S8: Not sure what our needs are on this | U8: For all 6 knockout criteria are you somewhat or very aligned? | V8: For how many high priority fit criteria are you somewhat or very aligned? | W8: For how many overall fit criteria are you somewhat or very aligned? | AG8: J | AH8: K | AI8: L | AJ8: M | AK8: N | AL8: O | AM8: P | AN8: Q | AO8: R | AP8: S | AQ8: Total
C9: Choose priority level (dropdown menu): | D9: High - MOST IMPORTANT to be aligned on these | J9: High | K9: Medium | L9: Medium | M9: High | N9: Medium | O9: Low | P9: Low | Q9: Low | R9: High | S9: Low | Y9: Knockout criteria results formula work | AG9: =IF(J9=Dropdowns!$A$1,1,0) | AH9: =IF(K9=Dropdowns!$A$1,1,0) | AI9: =IF(L9=Dropdowns!$A$1,1,0) | AJ9: =IF(M9=Dropdowns!$A$1,1,0) | AK9: =IF(N9=Dropdowns!$A$1,1,0) | AL9: =IF(O9=Dropdowns!$A$1,1,0) | AM9: =IF(P9=Dropdowns!$A$1,1,0) | AN9: =IF(Q9=Dropdowns!$A$1,1,0) | ... AP9: =IF(S9=Dropdowns!$A$1,1,0) | AQ9: =SUM(AG9:AP9)
B10: Information on potential investors: | Y10: D | Z10: E | AA10: F | AB10: G | AC10: H | AD10: I | AE10: Total | AG10: Very or somewhat aligned
B11: USA Development Grant Program | C11: Rate alignment (dropdown menu): | D11: Very Aligned | E11: Very Aligned | F11: Somewhat Aligned | G11: Very Aligned | H11: Very Aligned | I11: Very Aligned | J11: Very Aligned | K11: Very Aligned | L11: Very Aligned | M11: Very Aligned | N11: Don't Know | O11: Somewhat Aligned | P11: Very Aligned | Q11: Very Aligned | R11: Somewhat Aligned | S11: Very Aligned | U11: =IF(AE11=6,"Yes","No") | V11: =CONCATENATE(AQ12,"/", AQ9) | W11: =CONCATENATE(AQ11,"/", "10") | Y11: =IF(OR(D11=Dropdowns!$B$1,D11=Dropdowns!$B$2),1,0) | Z11: =IF(OR(E11=Dropdowns!$B$1,E11=Dropdowns!$B$2),1,0) | AA11: =IF(OR(F11=Dropdowns!$B$1,F11=Dropdowns!$B$2),1,0) | AB11: =IF(OR(G11=Dropdowns!$B$1,G11=Dropdowns!$B$2),1,0) | AC11: =IF(OR(H11=Dropdowns!$B$1,H11=Dropdowns!$B$2),1,0) | AD11: =IF(OR(I11=Dropdowns!$B$1,I11=Dropdowns!$B$2),1,0) | AE11: =SUM(Y11:AD11) | AG11: =IF(OR(J11=Dropdowns!$B$1,J11=Dropdowns!$B$2),1,0) | AH11: =IF(OR(K11=Dropdowns!$B$1,K11=Dropdowns!$B$2),1,0) | AI11: =IF(OR(L11=Dropdowns!$B$1,L11=Dropdowns!$B$2),1,0) | AJ11: =IF(OR(M11=Dropdowns!$B$1,M11=Dropdowns!$B$2),1,0) | AK11: =IF(OR(N11=Dropdowns!$B$1,N11=Dropdowns!$B$2),1,0) | AL11: =IF(OR(O11=Dropdowns!$B$1,O11=Dropdowns!$B$2),1,0) | AM11: =IF(OR(P11=Dropdowns!$B$1,P11=Dropdowns!$B$2),1,0) | AN11: =IF(OR(Q11=Dropdowns!$B$1,Q11=Dropdowns!$B$2),1,0) | ... AP11: =IF(OR(S11=Dropdowns!$B$1,S11=Dropdowns!$B$2),1,0) | AQ11: =SUM(AG11:AP11)
C12: Make notes on investor alignment: | D12: Focused on developing countries | E12: Fund for profits | F12: Up to $150K, so this could be a portion of what we need | G12: Offer grants | H12: Grant | I12: Stage 1 grant is for early stage | J12: Supports innovation in developing countries | K12: Stage 1 funding is for testing the model | L12: Wouldn't impact governance | M12: Funding is for testing a model and that is what we need to do | N12: Not sure the impact data we would need to report and how difficult it would be | O12: May be able to connect us to other grant funding | P12: Has funded other ventures in our area | Q12: Has funded other health ventures | R12: Funds early stage, but not sure how much direct support they will provide, besides $ | S12: Would look good to secure funding from DIV | AG12: =IF(AG9=1,AG11,0) | AH12: =IF(AH9=1,AH11,0) | AI12: =IF(AI9=1,AI11,0) | AJ12: =IF(AJ9=1,AJ11,0) | AK12: =IF(AK9=1,AK11,0) | AL12: =IF(AL9=1,AL11,0) | AM12: =IF(AM9=1,AM11,0) | AN12: =IF(AN9=1,AN11,0) | ... AP12: =IF(AP9=1,AP11,0) | AQ12: =SUM(AG12:AP12)
Y13: D | Z13: E | AA13: F | AB13: G | AC13: H | AD13: I | AE13: Total | AG13: Very or somewhat aligned
B14: Indian Seed Fund | C14: Rate alignment (dropdown menu): | D14: Very Aligned | E14: Very Aligned | F14: Very Aligned | G14: Don't Know | H14: Somewhat Aligned | I14: Very Aligned | J14: Very Aligned | K14: Don't Know | L14: Very Aligned | M14: Very Aligned | N14: Somewhat Aligned | O14: Very Aligned | P14: Very Aligned | Q14: Very Aligned | R14: Somewhat Aligned | S14: Very Aligned | U14: =IF(AE14=6,"Yes","No") | V14: =CONCATENATE(AQ15,"/", AQ9) | W14: =CONCATENATE(AQ14,"/", "10") | Y14: =IF(OR(D14=Dropdowns!$B$1,D14=Dropdowns!$B$2),1,0) | Z14: =IF(OR(E14=Dropdowns!$B$1,E14=Dropdowns!$B$2),1,0) | AA14: =IF(OR(F14=Dropdowns!$B$1,F14=Dropdowns!$B$2),1,0) | AB14: =IF(OR(G14=Dropdowns!$B$1,G14=Dropdowns!$B$2),1,0) | AC14: =IF(OR(H14=Dropdowns!$B$1,H14=Dropdowns!$B$2),1,0) | AD14: =IF(OR(I14=Dropdowns!$B$1,I14=Dropdowns!$B$2),1,0) | AE14: =SUM(Y14:AD14) | AG14: =IF(OR(J14=Dropdowns!$B$1,J14=Dropdowns!$B$2),1,0) | AH14: =IF(OR(K14=Dropdowns!$B$1,K14=Dropdowns!$B$2),1,0) | AI14: =IF(OR(L14=Dropdowns!$B$1,L14=Dropdowns!$B$2),1,0) | AJ14: =IF(OR(M14=Dropdowns!$B$1,M14=Dropdowns!$B$2),1,0) | AK14: =IF(OR(N14=Dropdowns!$B$1,N14=Dropdowns!$B$2),1,0) | AL14: =IF(OR(O14=Dropdowns!$B$1,O14=Dropdowns!$B$2),1,0) | AM14: =IF(OR(P14=Dropdowns!$B$1,P14=Dropdowns!$B$2),1,0) | AN14: =IF(OR(Q14=Dropdowns!$B$1,Q14=Dropdowns!$B$2),1,0) | ... AP14: =IF(OR(S14=Dropdowns!$B$1,S14=Dropdowns!$B$2),1,0) | AQ14: =SUM(AG14:AP14)
C15: Notes/comments on investor alignment: | D15: Focused on India | E15: Fund for profits | F15: $100,000-300,000 | G15: Don't know if they'll agree with our return forecasts | H15: Only do equity | I15: Do early stage | J15: Health for low income communities is a focus | K15: Not sure if our model would resonate with them | L15: They would probably want board seat | M15: Geography and sector match | N15: They are financial first, so probably wouldn't expect a lot of impact metrics yet | O15: Would have lots of connections in India and with health | P15: Focused on India | Q15: Health is a focus | R15: Would they see us as seed stage, or are we still too early? | S15: Think it will look good for us | AG15: =IF(AG9=1,AG14,0) | AH15: =IF(AH9=1,AH14,0) | AI15: =IF(AI9=1,AI14,0) | AJ15: =IF(AJ9=1,AJ14,0) | AK15: =IF(AK9=1,AK14,0) | AL15: =IF(AL9=1,AL14,0) | AM15: =IF(AM9=1,AM14,0) | AN15: =IF(AN9=1,AN14,0) | ... AP15: =IF(AP9=1,AP14,0) | AQ15: =SUM(AG15:AP15)
Y16: D | Z16: E | AA16: F | AB16: G | AC16: H | AD16: I | AE16: Total | AG16: Very or somewhat aligned
B17: Riser Equity | C17: Rate alignment (dropdown menu): | D17: Very Aligned | E17: Very Aligned | F17: Somewhat Aligned | G17: Not Aligned | H17: Somewhat Aligned | I17: Not Aligned | J17: Very Aligned | K17: Don't Know | L17: Very Aligned | M17: Very Aligned | N17: Don't Know | O17: Very Aligned | P17: Very Aligned | Q17: Very Aligned | R17: Not Aligned | S17: Very Aligned | U17: =IF(AE17=6,"Yes","No") | V17: =CONCATENATE(AQ18,"/", AQ9) | W17: =CONCATENATE(AQ17,"/", "10") | Y17: =IF(OR(D17=Dropdowns!$B$1,D17=Dropdowns!$B$2),1,0) | Z17: =IF(OR(E17=Dropdowns!$B$1,E17=Dropdowns!$B$2),1,0) | AA17: =IF(OR(F17=Dropdowns!$B$1,F17=Dropdowns!$B$2),1,0) | AB17: =IF(OR(G17=Dropdowns!$B$1,G17=Dropdowns!$B$2),1,0) | AC17: =IF(OR(H17=Dropdowns!$B$1,H17=Dropdowns!$B$2),1,0) | AD17: =IF(OR(I17=Dropdowns!$B$1,I17=Dropdowns!$B$2),1,0) | AE17: =SUM(Y17:AD17) | AG17: =IF(OR(J17=Dropdowns!$B$1,J17=Dropdowns!$B$2),1,0) | AH17: =IF(OR(K17=Dropdowns!$B$1,K17=Dropdowns!$B$2),1,0) | AI17: =IF(OR(L17=Dropdowns!$B$1,L17=Dropdowns!$B$2),1,0) | AJ17: =IF(OR(M17=Dropdowns!$B$1,M17=Dropdowns!$B$2),1,0) | AK17: =IF(OR(N17=Dropdowns!$B$1,N17=Dropdowns!$B$2),1,0) | AL17: =IF(OR(O17=Dropdowns!$B$1,O17=Dropdowns!$B$2),1,0) | AM17: =IF(OR(P17=Dropdowns!$B$1,P17=Dropdowns!$B$2),1,0) | AN17: =IF(OR(Q17=Dropdowns!$B$1,Q17=Dropdowns!$B$2),1,0) | ... AP17: =IF(OR(S17=Dropdowns!$B$1,S17=Dropdowns!$B$2),1,0) | AQ17: =SUM(AG17:AP17)
C18: Notes/comments on investor alignment: | D18: Funds in India | E18: Funds for profits | F18: $200,000-2,000,000 | G18: Expects market returns and we're not there yet | H18: Only do equity | I18: We're too early for them | J18: They focus on bringing essential services to underserved | K18: Not sure if our model would resonate with them | L18: They would want a board seat | M18: Probably wouldn't be any restrictions on use of equity funds | N18: Not sure what they would want from us on this | O18: Probably have connections to geography and industry expertise | P18: India is a geography focus for them | Q18: Health is an industry focus for them | R18: We're probably too early - they may not help test a model, but would help scale a working model | S18: They're respected investors, so I think it would help future raises | AG18: =IF(AG9=1,AG17,0) | AH18: =IF(AH9=1,AH17,0) | AI18: =IF(AI9=1,AI17,0) | AJ18: =IF(AJ9=1,AJ17,0) | AK18: =IF(AK9=1,AK17,0) | AL18: =IF(AL9=1,AL17,0) | AM18: =IF(AM9=1,AM17,0) | AN18: =IF(AN9=1,AN17,0) | ... AP18: =IF(AP9=1,AP17,0) | AQ18: =SUM(AG18:AP18)
Y19: D | Z19: E | AA19: F | AB19: G | AC19: H | AD19: I | AE19: Total | AG19: Very or somewhat aligned
B20: Crescent Foundation | C20: Rate alignment (dropdown menu): | D20: Very Aligned | E20: Very Aligned | F20: Somewhat Aligned | G20: Very Aligned | H20: Very Aligned | I20: Very Aligned | J20: Not Aligned | K20: Not Aligned | L20: Very Aligned | M20: Not Aligned | N20: Don't Know | O20: Somewhat Aligned | P20: Very Aligned | Q20: Not Aligned | R20: Somewhat Aligned | S20: Very Aligned | U20: =IF(AE20=6,"Yes","No") | V20: =CONCATENATE(AQ21,"/", AQ9) | W20: =CONCATENATE(AQ20,"/", "10") | Y20: =IF(OR(D20=Dropdowns!$B$1,D20=Dropdowns!$B$2),1,0) | Z20: =IF(OR(E20=Dropdowns!$B$1,E20=Dropdowns!$B$2),1,0) | AA20: =IF(OR(F20=Dropdowns!$B$1,F20=Dropdowns!$B$2),1,0) | AB20: =IF(OR(G20=Dropdowns!$B$1,G20=Dropdowns!$B$2),1,0) | AC20: =IF(OR(H20=Dropdowns!$B$1,H20=Dropdowns!$B$2),1,0) | AD20: =IF(OR(I20=Dropdowns!$B$1,I20=Dropdowns!$B$2),1,0) | AE20: =SUM(Y20:AD20) | AG20: =IF(OR(J20=Dropdowns!$B$1,J20=Dropdowns!$B$2),1,0) | AH20: =IF(OR(K20=Dropdowns!$B$1,K20=Dropdowns!$B$2),1,0) | AI20: =IF(OR(L20=Dropdowns!$B$1,L20=Dropdowns!$B$2),1,0) | AJ20: =IF(OR(M20=Dropdowns!$B$1,M20=Dropdowns!$B$2),1,0) | AK20: =IF(OR(N20=Dropdowns!$B$1,N20=Dropdowns!$B$2),1,0) | AL20: =IF(OR(O20=Dropdowns!$B$1,O20=Dropdowns!$B$2),1,0) | AM20: =IF(OR(P20=Dropdowns!$B$1,P20=Dropdowns!$B$2),1,0) | AN20: =IF(OR(Q20=Dropdowns!$B$1,Q20=Dropdowns!$B$2),1,0) | ... AP20: =IF(OR(S20=Dropdowns!$B$1,S20=Dropdowns!$B$2),1,0) | AQ20: =SUM(AG20:AP20)
C21: Notes/comments on investor alignment: | D21: Funds in India | E21: Funds for profits | F21: Grants are $100,000-$150,000. Equity isn't clear. | G21: "Social return first" | H21: Grants and Equity | I21: Early stage | J21: Don't seem to do health, and focus on urban poor not rural | K21: Haven't supported health venture before | L21: Probably no governance requirements | M21: May require a focus on urban poor, not rural | N21: Don't know what they require | O21: Not sure how extensive their network is, but this is low priority for us | P21: Experience in India | Q21: Don't seem to do health | R21: Have supported early stage ventures testing model, but not our type of model | S21: Don't think it will affect future raises | AG21: =IF(AG9=1,AG20,0) | AH21: =IF(AH9=1,AH20,0) | AI21: =IF(AI9=1,AI20,0) | AJ21: =IF(AJ9=1,AJ20,0) | AK21: =IF(AK9=1,AK20,0) | AL21: =IF(AL9=1,AL20,0) | AM21: =IF(AM9=1,AM20,0) | AN21: =IF(AN9=1,AN20,0) | ... AP21: =IF(AP9=1,AP20,0) | AQ21: =SUM(AG21:AP21)
Y22: D | Z22: E | AA22: F | AB22: G | AC22: H | AD22: I | AE22: Total | AG22: Very or somewhat aligned

Sheet Dropdowns
A1: High | B1: Very Aligned | C1: Possible | D1: Investor Type (choose from dropdown)
A2: Medium | B2: Somewhat Aligned | C2: Probably | D2: Angel
A3: Low | B3: Not Aligned | C3: Likely | D3: Friends & Family
A4: N/A | B4: Don't Know | D4: Family Office
B5: N/A | D5: Community or Family Foundation
D6: CDFI or DFI
D7: Private Foundation
D8: Government
D9: International NGO
D10: Corporate
D11: Investment Fund
D12: Institutional Investor or Bank
D13: Fellowship, Incubator, or Accelerator
D14: Crowdfunding platform
D15: Other
